<sdf version='1.7'>
  <model name='ur5e_2f85'>
    <joint name='table_to_world' type='fixed'>
      <pose relative_to='__model__'>0 0 0 0 -0 0</pose>
      <parent>world</parent>
      <child>table_base</child>
    </joint>
    <link name='table_base'>
      <pose relative_to='table_to_world'>0 0 0 0 -0 0</pose>
      <inertial>
        <pose>-0.00155 0.05625 0.165458 0 -0 0</pose>
        <mass>24</mass>
        <inertia>
          <ixx>4.6693</ixx>
          <ixy>0.0104625</ixy>
          <ixz>0.0307753</ixz>
          <iyy>4.2899</iyy>
          <iyz>-1.11684</iyz>
          <izz>1.38718</izz>
        </inertia>
      </inertial>
      <collision name='table_base_collision'>
        <pose>0 0 0 0 -0 0</pose>
        <geometry>
          <mesh>
            <scale>1 1 1</scale>
            <uri>model://coro_descriptions/meshes/small_vention_table.dae</uri>
          </mesh>
        </geometry>
      </collision>
      <collision name='table_base_fixed_joint_lump__base_link_inertia_collision_1'>
        <pose>-0.0093 0.3375 0.99275 0 0 -3.14159</pose>
        <geometry>
          <mesh>
            <scale>1 1 1</scale>
            <uri>model://ur_description/meshes/ur5e/collision/base.stl</uri>
          </mesh>
        </geometry>
      </collision>
      <visual name='table_base_visual'>
        <pose>0 0 0 0 -0 0</pose>
        <geometry>
          <mesh>
            <scale>1 1 1</scale>
            <uri>model://coro_descriptions/meshes/small_vention_table.dae</uri>
          </mesh>
        </geometry>
      </visual>
      <visual name='table_base_fixed_joint_lump__base_link_inertia_visual_1'>
        <pose>-0.0093 0.3375 0.99275 0 0 -3.14159</pose>
        <geometry>
          <mesh>
            <scale>1 1 1</scale>
            <uri>model://ur_description/meshes/ur5e/visual/base.dae</uri>
          </mesh>
        </geometry>
      </visual>
      <self_collide>true</self_collide>
    </link>
    <joint name='shoulder_pan_joint' type='revolute'>
      <pose relative_to='table_base'>-0.0093 0.3375 1.15525 0 -0 7e-06</pose>
      <parent>table_base</parent>
      <child>shoulder_link</child>
      <axis>
        <xyz>0 0 1</xyz>
        <limit>
          <lower>-6.28319</lower>
          <upper>6.28319</upper>
          <effort>150</effort>
          <velocity>3.14159</velocity>
        </limit>
        <dynamics>
          <damping>0</damping>
          <friction>0</friction>
          <spring_reference>0</spring_reference>
          <spring_stiffness>0</spring_stiffness>
        </dynamics>
      </axis>
    </joint>
    <link name='shoulder_link'>
      <pose relative_to='shoulder_pan_joint'>0 0 0 0 -0 0</pose>
      <inertial>
        <pose>0 0 0 0 -0 0</pose>
        <mass>3.7</mass>
        <inertia>
          <ixx>0.0102675</ixx>
          <ixy>0</ixy>
          <ixz>0</ixz>
          <iyy>0.0102675</iyy>
          <iyz>0</iyz>
          <izz>0.00666</izz>
        </inertia>
      </inertial>
      <collision name='shoulder_link_collision'>
        <pose>0 0 0 0 -0 3.14159</pose>
        <geometry>
          <mesh>
            <scale>1 1 1</scale>
            <uri>model://ur_description/meshes/ur5e/collision/shoulder.stl</uri>
          </mesh>
        </geometry>
      </collision>
      <visual name='shoulder_link_visual'>
        <pose>0 0 0 0 -0 3.14159</pose>
        <geometry>
          <mesh>
            <scale>1 1 1</scale>
            <uri>model://ur_description/meshes/ur5e/visual/shoulder.dae</uri>
          </mesh>
        </geometry>
      </visual>
      <self_collide>true</self_collide>
    </link>
    <joint name='shoulder_lift_joint' type='revolute'>
      <pose relative_to='shoulder_link'>0 0 0 1.5708 -0 0</pose>
      <parent>shoulder_link</parent>
      <child>upper_arm_link</child>
      <axis>
        <xyz>0 0 1</xyz>
        <limit>
          <lower>-6.28319</lower>
          <upper>6.28319</upper>
          <effort>150</effort>
          <velocity>3.14159</velocity>
        </limit>
        <dynamics>
          <damping>0</damping>
          <friction>0</friction>
          <spring_reference>0</spring_reference>
          <spring_stiffness>0</spring_stiffness>
        </dynamics>
      </axis>
    </joint>
    <link name='upper_arm_link'>
      <pose relative_to='shoulder_lift_joint'>0 0 0 0 -0 0</pose>
      <inertial>
        <pose>-0.2125 0 0.138 0 1.5708 0</pose>
        <mass>8.393</mass>
        <inertia>
          <ixx>0.133886</ixx>
          <ixy>0</ixy>
          <ixz>0</ixz>
          <iyy>0.133886</iyy>
          <iyz>0</iyz>
          <izz>0.0151074</izz>
        </inertia>
      </inertial>
      <collision name='upper_arm_link_collision'>
        <pose>0 0 0.138 1.5708 0 -1.5708</pose>
        <geometry>
          <mesh>
            <scale>1 1 1</scale>
            <uri>model://ur_description/meshes/ur5e/collision/upperarm.stl</uri>
          </mesh>
        </geometry>
      </collision>
      <visual name='upper_arm_link_visual'>
        <pose>0 0 0.138 1.5708 0 -1.5708</pose>
        <geometry>
          <mesh>
            <scale>1 1 1</scale>
            <uri>model://ur_description/meshes/ur5e/visual/upperarm.dae</uri>
          </mesh>
        </geometry>
      </visual>
      <self_collide>true</self_collide>
    </link>
    <joint name='elbow_joint' type='revolute'>
      <pose relative_to='upper_arm_link'>-0.425 0 0 0 -0 0</pose>
      <parent>upper_arm_link</parent>
      <child>forearm_link</child>
      <axis>
        <xyz>0 0 1</xyz>
        <limit>
          <lower>-3.14159</lower>
          <upper>3.14159</upper>
          <effort>150</effort>
          <velocity>3.14159</velocity>
        </limit>
        <dynamics>
          <damping>0</damping>
          <friction>0</friction>
          <spring_reference>0</spring_reference>
          <spring_stiffness>0</spring_stiffness>
        </dynamics>
      </axis>
    </joint>
    <link name='forearm_link'>
      <pose relative_to='elbow_joint'>0 0 0 0 -0 0</pose>
      <inertial>
        <pose>-0.1961 0 0.007 0 1.5708 0</pose>
        <mass>2.275</mass>
        <inertia>
          <ixx>0.0312094</ixx>
          <ixy>0</ixy>
          <ixz>0</ixz>
          <iyy>0.0312094</iyy>
          <iyz>0</iyz>
          <izz>0.004095</izz>
        </inertia>
      </inertial>
      <collision name='forearm_link_collision'>
        <pose>0 0 0.007 1.5708 0 -1.5708</pose>
        <geometry>
          <mesh>
            <scale>1 1 1</scale>
            <uri>model://ur_description/meshes/ur5e/collision/forearm.stl</uri>
          </mesh>
        </geometry>
      </collision>
      <visual name='forearm_link_visual'>
        <pose>0 0 0.007 1.5708 0 -1.5708</pose>
        <geometry>
          <mesh>
            <scale>1 1 1</scale>
            <uri>model://ur_description/meshes/ur5e/visual/forearm.dae</uri>
          </mesh>
        </geometry>
      </visual>
      <self_collide>true</self_collide>
    </link>
    <joint name='wrist_1_joint' type='revolute'>
      <pose relative_to='forearm_link'>-0.3922 0 0.1333 0 -0 0</pose>
      <parent>forearm_link</parent>
      <child>wrist_1_link</child>
      <axis>
        <xyz>0 0 1</xyz>
        <limit>
          <lower>-6.28319</lower>
          <upper>6.28319</upper>
          <effort>28</effort>
          <velocity>3.14159</velocity>
        </limit>
        <dynamics>
          <damping>0</damping>
          <friction>0</friction>
          <spring_reference>0</spring_reference>
          <spring_stiffness>0</spring_stiffness>
        </dynamics>
      </axis>
    </joint>
    <link name='wrist_1_link'>
      <pose relative_to='wrist_1_joint'>0 0 0 0 -0 0</pose>
      <inertial>
        <pose>0 0 0 0 -0 0</pose>
        <mass>1.219</mass>
        <inertia>
          <ixx>0.0025599</ixx>
          <ixy>0</ixy>
          <ixz>0</ixz>
          <iyy>0.0025599</iyy>
          <iyz>0</iyz>
          <izz>0.0021942</izz>
        </inertia>
      </inertial>
      <collision name='wrist_1_link_collision'>
        <pose>0 0 -0.127 1.5708 -0 0</pose>
        <geometry>
          <mesh>
            <scale>1 1 1</scale>
            <uri>model://ur_description/meshes/ur5e/collision/wrist1.stl</uri>
          </mesh>
        </geometry>
      </collision>
      <visual name='wrist_1_link_visual'>
        <pose>0 0 -0.127 1.5708 -0 0</pose>
        <geometry>
          <mesh>
            <scale>1 1 1</scale>
            <uri>model://ur_description/meshes/ur5e/visual/wrist1.dae</uri>
          </mesh>
        </geometry>
      </visual>
      <self_collide>true</self_collide>
    </link>
    <joint name='wrist_2_joint' type='revolute'>
      <pose relative_to='wrist_1_link'>0 -0.0997 -0 1.5708 -0 0</pose>
      <parent>wrist_1_link</parent>
      <child>wrist_2_link</child>
      <axis>
        <xyz>0 0 1</xyz>
        <limit>
          <lower>-6.28319</lower>
          <upper>6.28319</upper>
          <effort>28</effort>
          <velocity>3.14159</velocity>
        </limit>
        <dynamics>
          <damping>0</damping>
          <friction>0</friction>
          <spring_reference>0</spring_reference>
          <spring_stiffness>0</spring_stiffness>
        </dynamics>
      </axis>
    </joint>
    <link name='wrist_2_link'>
      <pose relative_to='wrist_2_joint'>0 0 0 0 -0 0</pose>
      <inertial>
        <pose>0 0 0 0 -0 0</pose>
        <mass>1.219</mass>
        <inertia>
          <ixx>0.0025599</ixx>
          <ixy>0</ixy>
          <ixz>0</ixz>
          <iyy>0.0025599</iyy>
          <iyz>0</iyz>
          <izz>0.0021942</izz>
        </inertia>
      </inertial>
      <collision name='wrist_2_link_collision'>
        <pose>0 0 -0.0997 0 -0 0</pose>
        <geometry>
          <mesh>
            <scale>1 1 1</scale>
            <uri>model://ur_description/meshes/ur5e/collision/wrist2.stl</uri>
          </mesh>
        </geometry>
      </collision>
      <visual name='wrist_2_link_visual'>
        <pose>0 0 -0.0997 0 -0 0</pose>
        <geometry>
          <mesh>
            <scale>1 1 1</scale>
            <uri>model://ur_description/meshes/ur5e/visual/wrist2.dae</uri>
          </mesh>
        </geometry>
      </visual>
      <self_collide>true</self_collide>
    </link>
    <joint name='wrist_3_joint' type='revolute'>
      <pose relative_to='wrist_2_link'>0 0.0996 -0 -1.5708 -1.57 -0</pose>
      <parent>wrist_2_link</parent>
      <child>wrist_3_link</child>
      <axis>
        <xyz>0 0 1</xyz>
        <limit>
          <lower>-6.28319</lower>
          <upper>6.28319</upper>
          <effort>28</effort>
          <velocity>3.14159</velocity>
        </limit>
        <dynamics>
          <damping>0</damping>
          <friction>0</friction>
          <spring_reference>0</spring_reference>
          <spring_stiffness>0</spring_stiffness>
        </dynamics>
      </axis>
    </joint>
    <link name='wrist_3_link'>
      <pose relative_to='wrist_3_joint'>0 0 0 0 -0 0</pose>
      <inertial>
        <pose>0.002293 -0.015608 0.043268 0 -0 0</pose>
        <mass>0.729447</mass>
        <inertia>
          <ixx>0.00230758</ixx>
          <ixy>-7.26691e-05</ixy>
          <ixz>7.18589e-05</ixz>
          <iyy>0.00236122</iyy>
          <iyz>0.000420565</iyz>
          <izz>0.00114128</izz>
        </inertia>
      </inertial>
      <collision name='wrist_3_link_collision'>
        <pose>0 0 -0.0989 1.5708 -0 0</pose>
        <geometry>
          <mesh>
            <scale>1 1 1</scale>
            <uri>model://ur_description/meshes/ur5e/collision/wrist3.stl</uri>
          </mesh>
        </geometry>
      </collision>
      <collision name='wrist_3_link_fixed_joint_lump__ur_bracket_collision_1'>
        <pose>-0 0 0.01 -0 -0 0</pose>
        <geometry>
          <mesh>
            <scale>1 1 1</scale>
            <uri>model://coro_descriptions/meshes/ur_bracket.stl</uri>
          </mesh>
        </geometry>
        <surface>
          <contact>
            <ode>
              <max_vel>10</max_vel>
              <min_depth>0.001</min_depth>
            </ode>
          </contact>
        </surface>
        <max_contacts>1000</max_contacts>
      </collision>
      <collision name='wrist_3_link_fixed_joint_lump__palm_link_collision_2'>
        <pose>-0 -0.007 0.113 3.14159 -0 0</pose>
        <geometry>
          <mesh>
            <scale>1 1 1</scale>
            <uri>model://allegro_hand_description/meshes/g_r2.stl</uri>
          </mesh>
        </geometry>
        <surface>
          <contact>
            <ode>
              <max_vel>10</max_vel>
              <min_depth>0.001</min_depth>
            </ode>
          </contact>
        </surface>
        <max_contacts>1000</max_contacts>
      </collision>
      <collision name='wrist_3_link_fixed_joint_lump__boh_bracket_collision_3'>
        <pose>0 -0.0069 0.113 -4e-06 4e-06 1.57079</pose>
        <geometry>
          <mesh>
            <scale>1 1 1</scale>
            <uri>model://allegro_hand_description/meshes/part_4.stl</uri>
          </mesh>
        </geometry>
        <surface>
          <contact>
            <ode>
              <max_vel>10</max_vel>
              <min_depth>0.001</min_depth>
            </ode>
          </contact>
        </surface>
        <max_contacts>1000</max_contacts>
      </collision>
      <collision name='boh_fpcb'>
        <pose>0 -0.0069 0.113 -4e-06 4e-06 1.57079</pose>
        <geometry>
          <mesh>
            <scale>1 1 1</scale>
            <uri>model://allegro_hand_description/meshes/boh_fpcb.stl</uri>
          </mesh>
        </geometry>
        <surface>
          <contact>
            <ode>
              <max_vel>10</max_vel>
              <min_depth>0.001</min_depth>
            </ode>
          </contact>
        </surface>
        <max_contacts>1000</max_contacts>
      </collision>
<!--******************************************* -->
        <sensor name='boh' type='contact'>
          <contact>
            <collision>boh_fpcb</collision>
          </contact>
        <update_rate> 5 </update_rate>
        <visualize> true </visualize>
        </sensor>    
<!--******************************************* --> 
      <collision name='wrist_3_link_fixed_joint_lump__palm_bracket_collision_5'>
        <pose>-0 -0.007 0.113 4e-06 -4e-06 1.57079</pose>
        <geometry>
          <mesh>
            <scale>1 1 1</scale>
            <uri>model://allegro_hand_description/meshes/palm_bracket.stl</uri>
          </mesh>
        </geometry>
        <surface>
          <contact>
            <ode>
              <max_vel>10</max_vel>
              <min_depth>0.001</min_depth>
            </ode>
          </contact>
        </surface>
        <max_contacts>1000</max_contacts>
      </collision>
      <collision name='palm_fpcb'>
        <pose>-0 -0.007 0.113 4e-06 -4e-06 1.57079</pose>
        <geometry>
          <mesh>
            <scale>1 1 1</scale>
            <uri>model://allegro_hand_description/meshes/palm_fpcb.stl</uri>
          </mesh>
        </geometry>
        <surface>
          <contact>
            <ode>
              <max_vel>10</max_vel>
              <min_depth>0.001</min_depth>
            </ode>
          </contact>
        </surface>
        <max_contacts>1000</max_contacts>
      </collision>
<!--******************************************* -->
        <sensor name='palm' type='contact'>
          <contact>
            <collision>palm_fpcb</collision>
          </contact>
        <update_rate> 5 </update_rate>
        <visualize> true </visualize>
        </sensor>    
<!--******************************************* --> 
      <visual name='wrist_3_link_visual'>
        <pose>0 0 -0.0989 1.5708 -0 0</pose>
        <geometry>
          <mesh>
            <scale>1 1 1</scale>
            <uri>model://ur_description/meshes/ur5e/visual/wrist3.dae</uri>
          </mesh>
        </geometry>
      </visual>
      <visual name='wrist_3_link_fixed_joint_lump__ur_bracket_visual_1'>
        <pose>-0 0 0.01 -0 -0 0</pose>
        <geometry>
          <mesh>
            <scale>1 1 1</scale>
            <uri>model://coro_descriptions/meshes/ur_bracket.stl</uri>
          </mesh>
        </geometry>
      </visual>
      <visual name='wrist_3_link_fixed_joint_lump__palm_link_visual_2'>
        <pose>-0 -0.007 0.113 3.14159 -0 0</pose>
        <geometry>
          <mesh>
            <scale>1 1 1</scale>
            <uri>model://allegro_hand_description/meshes/g_r2.stl</uri>
          </mesh>
        </geometry>
      </visual>
      <visual name='wrist_3_link_fixed_joint_lump__boh_bracket_visual_3'>
        <pose>0 -0.0069 0.113 -4e-06 4e-06 1.57079</pose>
        <geometry>
          <mesh>
            <scale>1 1 1</scale>
            <uri>model://allegro_hand_description/meshes/part_4.stl</uri>
          </mesh>
        </geometry>
      </visual>
      <visual name='wrist_3_link_fixed_joint_lump__boh_visual_4'>
        <pose>0 -0.0069 0.113 -4e-06 4e-06 1.57079</pose>
        <geometry>
          <mesh>
            <scale>1 1 1</scale>
            <uri>model://allegro_hand_description/meshes/boh_fpcb.stl</uri>
          </mesh>
        </geometry>
      </visual>
      <visual name='wrist_3_link_fixed_joint_lump__palm_bracket_visual_5'>
        <pose>-0 -0.007 0.113 4e-06 -4e-06 1.57079</pose>
        <geometry>
          <mesh>
            <scale>1 1 1</scale>
            <uri>model://allegro_hand_description/meshes/palm_bracket.stl</uri>
          </mesh>
        </geometry>
      </visual>
      <visual name='wrist_3_link_fixed_joint_lump__palm_fpcb_visual_6'>
        <pose>-0 -0.007 0.113 4e-06 -4e-06 1.57079</pose>
        <geometry>
          <mesh>
            <scale>1 1 1</scale>
            <uri>model://allegro_hand_description/meshes/palm_fpcb.stl</uri>
          </mesh>
        </geometry>
      </visual>
      <self_collide>true</self_collide>
    </link>
    <joint name='joint_0_0' type='revolute'>
      <pose relative_to='wrist_3_link'>-0.043538 -0.007 0.109461 -0.087267 -0 1.5708</pose>
      <parent>wrist_3_link</parent>
      <child>link_0</child>
      <axis>
        <xyz>0 0 1</xyz>
        <limit>
          <lower>-0.45</lower>
          <upper>0.55</upper>
          <effort>15</effort>
          <velocity>20</velocity>
        </limit>
        <dynamics>
          <damping>0</damping>
          <friction>0.5</friction>
          <spring_reference>0</spring_reference>
          <spring_stiffness>0</spring_stiffness>
        </dynamics>
      </axis>
      <physics>
        <implicit_spring_damper> true </implicit_spring_damper>
      </physics>
    </joint>
    <link name='link_0'>
      <pose relative_to='joint_0_0'>0 0 0 0 -0 0</pose>
      <inertial>
        <pose>-0.000413 0.000666 0.009606 0 -0 0</pose>
        <mass>0.0136672</mass>
        <inertia>
          <ixx>2.13441e-06</ixx>
          <ixy>5.86704e-10</ixy>
          <ixz>-7.9563e-08</ixz>
          <iyy>1.24411e-06</iyy>
          <iyz>-6.13056e-08</iyz>
          <izz>1.671e-06</izz>
        </inertia>
      </inertial>
      <collision name='link_0_collision'>
        <pose>0 0 -0.0152 1.5708 0 -0</pose>
        <geometry>
          <mesh>
            <scale>1 1 1</scale>
            <uri>model://allegro_hand_description/meshes/extended_finger_base.stl</uri>
          </mesh>
        </geometry>
        <surface>
          <contact>
            <ode>
              <max_vel>10</max_vel>
              <min_depth>0.001</min_depth>
            </ode>
          </contact>
        </surface>
        <max_contacts>1000</max_contacts>
      </collision>
      <visual name='link_0_visual'>
        <pose>0 0 -0.0152 1.5708 0 -0</pose>
        <geometry>
          <mesh>
            <scale>1 1 1</scale>
            <uri>model://allegro_hand_description/meshes/extended_finger_base.stl</uri>
          </mesh>
        </geometry>
      </visual>
      <self_collide>true</self_collide>
    </link>
    <joint name='joint_1_0' type='revolute'>
      <pose relative_to='link_0'>0 -0.0119 0.02545 1.57079 -1.57079 3.14159</pose>
      <parent>link_0</parent>
      <child>link_1</child>
      <axis>
        <xyz>0 0 1</xyz>
        <limit>
          <lower>0</lower>
          <upper>1.65</upper>
          <effort>15</effort>
          <velocity>20</velocity>
        </limit>
        <dynamics>
          <damping>0</damping>
          <friction>0.5</friction>
          <spring_reference>0</spring_reference>
          <spring_stiffness>0</spring_stiffness>
        </dynamics>
      </axis>
      <physics>
        <implicit_spring_damper> true </implicit_spring_damper>
      </physics>
    </joint>
    <link name='link_1'>
      <pose relative_to='joint_1_0'>0 0 0 0 -0 0</pose>
      <inertial>
        <pose>0.027039 -0.000297 0.012126 0 -0 0</pose>
        <mass>0.0561213</mass>
        <inertia>
          <ixx>8.35167e-06</ixx>
          <ixy>-6.64708e-08</ixy>
          <ixz>-1.70712e-08</ixz>
          <iyy>2.46927e-05</iyy>
          <iyz>-1.03911e-07</iyz>
          <izz>2.41233e-05</izz>
        </inertia>
      </inertial>
      <collision name='link_1_collision'>
        <pose>-0.018269 0 -0.031781 0 1.48353 -3.14159</pose>
        <geometry>
          <mesh>
            <scale>1 1 1</scale>
            <uri>model://allegro_hand_description/meshes/p2_r6.stl</uri>
          </mesh>
        </geometry>
        <surface>
          <contact>
            <ode>
              <max_vel>10</max_vel>
              <min_depth>0.001</min_depth>
            </ode>
          </contact>
        </surface>
        <max_contacts>1000</max_contacts>
      </collision>
      <collision name='link_1_fixed_joint_lump__ipb_bracket_collision_1'>
        <pose>0 0 0.0113 5e-06 -0 0</pose>
        <geometry>
          <mesh>
            <scale>1 1 1</scale>
            <uri>model://allegro_hand_description/meshes/proximal_back.stl</uri>
          </mesh>
        </geometry>
        <surface>
          <contact>
            <ode>
              <max_vel>10</max_vel>
              <min_depth>0.001</min_depth>
            </ode>
          </contact>
        </surface>
        <max_contacts>1000</max_contacts>
      </collision>
      <collision name='ipb_fpcb'>
        <pose>0 -0 0.0113 -5e-06 -0 0</pose>
        <geometry>
          <mesh>
            <scale>1 1 1</scale>
            <uri>model://allegro_hand_description/meshes/proximal_back_fpcb.stl</uri>
          </mesh>
        </geometry>
        <surface>
          <contact>
            <ode>
              <max_vel>10</max_vel>
              <min_depth>0.001</min_depth>
            </ode>
          </contact>
        </surface>
        <max_contacts>1000</max_contacts>
      </collision>
<!--******************************************* -->
        <sensor name='ipb' type='contact'>
          <contact>
            <collision>ipb_fpcb</collision>
          </contact>
        <update_rate> 5 </update_rate>
        <visualize> true </visualize>
        </sensor>    
<!--******************************************* -->
      <collision name='link_1_fixed_joint_lump__ipf_bracket_collision_3'>
        <pose>-0 -0 0.0123 0 -0 -0</pose>
        <geometry>
          <mesh>
            <scale>1 1 1</scale>
            <uri>model://allegro_hand_description/meshes/proximal_front.stl</uri>
          </mesh>
        </geometry>
        <surface>
          <contact>
            <ode>
              <max_vel>10</max_vel>
              <min_depth>0.001</min_depth>
            </ode>
          </contact>
        </surface>
        <max_contacts>1000</max_contacts>
      </collision>
      <collision name='ipf_fpcb'>
        <pose>-0 0 0.0123 0 -0 -0</pose>
        <geometry>
          <mesh>
            <scale>1 1 1</scale>
            <uri>model://allegro_hand_description/meshes/proximal_frontfpcb.stl</uri>
          </mesh>
        </geometry>
        <surface>
          <contact>
            <ode>
              <max_vel>10</max_vel>
              <min_depth>0.001</min_depth>
            </ode>
          </contact>
        </surface>
        <max_contacts>1000</max_contacts>
      </collision>
<!--******************************************* -->
        <sensor name='ipf' type='contact'>
          <contact>
            <collision>ipf_fpcb</collision>
          </contact>
        <update_rate> 5 </update_rate>
        <visualize> true </visualize>
        </sensor>    
<!--******************************************* -->
      <visual name='link_1_visual'>
        <pose>-0.018269 0 -0.031781 0 1.48353 -3.14159</pose>
        <geometry>
          <mesh>
            <scale>1 1 1</scale>
            <uri>model://allegro_hand_description/meshes/p2_r6.stl</uri>
          </mesh>
        </geometry>
      </visual>
      <visual name='link_1_fixed_joint_lump__ipb_bracket_visual_1'>
        <pose>0 0 0.0113 5e-06 -0 0</pose>
        <geometry>
          <mesh>
            <scale>1 1 1</scale>
            <uri>model://allegro_hand_description/meshes/proximal_back.stl</uri>
          </mesh>
        </geometry>
      </visual>
      <visual name='link_1_fixed_joint_lump__index_proximal_back_fpcb_visual_2'>
        <pose>0 -0 0.0113 -5e-06 -0 0</pose>
        <geometry>
          <mesh>
            <scale>1 1 1</scale>
            <uri>model://allegro_hand_description/meshes/proximal_back_fpcb.stl</uri>
          </mesh>
        </geometry>
      </visual>
      <visual name='link_1_fixed_joint_lump__ipf_bracket_visual_3'>
        <pose>-0 -0 0.0123 0 -0 -0</pose>
        <geometry>
          <mesh>
            <scale>1 1 1</scale>
            <uri>model://allegro_hand_description/meshes/proximal_front.stl</uri>
          </mesh>
        </geometry>
      </visual>
      <visual name='link_1_fixed_joint_lump__index_proximal_front_fpcb_visual_4'>
        <pose>-0 0 0.0123 0 -0 -0</pose>
        <geometry>
          <mesh>
            <scale>1 1 1</scale>
            <uri>model://allegro_hand_description/meshes/proximal_frontfpcb.stl</uri>
          </mesh>
        </geometry>
      </visual>
      <self_collide>true</self_collide>
    </link>
    <joint name='joint_2_0' type='revolute'>
      <pose relative_to='link_1'>0.054 0 0 -0 0 -3.14159</pose>
      <parent>link_1</parent>
      <child>link_2</child>
      <axis>
        <xyz>0 0 1</xyz>
        <limit>
          <lower>0</lower>
          <upper>1.5</upper>
          <effort>15</effort>
          <velocity>20</velocity>
        </limit>
        <dynamics>
          <damping>0</damping>
          <friction>0.5</friction>
          <spring_reference>0</spring_reference>
          <spring_stiffness>0</spring_stiffness>
        </dynamics>
      </axis>
      <physics>
        <implicit_spring_damper> true </implicit_spring_damper>
      </physics>
    </joint>
    <link name='link_2'>
      <pose relative_to='joint_2_0'>0 0 0 0 -0 0</pose>
      <inertial>
        <pose>-0.028729 0.000348 0.012141 0 -0 0</pose>
        <mass>0.0437084</mass>
        <inertia>
          <ixx>7.32067e-06</ixx>
          <ixy>1.9129e-07</ixy>
          <ixz>6.50558e-07</ixz>
          <iyy>1.32067e-05</iyy>
          <iyz>1.79468e-07</iyz>
          <izz>1.13788e-05</izz>
        </inertia>
      </inertial>
      <collision name='link_2_collision'>
        <pose>0.072269 -0 -0.031781 -0 1.48353 -0</pose>
        <geometry>
          <mesh>
            <scale>1 1 1</scale>
            <uri>model://allegro_hand_description/meshes/extended_fingertop.stl</uri>
          </mesh>
        </geometry>
        <surface>
          <contact>
            <ode>
              <max_vel>10</max_vel>
              <min_depth>0.001</min_depth>
            </ode>
          </contact>
        </surface>
        <max_contacts>1000</max_contacts>
      </collision>
      <collision name='link_2_fixed_joint_lump__imb_bracket_collision_1'>
        <pose>0.054 0 0.0119 0 0 -3.14159</pose>
        <geometry>
          <mesh>
            <scale>1 1 1</scale>
            <uri>model://allegro_hand_description/meshes/medial_back.stl</uri>
          </mesh>
        </geometry>
        <surface>
          <contact>
            <ode>
              <max_vel>10</max_vel>
              <min_depth>0.001</min_depth>
            </ode>
          </contact>
        </surface>
        <max_contacts>1000</max_contacts>
      </collision>
      <collision name='imb_fpcb'>
        <pose>0.054 1e-06 0.0119 -6e-06 -4e-06 -3.14159</pose>
        <geometry>
          <mesh>
            <scale>1 1 1</scale>
            <uri>model://allegro_hand_description/meshes/medial_back_fpcb.stl</uri>
          </mesh>
        </geometry>
        <surface>
          <contact>
            <ode>
              <max_vel>10</max_vel>
              <min_depth>0.001</min_depth>
            </ode>
          </contact>
        </surface>
        <max_contacts>1000</max_contacts>
      </collision>
<!--******************************************* -->
        <sensor name='imb' type='contact'>
          <contact>
            <collision>imb_fpcb</collision>
          </contact>
        <update_rate> 5 </update_rate>
        <visualize> true </visualize>
        </sensor>    
<!--******************************************* -->
      <collision name='link_2_fixed_joint_lump__imf_bracket_collision_3'>
        <pose>0.054 -0 0.0119 0 0 3.14159</pose>
        <geometry>
          <mesh>
            <scale>1 1 1</scale>
            <uri>model://allegro_hand_description/meshes/medial_front.stl</uri>
          </mesh>
        </geometry>
        <surface>
          <contact>
            <ode>
              <max_vel>10</max_vel>
              <min_depth>0.001</min_depth>
            </ode>
          </contact>
        </surface>
        <max_contacts>1000</max_contacts>
      </collision>
      <collision name='imf_fpcb'>
        <pose>0.054 0 0.0119 -4e-06 4e-06 3.14159</pose>
        <geometry>
          <mesh>
            <scale>1 1 1</scale>
            <uri>model://allegro_hand_description/meshes/medial_front_fpcb.stl</uri>
          </mesh>
        </geometry>
        <surface>
          <contact>
            <ode>
              <max_vel>10</max_vel>
              <min_depth>0.001</min_depth>
            </ode>
          </contact>
        </surface>
        <max_contacts>1000</max_contacts>
      </collision>
<!--******************************************* -->
        <sensor name='imf' type='contact'>
          <contact>
            <collision>imf_fpcb</collision>
          </contact>
        <update_rate> 5 </update_rate>
        <visualize> true </visualize>
        </sensor>    
<!--******************************************* -->
      <visual name='link_2_visual'>
        <pose>0.072269 -0 -0.031781 -0 1.48353 -0</pose>
        <geometry>
          <mesh>
            <scale>1 1 1</scale>
            <uri>model://allegro_hand_description/meshes/extended_fingertop.stl</uri>
          </mesh>
        </geometry>
      </visual>
      <visual name='link_2_fixed_joint_lump__imb_bracket_visual_1'>
        <pose>0.054 0 0.0119 0 0 -3.14159</pose>
        <geometry>
          <mesh>
            <scale>1 1 1</scale>
            <uri>model://allegro_hand_description/meshes/medial_back.stl</uri>
          </mesh>
        </geometry>
      </visual>
      <visual name='link_2_fixed_joint_lump__index_medial_back_fpcb_visual_2'>
        <pose>0.054 1e-06 0.0119 -6e-06 -4e-06 -3.14159</pose>
        <geometry>
          <mesh>
            <scale>1 1 1</scale>
            <uri>model://allegro_hand_description/meshes/medial_back_fpcb.stl</uri>
          </mesh>
        </geometry>
      </visual>
      <visual name='link_2_fixed_joint_lump__imf_bracket_visual_3'>
        <pose>0.054 -0 0.0119 0 0 3.14159</pose>
        <geometry>
          <mesh>
            <scale>1 1 1</scale>
            <uri>model://allegro_hand_description/meshes/medial_front.stl</uri>
          </mesh>
        </geometry>
      </visual>
      <visual name='link_2_fixed_joint_lump__index_medial_front_fpcb_visual_4'>
        <pose>0.054 0 0.0119 -4e-06 4e-06 3.14159</pose>
        <geometry>
          <mesh>
            <scale>1 1 1</scale>
            <uri>model://allegro_hand_description/meshes/medial_front_fpcb.stl</uri>
          </mesh>
        </geometry>
      </visual>
      <self_collide>true</self_collide>
    </link>
    <joint name='joint_3_0' type='revolute'>
      <pose relative_to='link_2'>-0.04615 0 0.0001 -0 0 -0</pose>
      <parent>link_2</parent>
      <child>link_3</child>
      <axis>
        <xyz>0 0 1</xyz>
        <limit>
          <lower>0</lower>
          <upper>2.5</upper>
          <effort>15</effort>
          <velocity>20</velocity>
        </limit>
        <dynamics>
          <damping>0</damping>
          <friction>0.5</friction>
          <spring_reference>0</spring_reference>
          <spring_stiffness>0</spring_stiffness>
        </dynamics>
      </axis>
      <physics>
        <implicit_spring_damper> true </implicit_spring_damper>
      </physics>
    </joint>
    <link name='link_3'>
      <pose relative_to='joint_3_0'>0 0 0 0 -0 0</pose>
      <inertial>
        <pose>-0.024577 0.002729 0.012009 0 -0 0</pose>
        <mass>0.0270564</mass>
        <inertia>
          <ixx>5.23237e-06</ixx>
          <ixy>9.55197e-07</ixy>
          <ixz>-7.21036e-08</ixz>
          <iyy>1.08492e-05</iyy>
          <iyz>8.1688e-09</iyz>
          <izz>8.7254e-06</izz>
        </inertia>
      </inertial>
      <collision name='link_3_collision'>
        <pose>0.1253 -0 0.0118 -3.14159 -0 -1.5708</pose>
        <geometry>
          <mesh>
            <scale>1 1 1</scale>
            <uri>model://allegro_hand_description/meshes/p4_r.stl</uri>
          </mesh>
        </geometry>
        <surface>
          <contact>
            <ode>
              <max_vel>10</max_vel>
              <min_depth>0.001</min_depth>
            </ode>
          </contact>
        </surface>
        <max_contacts>1000</max_contacts>
      </collision>
      <collision name='link_3_fixed_joint_lump__ift_bracket_collision_1'>
        <pose>0.1004 -0 0.0119 0 -0 3.14159</pose>
        <geometry>
          <mesh>
            <scale>1 1 1</scale>
            <uri>model://allegro_hand_description/meshes/distal_pcbbase.stl</uri>
          </mesh>
        </geometry>
        <surface>
          <contact>
            <ode>
              <max_vel>10</max_vel>
              <min_depth>0.001</min_depth>
            </ode>
          </contact>
        </surface>
        <max_contacts>1000</max_contacts>
      </collision>
      <collision name='ift_fpcb'>
        <pose>0.1004 -0 0.0119 0 0 3.14159</pose>
        <geometry>
          <mesh>
            <scale>1 1 1</scale>
            <uri>model://allegro_hand_description/meshes/distal_fpcb_1.stl</uri>
          </mesh>
        </geometry>
        <surface>
          <contact>
            <ode>
              <max_vel>10</max_vel>
              <min_depth>0.001</min_depth>
            </ode>
          </contact>
        </surface>
        <max_contacts>1000</max_contacts>
      </collision>
<!--******************************************* -->
        <sensor name='ift' type='contact'>
          <contact>
            <collision>ift_fpcb</collision>
          </contact>
        <update_rate> 5 </update_rate>
        <visualize> true </visualize>
        </sensor>    
<!--******************************************* -->
      <collision name='link_3_fixed_joint_lump__index_fingertip_side_fpcb_collision_3'>
        <pose>0.1004 -0 0.011899 0 -0 3.14159</pose>
        <geometry>
          <mesh>
            <scale>1 1 1</scale>
            <uri>model://allegro_hand_description/meshes/distal_fpcb_2.stl</uri>
          </mesh>
        </geometry>
        <surface>
          <contact>
            <ode>
              <max_vel>10</max_vel>
              <min_depth>0.001</min_depth>
            </ode>
          </contact>
        </surface>
        <max_contacts>1000</max_contacts>
      </collision>
      <visual name='link_3_visual'>
        <pose>0.1253 -0 0.0118 -3.14159 -0 -1.5708</pose>
        <geometry>
          <mesh>
            <scale>1 1 1</scale>
            <uri>model://allegro_hand_description/meshes/p4_r.stl</uri>
          </mesh>
        </geometry>
      </visual>
      <visual name='link_3_fixed_joint_lump__ift_bracket_visual_1'>
        <pose>0.1004 -0 0.0119 0 -0 3.14159</pose>
        <geometry>
          <mesh>
            <scale>1 1 1</scale>
            <uri>model://allegro_hand_description/meshes/distal_pcbbase.stl</uri>
          </mesh>
        </geometry>
      </visual>
      <visual name='link_3_fixed_joint_lump__index_fingertip_main_fpcb_visual_2'>
        <pose>0.1004 -0 0.0119 0 0 3.14159</pose>
        <geometry>
          <mesh>
            <scale>1 1 1</scale>
            <uri>model://allegro_hand_description/meshes/distal_fpcb_1.stl</uri>
          </mesh>
        </geometry>
      </visual>
      <visual name='link_3_fixed_joint_lump__index_fingertip_side_fpcb_visual_3'>
        <pose>0.1004 -0 0.011899 0 -0 3.14159</pose>
        <geometry>
          <mesh>
            <scale>1 1 1</scale>
            <uri>model://allegro_hand_description/meshes/distal_fpcb_2.stl</uri>
          </mesh>
        </geometry>
      </visual>
      <self_collide>true</self_collide>
    </link>
    <joint name='joint_12_0' type='revolute'>
      <pose relative_to='wrist_3_link'>-0.016121 -0.0252 0.030148 -3.14159 -0.087267 0</pose>
      <parent>wrist_3_link</parent>
      <child>link_12</child>
      <axis>
        <xyz>0 0 1</xyz>
        <limit>
          <lower>0.35</lower>
          <upper>1.57</upper>
          <effort>15</effort>
          <velocity>20</velocity>
        </limit>
        <dynamics>
          <damping>0</damping>
          <friction>0.5</friction>
          <spring_reference>0</spring_reference>
          <spring_stiffness>0</spring_stiffness>
        </dynamics>
      </axis>
      <physics>
        <implicit_spring_damper> true </implicit_spring_damper>
      </physics>
    </joint>
    <link name='link_12'>
      <pose relative_to='joint_12_0'>0 0 0 0 -0 0</pose>
      <inertial>
        <pose>-0.015116 -0.009058 -0.01923 0 -0 0</pose>
        <mass>0.0660275</mass>
        <inertia>
          <ixx>1.44344e-05</ixx>
          <ixy>1.24597e-06</ixy>
          <ixz>3.47822e-08</ixz>
          <iyy>1.76386e-05</iyy>
          <iyz>6.49531e-07</iyz>
          <izz>1.41981e-05</izz>
        </inertia>
      </inertial>
      <collision name='link_12_collision'>
        <pose>0.023281 -0.0182 -0.080831 -0 -0.087267 -0</pose>
        <geometry>
          <mesh>
            <scale>1 1 1</scale>
            <uri>model://allegro_hand_description/meshes/f1_r.stl</uri>
          </mesh>
        </geometry>
        <surface>
          <contact>
            <ode>
              <max_vel>10</max_vel>
              <min_depth>0.001</min_depth>
            </ode>
          </contact>
        </surface>
        <max_contacts>1000</max_contacts>
      </collision>
      <visual name='link_12_visual'>
        <pose>0.023281 -0.0182 -0.080831 -0 -0.087267 -0</pose>
        <geometry>
          <mesh>
            <scale>1 1 1</scale>
            <uri>model://allegro_hand_description/meshes/f1_r.stl</uri>
          </mesh>
        </geometry>
      </visual>
      <self_collide>true</self_collide>
    </link>
    <joint name='joint_13_0' type='revolute'>
      <pose relative_to='link_12'>-0.0375 -0.005 -0.0092 -1.5708 -0 1.5708</pose>
      <parent>link_12</parent>
      <child>link_13</child>
      <axis>
        <xyz>0 0 1</xyz>
        <limit>
          <lower>-1.3</lower>
          <upper>1.15</upper>
          <effort>15</effort>
          <velocity>20</velocity>
        </limit>
        <dynamics>
          <damping>0</damping>
          <friction>0.5</friction>
          <spring_reference>0</spring_reference>
          <spring_stiffness>0</spring_stiffness>
        </dynamics>
      </axis>
      <physics>
        <implicit_spring_damper> true </implicit_spring_damper>
      </physics>
    </joint>
    <link name='link_13'>
      <pose relative_to='joint_13_0'>0 0 0 0 -0 0</pose>
      <inertial>
        <pose>-0.000666 -0.000413 0.009606 0 -0 0</pose>
        <mass>0.0136672</mass>
        <inertia>
          <ixx>1.671e-06</ixx>
          <ixy>6.13056e-08</ixy>
          <ixz>7.9563e-08</ixz>
          <iyy>1.24411e-06</iyy>
          <iyz>5.86704e-10</iyz>
          <izz>2.13441e-06</izz>
        </inertia>
      </inertial>
      <collision name='link_13_collision'>
        <pose>-0 0 -0.0152 1.5708 -0 1.5708</pose>
        <geometry>
          <mesh>
            <scale>1 1 1</scale>
            <uri>model://allegro_hand_description/meshes/extended_finger_base.stl</uri>
          </mesh>
        </geometry>
        <surface>
          <contact>
            <ode>
              <max_vel>10</max_vel>
              <min_depth>0.001</min_depth>
            </ode>
          </contact>
        </surface>
        <max_contacts>1000</max_contacts>
      </collision>
      <visual name='link_13_visual'>
        <pose>-0 0 -0.0152 1.5708 -0 1.5708</pose>
        <geometry>
          <mesh>
            <scale>1 1 1</scale>
            <uri>model://allegro_hand_description/meshes/extended_finger_base.stl</uri>
          </mesh>
        </geometry>
      </visual>
      <self_collide>true</self_collide>
    </link>
    <joint name='joint_14_0' type='revolute'>
      <pose relative_to='link_13'>0.0119 -0 0.02545 -3e-06 1.57079 3.14159</pose>
      <parent>link_13</parent>
      <child>link_14</child>
      <axis>
        <xyz>0 0 1</xyz>
        <limit>
          <lower>0</lower>
          <upper>1.45</upper>
          <effort>15</effort>
          <velocity>20</velocity>
        </limit>
        <dynamics>
          <damping>0</damping>
          <friction>0.5</friction>
          <spring_reference>0</spring_reference>
          <spring_stiffness>0</spring_stiffness>
        </dynamics>
      </axis>
      <physics>
        <implicit_spring_damper> true </implicit_spring_damper>
      </physics>
    </joint>
    <link name='link_14'>
      <pose relative_to='joint_14_0'>0 0 0 0 -0 0</pose>
      <inertial>
        <pose>-0.017391 0.000674 0.012202 0 -0 0</pose>
        <mass>0.0406337</mass>
        <inertia>
          <ixx>6.1952e-06</ixx>
          <ixy>-7.73474e-07</ixy>
          <ixz>4.92157e-07</ixz>
          <iyy>1.18659e-05</iyy>
          <iyz>-5.30289e-07</iyz>
          <izz>1.08348e-05</izz>
        </inertia>
      </inertial>
      <collision name='link_14_collision'>
        <pose>0.078781 -0.071631 0.0251 -1.5708 -0 0.087267</pose>
        <geometry>
          <mesh>
            <scale>1 1 1</scale>
            <uri>model://allegro_hand_description/meshes/f3_r.stl</uri>
          </mesh>
        </geometry>
        <surface>
          <contact>
            <ode>
              <max_vel>10</max_vel>
              <min_depth>0.001</min_depth>
            </ode>
          </contact>
        </surface>
        <max_contacts>1000</max_contacts>
      </collision>
      <collision name='link_14_fixed_joint_lump__tmb_bracket_collision_1'>
        <pose>0.008 -0 0.0118 1.5708 -0 -1.5708</pose>
        <geometry>
          <mesh>
            <scale>1 1 1</scale>
            <uri>model://allegro_hand_description/meshes/thumb_medial_back_bracket.stl</uri>
          </mesh>
        </geometry>
        <surface>
          <contact>
            <ode>
              <max_vel>10</max_vel>
              <min_depth>0.001</min_depth>
            </ode>
          </contact>
        </surface>
        <max_contacts>1000</max_contacts>
      </collision>
      <collision name='tmb_fpcb'>
        <pose>0.008 -0 0.0118 1.57079 -0 -1.5708</pose>
        <geometry>
          <mesh>
            <scale>1 1 1</scale>
            <uri>model://allegro_hand_description/meshes/part_5.stl</uri>
          </mesh>
        </geometry>
        <surface>
          <contact>
            <ode>
              <max_vel>10</max_vel>
              <min_depth>0.001</min_depth>
            </ode>
          </contact>
        </surface>
        <max_contacts>1000</max_contacts>
      </collision>
<!--******************************************* -->
        <sensor name='tmb' type='contact'>
          <contact>
            <collision>tmb_fpcb</collision>
          </contact>
        <update_rate> 5 </update_rate>
        <visualize> true </visualize>
        </sensor>    
<!--******************************************* -->
      <collision name='link_14_fixed_joint_lump__tmf_bracket_collision_3'>
        <pose>0.008 -0 0.0118 1.57079 0 -1.5708</pose>
        <geometry>
          <mesh>
            <scale>1 1 1</scale>
            <uri>model://allegro_hand_description/meshes/thumb_medial_front_bracket.stl</uri>
          </mesh>
        </geometry>
        <surface>
          <contact>
            <ode>
              <max_vel>10</max_vel>
              <min_depth>0.001</min_depth>
            </ode>
          </contact>
        </surface>
        <max_contacts>1000</max_contacts>
      </collision>
      <collision name='tmf_fpcb'>
        <pose>0.008 -0 0.0118 1.57079 0 -1.5708</pose>
        <geometry>
          <mesh>
            <scale>1 1 1</scale>
            <uri>model://allegro_hand_description/meshes/part_6.stl</uri>
          </mesh>
        </geometry>
        <surface>
          <contact>
            <ode>
              <max_vel>10</max_vel>
              <min_depth>0.001</min_depth>
            </ode>
          </contact>
        </surface>
        <max_contacts>1000</max_contacts>
      </collision>
<!--******************************************* -->
        <sensor name='tmf' type='contact'>
          <contact>
            <collision>tmf_fpcb</collision>
          </contact>
        <update_rate> 5 </update_rate>
        <visualize> true </visualize>
        </sensor>    
<!--******************************************* -->
      <visual name='link_14_visual'>
        <pose>0.078781 -0.071631 0.0251 -1.5708 -0 0.087267</pose>
        <geometry>
          <mesh>
            <scale>1 1 1</scale>
            <uri>model://allegro_hand_description/meshes/f3_r.stl</uri>
          </mesh>
        </geometry>
      </visual>
      <visual name='link_14_fixed_joint_lump__tmb_bracket_visual_1'>
        <pose>0.008 -0 0.0118 1.5708 -0 -1.5708</pose>
        <geometry>
          <mesh>
            <scale>1 1 1</scale>
            <uri>model://allegro_hand_description/meshes/thumb_medial_back_bracket.stl</uri>
          </mesh>
        </geometry>
      </visual>
      <visual name='link_14_fixed_joint_lump__thumb_medial_back_fpcb_visual_2'>
        <pose>0.008 -0 0.0118 1.57079 -0 -1.5708</pose>
        <geometry>
          <mesh>
            <scale>1 1 1</scale>
            <uri>model://allegro_hand_description/meshes/part_5.stl</uri>
          </mesh>
        </geometry>
      </visual>
      <visual name='link_14_fixed_joint_lump__tmf_bracket_visual_3'>
        <pose>0.008 -0 0.0118 1.57079 0 -1.5708</pose>
        <geometry>
          <mesh>
            <scale>1 1 1</scale>
            <uri>model://allegro_hand_description/meshes/thumb_medial_front_bracket.stl</uri>
          </mesh>
        </geometry>
      </visual>
      <visual name='link_14_fixed_joint_lump__thumb_medial_front_fpcb_visual_4'>
        <pose>0.008 -0 0.0118 1.57079 0 -1.5708</pose>
        <geometry>
          <mesh>
            <scale>1 1 1</scale>
            <uri>model://allegro_hand_description/meshes/part_6.stl</uri>
          </mesh>
        </geometry>
      </visual>
      <self_collide>true</self_collide>
    </link>
    <joint name='joint_15_0' type='revolute'>
      <pose relative_to='link_14'>-0.0514 -0 -0.0001 -0 0 0</pose>
      <parent>link_14</parent>
      <child>link_15</child>
      <axis>
        <xyz>0 0 1</xyz>
        <limit>
          <lower>0</lower>
          <upper>1.7</upper>
          <effort>15</effort>
          <velocity>20</velocity>
        </limit>
        <dynamics>
          <damping>0</damping>
          <friction>0.5</friction>
          <spring_reference>0</spring_reference>
          <spring_stiffness>0</spring_stiffness>
        </dynamics>
      </axis>
      <physics>
        <implicit_spring_damper> true </implicit_spring_damper>
      </physics>
    </joint>
    <link name='link_15'>
      <pose relative_to='joint_15_0'>0 0 0 0 -0 0</pose>
      <inertial>
        <pose>-0.026328 0.0013 0.012042 0 -0 0</pose>
        <mass>0.0509128</mass>
        <inertia>
          <ixx>7.08319e-06</ixx>
          <ixy>1.59687e-06</ixy>
          <ixz>2.31094e-07</ixz>
          <iyy>2.54765e-05</iyy>
          <iyz>7.51244e-08</iyz>
          <izz>2.32319e-05</izz>
        </inertia>
      </inertial>
      <collision name='link_15_collision'>
        <pose>0.13018 -0.071631 0.0252 -1.5708 -0 0.087267</pose>
        <geometry>
          <mesh>
            <scale>1 1 1</scale>
            <uri>model://allegro_hand_description/meshes/f4_r.stl</uri>
          </mesh>
        </geometry>
        <surface>
          <contact>
            <ode>
              <max_vel>10</max_vel>
              <min_depth>0.001</min_depth>
            </ode>
          </contact>
        </surface>
        <max_contacts>1000</max_contacts>
      </collision>
      <collision name='link_15_fixed_joint_lump__tft_bracket_collision_1'>
        <pose>0.0848 -0.0003 0.0118 -0 0 -3.14159</pose>
        <geometry>
          <mesh>
            <scale>1 1 1</scale>
            <uri>model://allegro_hand_description/meshes/distal_pcbbase.stl</uri>
          </mesh>
        </geometry>
        <surface>
          <contact>
            <ode>
              <max_vel>10</max_vel>
              <min_depth>0.001</min_depth>
            </ode>
          </contact>
        </surface>
        <max_contacts>1000</max_contacts>
      </collision>
      <collision name='tft_fpcb'>
        <pose>0.0848 -0.0003 0.0118 0 0 -3.14159</pose>
        <geometry>
          <mesh>
            <scale>1 1 1</scale>
            <uri>model://allegro_hand_description/meshes/distal_fpcb_1.stl</uri>
          </mesh>
        </geometry>
        <surface>
          <contact>
            <ode>
              <max_vel>10</max_vel>
              <min_depth>0.001</min_depth>
            </ode>
          </contact>
        </surface>
        <max_contacts>1000</max_contacts>
      </collision>
<!--******************************************* -->
        <sensor name='tft' type='contact'>
          <contact>
            <collision>tft_fpcb</collision>
          </contact>
        <update_rate> 5 </update_rate>
        <visualize> true </visualize>
        </sensor>    
<!--******************************************* -->
      <collision name='link_15_fixed_joint_lump__thumb_fingertip_side_fpcb_collision_3'>
        <pose>0.0848 -0.0003 0.011799 -0 0 -3.14159</pose>
        <geometry>
          <mesh>
            <scale>1 1 1</scale>
            <uri>model://allegro_hand_description/meshes/distal_fpcb_2.stl</uri>
          </mesh>
        </geometry>
        <surface>
          <contact>
            <ode>
              <max_vel>10</max_vel>
              <min_depth>0.001</min_depth>
            </ode>
          </contact>
        </surface>
        <max_contacts>1000</max_contacts>
      </collision>
      <visual name='link_15_visual'>
        <pose>0.13018 -0.071631 0.0252 -1.5708 -0 0.087267</pose>
        <geometry>
          <mesh>
            <scale>1 1 1</scale>
            <uri>model://allegro_hand_description/meshes/f4_r.stl</uri>
          </mesh>
        </geometry>
      </visual>
      <visual name='link_15_fixed_joint_lump__tft_bracket_visual_1'>
        <pose>0.0848 -0.0003 0.0118 -0 0 -3.14159</pose>
        <geometry>
          <mesh>
            <scale>1 1 1</scale>
            <uri>model://allegro_hand_description/meshes/distal_pcbbase.stl</uri>
          </mesh>
        </geometry>
      </visual>
      <visual name='link_15_fixed_joint_lump__thumb_fingertip_main_fpcb_visual_2'>
        <pose>0.0848 -0.0003 0.0118 0 0 -3.14159</pose>
        <geometry>
          <mesh>
            <scale>1 1 1</scale>
            <uri>model://allegro_hand_description/meshes/distal_fpcb_1.stl</uri>
          </mesh>
        </geometry>
      </visual>
      <visual name='link_15_fixed_joint_lump__thumb_fingertip_side_fpcb_visual_3'>
        <pose>0.0848 -0.0003 0.011799 -0 0 -3.14159</pose>
        <geometry>
          <mesh>
            <scale>1 1 1</scale>
            <uri>model://allegro_hand_description/meshes/distal_fpcb_2.stl</uri>
          </mesh>
        </geometry>
      </visual>
      <self_collide>true</self_collide>
    </link>
    <joint name='joint_4_0' type='revolute'>
      <pose relative_to='wrist_3_link'>-0 -0.007 0.1117 -0 0 1.5708</pose>
      <parent>wrist_3_link</parent>
      <child>link_4</child>
      <axis>
        <xyz>0 0 1</xyz>
        <limit>
          <lower>-0.55</lower>
          <upper>0.45</upper>
          <effort>15</effort>
          <velocity>20</velocity>
        </limit>
        <dynamics>
          <damping>0</damping>
          <friction>0.5</friction>
          <spring_reference>0</spring_reference>
          <spring_stiffness>0</spring_stiffness>
        </dynamics>
      </axis>
      <physics>
        <implicit_spring_damper> true </implicit_spring_damper>
      </physics>
    </joint>
    <link name='link_4'>
      <pose relative_to='joint_4_0'>0 0 0 0 -0 0</pose>
      <inertial>
        <pose>-0.000413 0.000666 0.009606 0 -0 0</pose>
        <mass>0.0136672</mass>
        <inertia>
          <ixx>2.13441e-06</ixx>
          <ixy>5.86704e-10</ixy>
          <ixz>-7.9563e-08</ixz>
          <iyy>1.24411e-06</iyy>
          <iyz>-6.13056e-08</iyz>
          <izz>1.671e-06</izz>
        </inertia>
      </inertial>
      <collision name='link_4_collision'>
        <pose>0 -0 -0.0152 1.5708 -0 0</pose>
        <geometry>
          <mesh>
            <scale>1 1 1</scale>
            <uri>model://allegro_hand_description/meshes/extended_finger_base.stl</uri>
          </mesh>
        </geometry>
        <surface>
          <contact>
            <ode>
              <max_vel>10</max_vel>
              <min_depth>0.001</min_depth>
            </ode>
          </contact>
        </surface>
        <max_contacts>1000</max_contacts>
      </collision>
      <visual name='link_4_visual'>
        <pose>0 -0 -0.0152 1.5708 -0 0</pose>
        <geometry>
          <mesh>
            <scale>1 1 1</scale>
            <uri>model://allegro_hand_description/meshes/extended_finger_base.stl</uri>
          </mesh>
        </geometry>
      </visual>
      <self_collide>true</self_collide>
    </link>
    <joint name='joint_5_0' type='revolute'>
      <pose relative_to='link_4'>-0 -0.0119 0.02545 1.57079 1.57079 -3.14159</pose>
      <parent>link_4</parent>
      <child>link_5</child>
      <axis>
        <xyz>0 0 1</xyz>
        <limit>
          <lower>0</lower>
          <upper>1.65</upper>
          <effort>15</effort>
          <velocity>20</velocity>
        </limit>
        <dynamics>
          <damping>0</damping>
          <friction>0.5</friction>
          <spring_reference>0</spring_reference>
          <spring_stiffness>0</spring_stiffness>
        </dynamics>
      </axis>
      <physics>
        <implicit_spring_damper> true </implicit_spring_damper>
      </physics>
    </joint>
    <link name='link_5'>
      <pose relative_to='joint_5_0'>0 0 0 0 -0 0</pose>
      <inertial>
        <pose>-0.027039 0.000297 0.012126 0 -0 0</pose>
        <mass>0.0561213</mass>
        <inertia>
          <ixx>8.79961e-06</ixx>
          <ixy>-2.75758e-08</ixy>
          <ixz>2.55745e-06</ixz>
          <iyy>2.46927e-05</iyy>
          <iyz>1.32424e-07</iyz>
          <izz>2.36754e-05</izz>
        </inertia>
      </inertial>
      <collision name='link_5_collision'>
        <pose>0.018269 0 -0.031781 0 1.48353 -0</pose>
        <geometry>
          <mesh>
            <scale>1 1 1</scale>
            <uri>model://allegro_hand_description/meshes/p2_r6.stl</uri>
          </mesh>
        </geometry>
        <surface>
          <contact>
            <ode>
              <max_vel>10</max_vel>
              <min_depth>0.001</min_depth>
            </ode>
          </contact>
        </surface>
        <max_contacts>1000</max_contacts>
      </collision>
      <collision name='link_5_fixed_joint_lump__mpb_bracket_collision_1'>
        <pose>-0 -0 0.0113 0 0 3.14159</pose>
        <geometry>
          <mesh>
            <scale>1 1 1</scale>
            <uri>model://allegro_hand_description/meshes/proximal_back.stl</uri>
          </mesh>
        </geometry>
        <surface>
          <contact>
            <ode>
              <max_vel>10</max_vel>
              <min_depth>0.001</min_depth>
            </ode>
          </contact>
        </surface>
        <max_contacts>1000</max_contacts>
      </collision>
      <collision name='mpb_fpcb'>
        <pose>-0 -0 0.0113 -5e-06 0 3.14159</pose>
        <geometry>
          <mesh>
            <scale>1 1 1</scale>
            <uri>model://allegro_hand_description/meshes/proximal_back_fpcb.stl</uri>
          </mesh>
        </geometry>
        <surface>
          <contact>
            <ode>
              <max_vel>10</max_vel>
              <min_depth>0.001</min_depth>
            </ode>
          </contact>
        </surface>
        <max_contacts>1000</max_contacts>
      </collision>
<!--******************************************* -->
        <sensor name='mpb' type='contact'>
          <contact>
            <collision>mpb_fpcb</collision>
          </contact>
        <update_rate> 5 </update_rate>
        <visualize> true </visualize>
        </sensor>    
<!--******************************************* -->
      <collision name='link_5_fixed_joint_lump__mpf_bracket_collision_3'>
        <pose>0 -0 0.0123 -0 0 3.14159</pose>
        <geometry>
          <mesh>
            <scale>1 1 1</scale>
            <uri>model://allegro_hand_description/meshes/proximal_front.stl</uri>
          </mesh>
        </geometry>
        <surface>
          <contact>
            <ode>
              <max_vel>10</max_vel>
              <min_depth>0.001</min_depth>
            </ode>
          </contact>
        </surface>
        <max_contacts>1000</max_contacts>
      </collision>
      <collision name='mpf_fpcb'>
        <pose>0 -0 0.0123 -0 0 3.14159</pose>
        <geometry>
          <mesh>
            <scale>1 1 1</scale>
            <uri>model://allegro_hand_description/meshes/proximal_frontfpcb.stl</uri>
          </mesh>
        </geometry>
        <surface>
          <contact>
            <ode>
              <max_vel>10</max_vel>
              <min_depth>0.001</min_depth>
            </ode>
          </contact>
        </surface>
        <max_contacts>1000</max_contacts>
      </collision>
<!--******************************************* -->
        <sensor name='mpf' type='contact'>
          <contact>
            <collision>mpf_fpcb</collision>
          </contact>
        <update_rate> 5 </update_rate>
        <visualize> true </visualize>
        </sensor>    
<!--******************************************* -->
      <visual name='link_5_visual'>
        <pose>0.018269 0 -0.031781 0 1.48353 -0</pose>
        <geometry>
          <mesh>
            <scale>1 1 1</scale>
            <uri>model://allegro_hand_description/meshes/p2_r6.stl</uri>
          </mesh>
        </geometry>
      </visual>
      <visual name='link_5_fixed_joint_lump__mpb_bracket_visual_1'>
        <pose>-0 -0 0.0113 0 0 3.14159</pose>
        <geometry>
          <mesh>
            <scale>1 1 1</scale>
            <uri>model://allegro_hand_description/meshes/proximal_back.stl</uri>
          </mesh>
        </geometry>
      </visual>
      <visual name='link_5_fixed_joint_lump__middle_proximal_back_fpcb_visual_2'>
        <pose>-0 -0 0.0113 -5e-06 0 3.14159</pose>
        <geometry>
          <mesh>
            <scale>1 1 1</scale>
            <uri>model://allegro_hand_description/meshes/proximal_back_fpcb.stl</uri>
          </mesh>
        </geometry>
      </visual>
      <visual name='link_5_fixed_joint_lump__mpf_bracket_visual_3'>
        <pose>0 -0 0.0123 -0 0 3.14159</pose>
        <geometry>
          <mesh>
            <scale>1 1 1</scale>
            <uri>model://allegro_hand_description/meshes/proximal_front.stl</uri>
          </mesh>
        </geometry>
      </visual>
      <visual name='link_5_fixed_joint_lump__middle_proximal_front_fpcb_visual_4'>
        <pose>0 -0 0.0123 -0 0 3.14159</pose>
        <geometry>
          <mesh>
            <scale>1 1 1</scale>
            <uri>model://allegro_hand_description/meshes/proximal_frontfpcb.stl</uri>
          </mesh>
        </geometry>
      </visual>
      <self_collide>true</self_collide>
    </link>
    <joint name='joint_6_0' type='revolute'>
      <pose relative_to='link_5'>-0.054 -0 -0 0 -0 0</pose>
      <parent>link_5</parent>
      <child>link_6</child>
      <axis>
        <xyz>0 0 1</xyz>
        <limit>
          <lower>0</lower>
          <upper>1.5</upper>
          <effort>15</effort>
          <velocity>20</velocity>
        </limit>
        <dynamics>
          <damping>0</damping>
          <friction>0.5</friction>
          <spring_reference>0</spring_reference>
          <spring_stiffness>0</spring_stiffness>
        </dynamics>
      </axis>
      <physics>
        <implicit_spring_damper> true </implicit_spring_damper>
      </physics>
    </joint>
    <link name='link_6'>
      <pose relative_to='joint_6_0'>0 0 0 0 -0 0</pose>
      <inertial>
        <pose>-0.028729 0.000348 0.012141 0 -0 0</pose>
        <mass>0.0437084</mass>
        <inertia>
          <ixx>7.32067e-06</ixx>
          <ixy>1.91294e-07</ixy>
          <ixz>6.50557e-07</ixz>
          <iyy>1.32067e-05</iyy>
          <iyz>1.79464e-07</iyz>
          <izz>1.13788e-05</izz>
        </inertia>
      </inertial>
      <collision name='link_6_collision'>
        <pose>0.072269 -0 -0.031781 -0 1.48353 0</pose>
        <geometry>
          <mesh>
            <scale>1 1 1</scale>
            <uri>model://allegro_hand_description/meshes/extended_fingertop.stl</uri>
          </mesh>
        </geometry>
        <surface>
          <contact>
            <ode>
              <max_vel>10</max_vel>
              <min_depth>0.001</min_depth>
            </ode>
          </contact>
        </surface>
        <max_contacts>1000</max_contacts>
      </collision>
      <collision name='link_6_fixed_joint_lump__mmb_bracket_collision_1'>
        <pose>0.054 -0 0.0119 0 -0 3.14159</pose>
        <geometry>
          <mesh>
            <scale>1 1 1</scale>
            <uri>model://allegro_hand_description/meshes/medial_back.stl</uri>
          </mesh>
        </geometry>
        <surface>
          <contact>
            <ode>
              <max_vel>10</max_vel>
              <min_depth>0.001</min_depth>
            </ode>
          </contact>
        </surface>
        <max_contacts>1000</max_contacts>
      </collision>
      <collision name='mmb_fpcb'>
        <pose>0.054 0 0.0119 -1e-06 -4e-06 3.14159</pose>
        <geometry>
          <mesh>
            <scale>1 1 1</scale>
            <uri>model://allegro_hand_description/meshes/medial_back_fpcb.stl</uri>
          </mesh>
        </geometry>
        <surface>
          <contact>
            <ode>
              <max_vel>10</max_vel>
              <min_depth>0.001</min_depth>
            </ode>
          </contact>
        </surface>
        <max_contacts>1000</max_contacts>
      </collision>
<!--******************************************* -->
        <sensor name='mmb' type='contact'>
          <contact>
            <collision>mmb_fpcb</collision>
          </contact>
        <update_rate> 5 </update_rate>
        <visualize> true </visualize>
        </sensor>    
<!--******************************************* -->
      <collision name='link_6_fixed_joint_lump__mmf_bracket_collision_3'>
        <pose>0.054 -0 0.0119 -0 0 3.14159</pose>
        <geometry>
          <mesh>
            <scale>1 1 1</scale>
            <uri>model://allegro_hand_description/meshes/medial_front.stl</uri>
          </mesh>
        </geometry>
        <surface>
          <contact>
            <ode>
              <max_vel>10</max_vel>
              <min_depth>0.001</min_depth>
            </ode>
          </contact>
        </surface>
        <max_contacts>1000</max_contacts>
      </collision>
      <collision name='mmf_fpcb'>
        <pose>0.054 0 0.0119 -4e-06 4e-06 3.14159</pose>
        <geometry>
          <mesh>
            <scale>1 1 1</scale>
            <uri>model://allegro_hand_description/meshes/medial_front_fpcb.stl</uri>
          </mesh>
        </geometry>
        <surface>
          <contact>
            <ode>
              <max_vel>10</max_vel>
              <min_depth>0.001</min_depth>
            </ode>
          </contact>
        </surface>
        <max_contacts>1000</max_contacts>
      </collision>
<!--******************************************* -->
        <sensor name='mmf' type='contact'>
          <contact>
            <collision>mmf_fpcb</collision>
          </contact>
        <update_rate> 5 </update_rate>
        <visualize> true </visualize>
        </sensor>    
<!--******************************************* -->
      <visual name='link_6_visual'>
        <pose>0.072269 -0 -0.031781 -0 1.48353 0</pose>
        <geometry>
          <mesh>
            <scale>1 1 1</scale>
            <uri>model://allegro_hand_description/meshes/extended_fingertop.stl</uri>
          </mesh>
        </geometry>
      </visual>
      <visual name='link_6_fixed_joint_lump__mmb_bracket_visual_1'>
        <pose>0.054 -0 0.0119 0 -0 3.14159</pose>
        <geometry>
          <mesh>
            <scale>1 1 1</scale>
            <uri>model://allegro_hand_description/meshes/medial_back.stl</uri>
          </mesh>
        </geometry>
      </visual>
      <visual name='link_6_fixed_joint_lump__middle_medial_back_fpcb_visual_2'>
        <pose>0.054 0 0.0119 -1e-06 -4e-06 3.14159</pose>
        <geometry>
          <mesh>
            <scale>1 1 1</scale>
            <uri>model://allegro_hand_description/meshes/medial_back_fpcb.stl</uri>
          </mesh>
        </geometry>
      </visual>
      <visual name='link_6_fixed_joint_lump__mmf_bracket_visual_3'>
        <pose>0.054 -0 0.0119 -0 0 3.14159</pose>
        <geometry>
          <mesh>
            <scale>1 1 1</scale>
            <uri>model://allegro_hand_description/meshes/medial_front.stl</uri>
          </mesh>
        </geometry>
      </visual>
      <visual name='link_6_fixed_joint_lump__middle_medial_front_fpcb_visual_4'>
        <pose>0.054 0 0.0119 -4e-06 4e-06 3.14159</pose>
        <geometry>
          <mesh>
            <scale>1 1 1</scale>
            <uri>model://allegro_hand_description/meshes/medial_front_fpcb.stl</uri>
          </mesh>
        </geometry>
      </visual>
      <self_collide>true</self_collide>
    </link>
    <joint name='joint_7_0' type='revolute'>
      <pose relative_to='link_6'>-0.04615 0 0.0001 -0 0 0</pose>
      <parent>link_6</parent>
      <child>link_7</child>
      <axis>
        <xyz>0 0 1</xyz>
        <limit>
          <lower>0</lower>
          <upper>2.5</upper>
          <effort>15</effort>
          <velocity>20</velocity>
        </limit>
        <dynamics>
          <damping>0</damping>
          <friction>0.5</friction>
          <spring_reference>0</spring_reference>
          <spring_stiffness>0</spring_stiffness>
        </dynamics>
      </axis>
      <physics>
        <implicit_spring_damper> true </implicit_spring_damper>
      </physics>
    </joint>
    <link name='link_7'>
      <pose relative_to='joint_7_0'>0 0 0 0 -0 0</pose>
      <inertial>
        <pose>-0.024577 0.002728 0.012009 0 -0 0</pose>
        <mass>0.0270564</mass>
        <inertia>
          <ixx>5.23236e-06</ixx>
          <ixy>9.5517e-07</ixy>
          <ixz>-7.21037e-08</ixz>
          <iyy>1.08492e-05</iyy>
          <iyz>8.16974e-09</iyz>
          <izz>8.7254e-06</izz>
        </inertia>
      </inertial>
      <collision name='link_7_collision'>
        <pose>0.1253 -0 0.0118 3.14159 -0 -1.5708</pose>
        <geometry>
          <mesh>
            <scale>1 1 1</scale>
            <uri>model://allegro_hand_description/meshes/p4_r.stl</uri>
          </mesh>
        </geometry>
        <surface>
          <contact>
            <ode>
              <max_vel>10</max_vel>
              <min_depth>0.001</min_depth>
            </ode>
          </contact>
        </surface>
        <max_contacts>1000</max_contacts>
      </collision>
      <collision name='link_7_fixed_joint_lump__mft_bracket_collision_1'>
        <pose>0.1004 0 0.0119 0 -0 -3.14159</pose>
        <geometry>
          <mesh>
            <scale>1 1 1</scale>
            <uri>model://allegro_hand_description/meshes/distal_pcbbase.stl</uri>
          </mesh>
        </geometry>
        <surface>
          <contact>
            <ode>
              <max_vel>10</max_vel>
              <min_depth>0.001</min_depth>
            </ode>
          </contact>
        </surface>
        <max_contacts>1000</max_contacts>
      </collision>
      <collision name='mft_fpcb'>
        <pose>0.1004 0 0.0119 -5e-06 0 -3.14159</pose>
        <geometry>
          <mesh>
            <scale>1 1 1</scale>
            <uri>model://allegro_hand_description/meshes/distal_fpcb_1.stl</uri>
          </mesh>
        </geometry>
        <surface>
          <contact>
            <ode>
              <max_vel>10</max_vel>
              <min_depth>0.001</min_depth>
            </ode>
          </contact>
        </surface>
        <max_contacts>1000</max_contacts>
      </collision>
<!--******************************************* -->
        <sensor name='mft' type='contact'>
          <contact>
            <collision>mft_fpcb</collision>
          </contact>
        <update_rate> 5 </update_rate>
        <visualize> true </visualize>
        </sensor>    
<!--******************************************* -->
      <collision name='link_7_fixed_joint_lump__middle_fingertip_side_fpcb_collision_3'>
        <pose>0.1004 0 0.011899 -5e-06 -0 -3.14159</pose>
        <geometry>
          <mesh>
            <scale>1 1 1</scale>
            <uri>model://allegro_hand_description/meshes/distal_fpcb_2.stl</uri>
          </mesh>
        </geometry>
        <surface>
          <contact>
            <ode>
              <max_vel>10</max_vel>
              <min_depth>0.001</min_depth>
            </ode>
          </contact>
        </surface>
        <max_contacts>1000</max_contacts>
      </collision>
      <visual name='link_7_visual'>
        <pose>0.1253 -0 0.0118 3.14159 -0 -1.5708</pose>
        <geometry>
          <mesh>
            <scale>1 1 1</scale>
            <uri>model://allegro_hand_description/meshes/p4_r.stl</uri>
          </mesh>
        </geometry>
      </visual>
      <visual name='link_7_fixed_joint_lump__mft_bracket_visual_1'>
        <pose>0.1004 0 0.0119 0 -0 -3.14159</pose>
        <geometry>
          <mesh>
            <scale>1 1 1</scale>
            <uri>model://allegro_hand_description/meshes/distal_pcbbase.stl</uri>
          </mesh>
        </geometry>
      </visual>
      <visual name='link_7_fixed_joint_lump__middle_fingertip_main_fpcb_visual_2'>
        <pose>0.1004 0 0.0119 -5e-06 0 -3.14159</pose>
        <geometry>
          <mesh>
            <scale>1 1 1</scale>
            <uri>model://allegro_hand_description/meshes/distal_fpcb_1.stl</uri>
          </mesh>
        </geometry>
      </visual>
      <visual name='link_7_fixed_joint_lump__middle_fingertip_side_fpcb_visual_3'>
        <pose>0.1004 0 0.011899 -5e-06 -0 -3.14159</pose>
        <geometry>
          <mesh>
            <scale>1 1 1</scale>
            <uri>model://allegro_hand_description/meshes/distal_fpcb_2.stl</uri>
          </mesh>
        </geometry>
      </visual>
      <self_collide>true</self_collide>
    </link>
    <joint name='joint_8_0' type='revolute'>
      <pose relative_to='wrist_3_link'>0.043538 -0.007 0.109461 0.087266 0 1.5708</pose>
      <parent>wrist_3_link</parent>
      <child>link_8</child>
      <axis>
        <xyz>0 0 1</xyz>
        <limit>
          <lower>-0.45</lower>
          <upper>0.55</upper>
          <effort>15</effort>
          <velocity>20</velocity>
        </limit>
        <dynamics>
          <damping>0</damping>
          <friction>0.5</friction>
          <spring_reference>0</spring_reference>
          <spring_stiffness>0</spring_stiffness>
        </dynamics>
      </axis>
      <physics>
        <implicit_spring_damper> true </implicit_spring_damper>
      </physics>
    </joint>
    <link name='link_8'>
      <pose relative_to='joint_8_0'>0 0 0 0 -0 0</pose>
      <inertial>
        <pose>-0.000413 0.000666 0.009606 0 -0 0</pose>
        <mass>0.0136672</mass>
        <inertia>
          <ixx>2.13441e-06</ixx>
          <ixy>5.86704e-10</ixy>
          <ixz>-7.9563e-08</ixz>
          <iyy>1.24411e-06</iyy>
          <iyz>-6.13056e-08</iyz>
          <izz>1.671e-06</izz>
        </inertia>
      </inertial>
      <collision name='link_8_collision'>
        <pose>0 -0 -0.0152 1.5708 -0 0</pose>
        <geometry>
          <mesh>
            <scale>1 1 1</scale>
            <uri>model://allegro_hand_description/meshes/extended_finger_base.stl</uri>
          </mesh>
        </geometry>
        <surface>
          <contact>
            <ode>
              <max_vel>10</max_vel>
              <min_depth>0.001</min_depth>
            </ode>
          </contact>
        </surface>
        <max_contacts>1000</max_contacts>
      </collision>
      <visual name='link_8_visual'>
        <pose>0 -0 -0.0152 1.5708 -0 0</pose>
        <geometry>
          <mesh>
            <scale>1 1 1</scale>
            <uri>model://allegro_hand_description/meshes/extended_finger_base.stl</uri>
          </mesh>
        </geometry>
      </visual>
      <self_collide>true</self_collide>
    </link>
    <joint name='joint_9_0' type='revolute'>
      <pose relative_to='link_8'>-0 -0.0119 0.02545 1.57079 1.57079 -3.14159</pose>
      <parent>link_8</parent>
      <child>link_9</child>
      <axis>
        <xyz>0 0 1</xyz>
        <limit>
          <lower>0</lower>
          <upper>1.65</upper>
          <effort>15</effort>
          <velocity>20</velocity>
        </limit>
        <dynamics>
          <damping>0</damping>
          <friction>0.5</friction>
          <spring_reference>0</spring_reference>
          <spring_stiffness>0</spring_stiffness>
        </dynamics>
      </axis>
      <physics>
        <implicit_spring_damper> true </implicit_spring_damper>
      </physics>
    </joint>
    <link name='link_9'>
      <pose relative_to='joint_9_0'>0 0 0 0 -0 0</pose>
      <inertial>
        <pose>-0.027039 0.000297 0.012126 0 -0 0</pose>
        <mass>0.0561213</mass>
        <inertia>
          <ixx>8.79961e-06</ixx>
          <ixy>-2.75758e-08</ixy>
          <ixz>2.55745e-06</ixz>
          <iyy>2.46927e-05</iyy>
          <iyz>1.32424e-07</iyz>
          <izz>2.36754e-05</izz>
        </inertia>
      </inertial>
      <collision name='link_9_collision'>
        <pose>0.018269 0 -0.031781 0 1.48353 -0</pose>
        <geometry>
          <mesh>
            <scale>1 1 1</scale>
            <uri>model://allegro_hand_description/meshes/p2_r6.stl</uri>
          </mesh>
        </geometry>
        <surface>
          <contact>
            <ode>
              <max_vel>10</max_vel>
              <min_depth>0.001</min_depth>
            </ode>
          </contact>
        </surface>
        <max_contacts>1000</max_contacts>
      </collision>
      <collision name='link_9_fixed_joint_lump__ppb_bracket_collision_1'>
        <pose>-0 -0 0.0113 5e-06 0 3.14159</pose>
        <geometry>
          <mesh>
            <scale>1 1 1</scale>
            <uri>model://allegro_hand_description/meshes/proximal_back.stl</uri>
          </mesh>
        </geometry>
        <surface>
          <contact>
            <ode>
              <max_vel>10</max_vel>
              <min_depth>0.001</min_depth>
            </ode>
          </contact>
        </surface>
        <max_contacts>1000</max_contacts>
      </collision>
      <collision name='ppb_fpcb'>
        <pose>-0 -0 0.0113 -5e-06 0 3.14159</pose>
        <geometry>
          <mesh>
            <scale>1 1 1</scale>
            <uri>model://allegro_hand_description/meshes/proximal_back_fpcb.stl</uri>
          </mesh>
        </geometry>
        <surface>
          <contact>
            <ode>
              <max_vel>10</max_vel>
              <min_depth>0.001</min_depth>
            </ode>
          </contact>
        </surface>
        <max_contacts>1000</max_contacts>
      </collision>
<!--******************************************* -->
        <sensor name='ppb' type='contact'>
          <contact>
            <collision>ppb_fpcb</collision>
          </contact>
        <update_rate> 5 </update_rate>
        <visualize> true </visualize>
        </sensor>    
<!--******************************************* -->
      <collision name='link_9_fixed_joint_lump__ppf_bracket_collision_3'>
        <pose>0 -0 0.0123 -0 0 3.14159</pose>
        <geometry>
          <mesh>
            <scale>1 1 1</scale>
            <uri>model://allegro_hand_description/meshes/proximal_front.stl</uri>
          </mesh>
        </geometry>
        <surface>
          <contact>
            <ode>
              <max_vel>10</max_vel>
              <min_depth>0.001</min_depth>
            </ode>
          </contact>
        </surface>
        <max_contacts>1000</max_contacts>
      </collision>
      <collision name='ppf_fpcb'>
        <pose>0 -0 0.0123 -0 0 3.14159</pose>
        <geometry>
          <mesh>
            <scale>1 1 1</scale>
            <uri>model://allegro_hand_description/meshes/proximal_frontfpcb.stl</uri>
          </mesh>
        </geometry>
        <surface>
          <contact>
            <ode>
              <max_vel>10</max_vel>
              <min_depth>0.001</min_depth>
            </ode>
          </contact>
        </surface>
        <max_contacts>1000</max_contacts>
      </collision>
<!--******************************************* -->
        <sensor name='ppf' type='contact'>
          <contact>
            <collision>ppf_fpcb</collision>
          </contact>
        <update_rate> 5 </update_rate>
        <visualize> true </visualize>
        </sensor>    
<!--******************************************* -->
      <visual name='link_9_visual'>
        <pose>0.018269 0 -0.031781 0 1.48353 -0</pose>
        <geometry>
          <mesh>
            <scale>1 1 1</scale>
            <uri>model://allegro_hand_description/meshes/p2_r6.stl</uri>
          </mesh>
        </geometry>
      </visual>
      <visual name='link_9_fixed_joint_lump__ppb_bracket_visual_1'>
        <pose>-0 -0 0.0113 5e-06 0 3.14159</pose>
        <geometry>
          <mesh>
            <scale>1 1 1</scale>
            <uri>model://allegro_hand_description/meshes/proximal_back.stl</uri>
          </mesh>
        </geometry>
      </visual>
      <visual name='link_9_fixed_joint_lump__pinky_proximal_back_fpcb_visual_2'>
        <pose>-0 -0 0.0113 -5e-06 0 3.14159</pose>
        <geometry>
          <mesh>
            <scale>1 1 1</scale>
            <uri>model://allegro_hand_description/meshes/proximal_back_fpcb.stl</uri>
          </mesh>
        </geometry>
      </visual>
      <visual name='link_9_fixed_joint_lump__ppf_bracket_visual_3'>
        <pose>0 -0 0.0123 -0 0 3.14159</pose>
        <geometry>
          <mesh>
            <scale>1 1 1</scale>
            <uri>model://allegro_hand_description/meshes/proximal_front.stl</uri>
          </mesh>
        </geometry>
      </visual>
      <visual name='link_9_fixed_joint_lump__pinky_proximal_front_fpcb_visual_4'>
        <pose>0 -0 0.0123 -0 0 3.14159</pose>
        <geometry>
          <mesh>
            <scale>1 1 1</scale>
            <uri>model://allegro_hand_description/meshes/proximal_frontfpcb.stl</uri>
          </mesh>
        </geometry>
      </visual>
      <self_collide>true</self_collide>
    </link>
    <joint name='joint_10_0' type='revolute'>
      <pose relative_to='link_9'>-0.054 0 -0 0 -0 -0</pose>
      <parent>link_9</parent>
      <child>link_10</child>
      <axis>
        <xyz>0 0 1</xyz>
        <limit>
          <lower>0</lower>
          <upper>1.5</upper>
          <effort>15</effort>
          <velocity>20</velocity>
        </limit>
        <dynamics>
          <damping>0</damping>
          <friction>0.5</friction>
          <spring_reference>0</spring_reference>
          <spring_stiffness>0</spring_stiffness>
        </dynamics>
      </axis>
      <physics>
        <implicit_spring_damper> true </implicit_spring_damper>
      </physics>
    </joint>
    <link name='link_10'>
      <pose relative_to='joint_10_0'>0 0 0 0 -0 0</pose>
      <inertial>
        <pose>-0.028729 0.000348 0.012141 0 -0 0</pose>
        <mass>0.0437084</mass>
        <inertia>
          <ixx>7.32067e-06</ixx>
          <ixy>1.91294e-07</ixy>
          <ixz>6.50557e-07</ixz>
          <iyy>1.32067e-05</iyy>
          <iyz>1.79464e-07</iyz>
          <izz>1.13788e-05</izz>
        </inertia>
      </inertial>
      <collision name='link_10_collision'>
        <pose>0.072269 -0 -0.031781 -0 1.48353 0</pose>
        <geometry>
          <mesh>
            <scale>1 1 1</scale>
            <uri>model://allegro_hand_description/meshes/extended_fingertop.stl</uri>
          </mesh>
        </geometry>
        <surface>
          <contact>
            <ode>
              <max_vel>10</max_vel>
              <min_depth>0.001</min_depth>
            </ode>
          </contact>
        </surface>
        <max_contacts>1000</max_contacts>
      </collision>
      <collision name='link_10_fixed_joint_lump__pmb_bracket_collision_1'>
        <pose>0.054 -0 0.0119 5e-06 -0 3.14159</pose>
        <geometry>
          <mesh>
            <scale>1 1 1</scale>
            <uri>model://allegro_hand_description/meshes/medial_back.stl</uri>
          </mesh>
        </geometry>
        <surface>
          <contact>
            <ode>
              <max_vel>10</max_vel>
              <min_depth>0.001</min_depth>
            </ode>
          </contact>
        </surface>
        <max_contacts>1000</max_contacts>
      </collision>
      <collision name='pmb_fpcb'>
        <pose>0.054 0 0.0119 -1e-06 -4e-06 3.14159</pose>
        <geometry>
          <mesh>
            <scale>1 1 1</scale>
            <uri>model://allegro_hand_description/meshes/medial_back_fpcb.stl</uri>
          </mesh>
        </geometry>
        <surface>
          <contact>
            <ode>
              <max_vel>10</max_vel>
              <min_depth>0.001</min_depth>
            </ode>
          </contact>
        </surface>
        <max_contacts>1000</max_contacts>
      </collision>
<!--******************************************* -->
        <sensor name='pmb' type='contact'>
          <contact>
            <collision>pmb_fpcb</collision>
          </contact>
        <update_rate> 5 </update_rate>
        <visualize> true </visualize>
        </sensor>    
<!--******************************************* -->
      <collision name='link_10_fixed_joint_lump__pmf_bracket_collision_3'>
        <pose>0.054 -0 0.0119 0 -0 3.14159</pose>
        <geometry>
          <mesh>
            <scale>1 1 1</scale>
            <uri>model://allegro_hand_description/meshes/medial_front.stl</uri>
          </mesh>
        </geometry>
        <surface>
          <contact>
            <ode>
              <max_vel>10</max_vel>
              <min_depth>0.001</min_depth>
            </ode>
          </contact>
        </surface>
        <max_contacts>1000</max_contacts>
      </collision>
      <collision name='pmf_fpcb'>
        <pose>0.054 0 0.0119 -4e-06 4e-06 3.14159</pose>
        <geometry>
          <mesh>
            <scale>1 1 1</scale>
            <uri>model://allegro_hand_description/meshes/medial_front_fpcb.stl</uri>
          </mesh>
        </geometry>
        <surface>
          <contact>
            <ode>
              <max_vel>10</max_vel>
              <min_depth>0.001</min_depth>
            </ode>
          </contact>
        </surface>
        <max_contacts>1000</max_contacts>
      </collision>
<!--******************************************* -->
        <sensor name='pmf' type='contact'>
          <contact>
            <collision>pmf_fpcb</collision>
          </contact>
        <update_rate> 5 </update_rate>
        <visualize> true </visualize>
        </sensor>    
<!--******************************************* -->
      <visual name='link_10_visual'>
        <pose>0.072269 -0 -0.031781 -0 1.48353 0</pose>
        <geometry>
          <mesh>
            <scale>1 1 1</scale>
            <uri>model://allegro_hand_description/meshes/extended_fingertop.stl</uri>
          </mesh>
        </geometry>
      </visual>
      <visual name='link_10_fixed_joint_lump__pmb_bracket_visual_1'>
        <pose>0.054 -0 0.0119 5e-06 -0 3.14159</pose>
        <geometry>
          <mesh>
            <scale>1 1 1</scale>
            <uri>model://allegro_hand_description/meshes/medial_back.stl</uri>
          </mesh>
        </geometry>
      </visual>
      <visual name='link_10_fixed_joint_lump__pinky_medial_back_fpcb_visual_2'>
        <pose>0.054 0 0.0119 -1e-06 -4e-06 3.14159</pose>
        <geometry>
          <mesh>
            <scale>1 1 1</scale>
            <uri>model://allegro_hand_description/meshes/medial_back_fpcb.stl</uri>
          </mesh>
        </geometry>
      </visual>
      <visual name='link_10_fixed_joint_lump__pmf_bracket_visual_3'>
        <pose>0.054 -0 0.0119 0 -0 3.14159</pose>
        <geometry>
          <mesh>
            <scale>1 1 1</scale>
            <uri>model://allegro_hand_description/meshes/medial_front.stl</uri>
          </mesh>
        </geometry>
      </visual>
      <visual name='link_10_fixed_joint_lump__pinky_medial_front_fpcb_visual_4'>
        <pose>0.054 0 0.0119 -4e-06 4e-06 3.14159</pose>
        <geometry>
          <mesh>
            <scale>1 1 1</scale>
            <uri>model://allegro_hand_description/meshes/medial_front_fpcb.stl</uri>
          </mesh>
        </geometry>
      </visual>
      <self_collide>true</self_collide>
    </link>
    <joint name='joint_11_0' type='revolute'>
      <pose relative_to='link_10'>-0.04615 0 0.0001 -0 0 -0</pose>
      <parent>link_10</parent>
      <child>link_11</child>
      <axis>
        <xyz>0 0 1</xyz>
        <limit>
          <lower>0</lower>
          <upper>2.5</upper>
          <effort>15</effort>
          <velocity>20</velocity>
        </limit>
        <dynamics>
          <damping>0</damping>
          <friction>0.5</friction>
          <spring_reference>0</spring_reference>
          <spring_stiffness>0</spring_stiffness>
        </dynamics>
      </axis>
      <physics>
        <implicit_spring_damper> true </implicit_spring_damper>
      </physics>
    </joint>
    <link name='link_11'>
      <pose relative_to='joint_11_0'>0 0 0 0 -0 0</pose>
      <inertial>
        <pose>-0.024577 0.002729 0.012009 0 -0 0</pose>
        <mass>0.0270564</mass>
        <inertia>
          <ixx>5.23237e-06</ixx>
          <ixy>9.55197e-07</ixy>
          <ixz>-7.21036e-08</ixz>
          <iyy>1.08492e-05</iyy>
          <iyz>8.1688e-09</iyz>
          <izz>8.7254e-06</izz>
        </inertia>
      </inertial>
      <collision name='link_11_collision'>
        <pose>0.1253 -0 0.0118 3.14159 -0 -1.5708</pose>
        <geometry>
          <mesh>
            <scale>1 1 1</scale>
            <uri>model://allegro_hand_description/meshes/p4_r.stl</uri>
          </mesh>
        </geometry>
        <surface>
          <contact>
            <ode>
              <max_vel>10</max_vel>
              <min_depth>0.001</min_depth>
            </ode>
          </contact>
        </surface>
        <max_contacts>1000</max_contacts>
      </collision>
      <collision name='link_11_fixed_joint_lump__pft_bracket_collision_1'>
        <pose>0.1004 -0 0.0119 -0 0 3.14159</pose>
        <geometry>
          <mesh>
            <scale>1 1 1</scale>
            <uri>model://allegro_hand_description/meshes/distal_pcbbase.stl</uri>
          </mesh>
        </geometry>
        <surface>
          <contact>
            <ode>
              <max_vel>10</max_vel>
              <min_depth>0.001</min_depth>
            </ode>
          </contact>
        </surface>
        <max_contacts>1000</max_contacts>
      </collision>
      <collision name='pft_fpcb'>
        <pose>0.1004 -0 0.0119 -0 -0 3.14159</pose>
        <geometry>
          <mesh>
            <scale>1 1 1</scale>
            <uri>model://allegro_hand_description/meshes/distal_fpcb_1.stl</uri>
          </mesh>
        </geometry>
        <surface>
          <contact>
            <ode>
              <max_vel>10</max_vel>
              <min_depth>0.001</min_depth>
            </ode>
          </contact>
        </surface>
        <max_contacts>1000</max_contacts>
      </collision>
<!--******************************************* -->
        <sensor name='pft' type='contact'>
          <contact>
            <collision>pft_fpcb</collision>
          </contact>
        <update_rate> 5 </update_rate>
        <visualize> true </visualize>
        </sensor>    
<!--******************************************* -->
      <collision name='link_11_fixed_joint_lump__pinky_fingertip_side_fpcb_collision_3'>
        <pose>0.1004 -0 0.011899 -0 0 3.14159</pose>
        <geometry>
          <mesh>
            <scale>1 1 1</scale>
            <uri>model://allegro_hand_description/meshes/distal_fpcb_2.stl</uri>
          </mesh>
        </geometry>
        <surface>
          <contact>
            <ode>
              <max_vel>10</max_vel>
              <min_depth>0.001</min_depth>
            </ode>
          </contact>
        </surface>
        <max_contacts>1000</max_contacts>
      </collision>
      <visual name='link_11_visual'>
        <pose>0.1253 -0 0.0118 3.14159 -0 -1.5708</pose>
        <geometry>
          <mesh>
            <scale>1 1 1</scale>
            <uri>model://allegro_hand_description/meshes/p4_r.stl</uri>
          </mesh>
        </geometry>
      </visual>
      <visual name='link_11_fixed_joint_lump__pft_bracket_visual_1'>
        <pose>0.1004 -0 0.0119 -0 0 3.14159</pose>
        <geometry>
          <mesh>
            <scale>1 1 1</scale>
            <uri>model://allegro_hand_description/meshes/distal_pcbbase.stl</uri>
          </mesh>
        </geometry>
      </visual>
      <visual name='link_11_fixed_joint_lump__pinky_fingertip_main_fpcb_visual_2'>
        <pose>0.1004 -0 0.0119 -0 -0 3.14159</pose>
        <geometry>
          <mesh>
            <scale>1 1 1</scale>
            <uri>model://allegro_hand_description/meshes/distal_fpcb_1.stl</uri>
          </mesh>
        </geometry>
      </visual>
      <visual name='link_11_fixed_joint_lump__pinky_fingertip_side_fpcb_visual_3'>
        <pose>0.1004 -0 0.011899 -0 0 3.14159</pose>
        <geometry>
          <mesh>
            <scale>1 1 1</scale>
            <uri>model://allegro_hand_description/meshes/distal_fpcb_2.stl</uri>
          </mesh>
        </geometry>
      </visual>
      <self_collide>true</self_collide>
    </link>

<!-- 
*********************************************************************
*********************************************************************
*********************************************************************
Object placed on the table and waiting to be grasped by the allegrp hand 
*********************************************************************
*********************************************************************
*********************************************************************
-->
<!--
    <joint name='object_to_table' type='prismatic'>
      <pose relative_to='table_base'>0.004217 -0.201201 0.951750 0 0 0</pose>
      <parent>table_base</parent>
      <child>cubic_object_link</child>
      <axis>
        <xyz>0 0 1</xyz>
        <limit>
          <lower>0</lower>
          <upper>0</upper>
        </limit>
        <dynamics>
          <damping>1</damping>
          <spring_reference>0</spring_reference>
          <spring_stiffness>1</spring_stiffness>
        </dynamics>
      </axis>

      <physics>
        <ode>
          <implicit_spring_damper> true </implicit_spring_damper>
        </ode>
      </physics>
    </joint>

    <link name='cubic_object_link'>
      <pose relative_to='object_to_table'>0 0 0 0 -0 0</pose>
      <inertial>
        <pose>-1.02566e-17 9.23364e-19 0.1075 0 0 0</pose>
        <mass>0.0770781</mass>
        <inertia>
          <ixx>0.000307188</ixx>
          <ixy>0</ixy>
          <ixz>0</ixz>
          <iyy>0.000307188</iyy>
          <iyz>0</iyz>
          <izz>2.05542e-05</izz>
        </inertia>
      </inertial>
      <collision name='cubic_object_collision'>
        <pose>0 0 0 0 -0 1.5708</pose>
        <geometry>
          <mesh>
            <scale>1 1 1</scale>
            <uri>model://cubic_object/meshes/cubic_object.stl</uri>
          </mesh>
        </geometry>
        <surface>
          <contact>
            <ode>         
              <max_vel>0.1</max_vel>
              <min_depth>0.001</min_depth>
            </ode>
          </contact>
        </surface>
        <max_contacts>1000</max_contacts>
      </collision>
      <visual name='cubic_object_visual'>
        <pose>0 0 0 0 -0 1.5708</pose>
        <geometry>
          <mesh>
            <scale>1 1 1</scale>
            <uri>model://cubic_object/meshes/cubic_object.stl</uri>
          </mesh>
        </geometry>
      </visual>
    <self_collide>true</self_collide>
    </link>

-->

    <static>0</static>
    <plugin name="contact_coordinates_plugin" filename="/home/abed/Documents/BICI_Project/BICI_SENSORS_ROS/Gazebo_Simulation/Contact_Sensor/build/libcoordinates.so"/>
    <plugin name='gazebo_ros_control' filename='libgazebo_ros_control.so'>
      <robotNamespace>/</robotNamespace>
      <robotSimType>gazebo_ros_control/DefaultRobotHWSim</robotSimType>
    </plugin>

  </model>
</sdf>