<?xml version="1.0" ?>
<!-- =================================================================================== -->
<!-- |    This document was autogenerated by xacro from ur5e_workstation.urdf.xacro    | -->
<!-- |    EDITING THIS FILE BY HAND IS NOT RECOMMENDED                                 | -->
<!-- =================================================================================== -->
<robot name="ur5e_2f85">
  <!-- WORLD -->
  <link name="world"/>
  <!-- Table -->
  <link name="table_base">
    <visual>
      <origin rpy="0 0 0" xyz="0 0 0"/>
      <geometry>
        <mesh filename="package://coro_descriptions/meshes/small_vention_table.dae"/>
      </geometry>
    </visual>
    <collision>
      <origin rpy="0 0 0" xyz="0 0 0"/>
      <geometry>
        <mesh filename="package://coro_descriptions/meshes/small_vention_table.dae"/>
      </geometry>
    </collision>
    <inertial>
      <origin rpy="0 0 0" xyz="0 0 0"/>
      <mass value="20"/>
      <inertia ixx="1" ixy="0" ixz="0" iyx="0" iyy="1" iyz="0" izx="0" izy="0" izz="1"/>
    </inertial>
  </link>
  <!-- Table top -->
	<link name='table_top'>
		<inertial>
			<origin xyz="1.41182e-16 -6.13716e-17 -0.00229716" rpy="0 0 0"/>
			<mass value="1.88145" />
			<inertia ixx="0.132708" ixy="0"  ixz="0" iyy="0.0587177" iyz="0" izz="0.191419" />
		</inertial>
		<collision>
			<origin xyz="0 0 -0.0047" rpy="0 0 0" />
			<geometry>
				<mesh filename= "package://coro_descriptions/meshes/table_top.stl"/>
			</geometry>
		    <material name="table_top_material">
				<color rgba="0.615686 0.811765 0.929412 1.0"/>
			</material>
		</collision>
		<visual>
			<geometry>
				<mesh filename= "package://coro_descriptions/meshes/table_top.stl"/>
			</geometry>
		    <material name="table_top_material">
				<color rgba="0.615686 0.811765 0.929412 1.0"/>
			</material>>
		</visual>
	</link>

	<joint name='table_top_to_table_base' type='fixed'>
		<origin xyz="0.004217 -0.201201 0.97025" rpy="0 0 1.57"/>
		<parent link="table_base"/>
		<child link="table_top"/>
	</joint>

  <!-- Robot mount -->
  <link name="robot_mount"/>
  <joint name="robot_mount" type="fixed">
    <parent link="table_base"/>
    <child link="robot_mount"/>
    <origin rpy="0 0 3.1416" xyz="-0.0093 0.3375 0.99275"/>
    <!-- Coordinates taken from a CAD assembly -->
  </joint>
  <joint name="table_to_world" type="fixed">
    <parent link="world"/>
    <child link="table_base"/>
    <origin rpy="0 0 0" xyz="0 0 0"/>
  </joint>
  <!--
    Base UR robot series xacro macro.

    NOTE: this is NOT a URDF. It cannot directly be loaded by consumers
    expecting a flattened '.urdf' file. See the top-level '.xacro' for that
    (but note: that .xacro must still be processed by the xacro command).

    For use in '.launch' files: use one of the 'load_urX.launch' convenience
    launch files.

    This file models the base kinematic chain of a UR robot, which then gets
    parameterised by various configuration files to convert it into a UR3(e),
    UR5(e), UR10(e) or UR16e.

    NOTE: the default kinematic parameters (ie: link lengths, frame locations,
    offets, etc) do not correspond to any particular robot. They are defaults
    only. There WILL be non-zero offsets between the Forward Kinematics results
    in TF (ie: robot_state_publisher) and the values reported by the Teach
    Pendant.

    For accurate (and robot-specific) transforms, the 'kinematics_parameters_file'
    parameter MUST point to a .yaml file containing the appropriate values for
    the targetted robot.

    If using the UniversalRobots/Universal_Robots_ROS_Driver, follow the steps
    described in the readme of that repository to extract the kinematic
    calibration from the controller and generate the required .yaml file.

    Main author of the migration to yaml configs: Ludovic Delval.

    Contributors to previous versions (in no particular order):

     - Felix Messmer
     - Kelsey Hawkins
     - Wim Meeussen
     - Shaun Edwards
     - Nadia Hammoudeh Garcia
     - Dave Hershberger
     - G. vd. Hoorn
     - Philip Long
     - Dave Coleman
     - Miguel Prada
     - Mathias Luedtke
     - Marcel Schnirring
     - Felix von Drigalski
     - Felix Exner
     - Jimmy Da Silva
     - Ajit Krisshna N L
     - Muhammad Asif Rana
  -->
  <!--
    NOTE: the macro defined in this file is NOT part of the public API of this
          package. Users CANNOT rely on this file being available, or stored in
          this location. Nor can they rely on the existence of the macro.
  -->
  <transmission name="shoulder_pan_trans">
    <type>transmission_interface/SimpleTransmission</type>
    <joint name="shoulder_pan_joint">
      <hardwareInterface>hardware_interface/PositionJointInterface</hardwareInterface>
    </joint>
    <actuator name="shoulder_pan_motor">
      <mechanicalReduction>1</mechanicalReduction>
    </actuator>
  </transmission>
  <transmission name="shoulder_lift_trans">
    <type>transmission_interface/SimpleTransmission</type>
    <joint name="shoulder_lift_joint">
      <hardwareInterface>hardware_interface/PositionJointInterface</hardwareInterface>
    </joint>
    <actuator name="shoulder_lift_motor">
      <mechanicalReduction>1</mechanicalReduction>
    </actuator>
  </transmission>
  <transmission name="elbow_trans">
    <type>transmission_interface/SimpleTransmission</type>
    <joint name="elbow_joint">
      <hardwareInterface>hardware_interface/PositionJointInterface</hardwareInterface>
    </joint>
    <actuator name="elbow_motor">
      <mechanicalReduction>1</mechanicalReduction>
    </actuator>
  </transmission>
  <transmission name="wrist_1_trans">
    <type>transmission_interface/SimpleTransmission</type>
    <joint name="wrist_1_joint">
      <hardwareInterface>hardware_interface/PositionJointInterface</hardwareInterface>
    </joint>
    <actuator name="wrist_1_motor">
      <mechanicalReduction>1</mechanicalReduction>
    </actuator>
  </transmission>
  <transmission name="wrist_2_trans">
    <type>transmission_interface/SimpleTransmission</type>
    <joint name="wrist_2_joint">
      <hardwareInterface>hardware_interface/PositionJointInterface</hardwareInterface>
    </joint>
    <actuator name="wrist_2_motor">
      <mechanicalReduction>1</mechanicalReduction>
    </actuator>
  </transmission>
  <transmission name="wrist_3_trans">
    <type>transmission_interface/SimpleTransmission</type>
    <joint name="wrist_3_joint">
      <hardwareInterface>hardware_interface/PositionJointInterface</hardwareInterface>
    </joint>
    <actuator name="wrist_3_motor">
      <mechanicalReduction>1</mechanicalReduction>
    </actuator>
  </transmission>
  <!-- links: main serial chain -->
  <link name="base_link"/>
  <link name="base_link_inertia">
    <visual>
      <origin rpy="0 0 3.141592653589793" xyz="0 0 0"/>
      <geometry>
        <mesh filename="package://ur_description/meshes/ur5e/visual/base.dae"/>
      </geometry>
      <material name="LightGrey">
        <color rgba="0.7 0.7 0.7 1.0"/>
      </material>
    </visual>
    <collision>
      <origin rpy="0 0 3.141592653589793" xyz="0 0 0"/>
      <geometry>
        <mesh filename="package://ur_description/meshes/ur5e/collision/base.stl"/>
      </geometry>
    </collision>
    <inertial>
      <mass value="4.0"/>
      <origin rpy="0 0 0" xyz="0 0 0"/>
      <inertia ixx="0.00443333156" ixy="0.0" ixz="0.0" iyy="0.00443333156" iyz="0.0" izz="0.0072"/>
    </inertial>
  </link>
  <link name="shoulder_link">
    <visual>
      <origin rpy="0 0 3.141592653589793" xyz="0 0 0"/>
      <geometry>
        <mesh filename="package://ur_description/meshes/ur5e/visual/shoulder.dae"/>
      </geometry>
      <material name="LightGrey">
        <color rgba="0.7 0.7 0.7 1.0"/>
      </material>
    </visual>
    <collision>
      <origin rpy="0 0 3.141592653589793" xyz="0 0 0"/>
      <geometry>
        <mesh filename="package://ur_description/meshes/ur5e/collision/shoulder.stl"/>
      </geometry>
    </collision>
    <inertial>
      <mass value="3.7"/>
      <origin rpy="0 0 0" xyz="0 0 0"/>
      <inertia ixx="0.010267495893" ixy="0.0" ixz="0.0" iyy="0.010267495893" iyz="0.0" izz="0.00666"/>
    </inertial>
  </link>
  <link name="upper_arm_link">
    <visual>
      <origin rpy="1.5707963267948966 0 -1.5707963267948966" xyz="0 0 0.138"/>
      <geometry>
        <mesh filename="package://ur_description/meshes/ur5e/visual/upperarm.dae"/>
      </geometry>
      <material name="LightGrey">
        <color rgba="0.7 0.7 0.7 1.0"/>
      </material>
    </visual>
    <collision>
      <origin rpy="1.5707963267948966 0 -1.5707963267948966" xyz="0 0 0.138"/>
      <geometry>
        <mesh filename="package://ur_description/meshes/ur5e/collision/upperarm.stl"/>
      </geometry>
    </collision>
    <inertial>
      <mass value="8.393"/>
      <origin rpy="0 1.5707963267948966 0" xyz="-0.2125 0.0 0.138"/>
      <inertia ixx="0.1338857818623325" ixy="0.0" ixz="0.0" iyy="0.1338857818623325" iyz="0.0" izz="0.0151074"/>
    </inertial>
  </link>
  <link name="forearm_link">
    <visual>
      <origin rpy="1.5707963267948966 0 -1.5707963267948966" xyz="0 0 0.007"/>
      <geometry>
        <mesh filename="package://ur_description/meshes/ur5e/visual/forearm.dae"/>
      </geometry>
      <material name="LightGrey">
        <color rgba="0.7 0.7 0.7 1.0"/>
      </material>
    </visual>
    <collision>
      <origin rpy="1.5707963267948966 0 -1.5707963267948966" xyz="0 0 0.007"/>
      <geometry>
        <mesh filename="package://ur_description/meshes/ur5e/collision/forearm.stl"/>
      </geometry>
    </collision>
    <inertial>
      <mass value="2.275"/>
      <origin rpy="0 1.5707963267948966 0" xyz="-0.1961 0.0 0.007"/>
      <inertia ixx="0.031209355099586295" ixy="0.0" ixz="0.0" iyy="0.031209355099586295" iyz="0.0" izz="0.004095"/>
    </inertial>
  </link>
  <link name="wrist_1_link">
    <visual>
      <!-- TODO: Move this to a parameter -->
      <origin rpy="1.5707963267948966 0 0" xyz="0 0 -0.127"/>
      <geometry>
        <mesh filename="package://ur_description/meshes/ur5e/visual/wrist1.dae"/>
      </geometry>
      <material name="LightGrey">
        <color rgba="0.7 0.7 0.7 1.0"/>
      </material>
    </visual>
    <collision>
      <origin rpy="1.5707963267948966 0 0" xyz="0 0 -0.127"/>
      <geometry>
        <mesh filename="package://ur_description/meshes/ur5e/collision/wrist1.stl"/>
      </geometry>
    </collision>
    <inertial>
      <mass value="1.219"/>
      <origin rpy="0 0 0" xyz="0 0 0"/>
      <inertia ixx="0.0025598989760400002" ixy="0.0" ixz="0.0" iyy="0.0025598989760400002" iyz="0.0" izz="0.0021942"/>
    </inertial>
  </link>
  <link name="wrist_2_link">
    <visual>
      <origin rpy="0 0 0" xyz="0 0 -0.0997"/>
      <geometry>
        <mesh filename="package://ur_description/meshes/ur5e/visual/wrist2.dae"/>
      </geometry>
      <material name="LightGrey">
        <color rgba="0.7 0.7 0.7 1.0"/>
      </material>
    </visual>
    <collision>
      <origin rpy="0 0 0" xyz="0 0 -0.0997"/>
      <geometry>
        <mesh filename="package://ur_description/meshes/ur5e/collision/wrist2.stl"/>
      </geometry>
    </collision>
    <inertial>
      <mass value="1.219"/>
      <origin rpy="0 0 0" xyz="0 0 0"/>
      <inertia ixx="0.0025598989760400002" ixy="0.0" ixz="0.0" iyy="0.0025598989760400002" iyz="0.0" izz="0.0021942"/>
    </inertial>
  </link>
  <link name="wrist_3_link">
    <visual>
      <origin rpy="1.5707963267948966 0 1.5707963267948966" xyz="0 0 -0.0989"/>
      <geometry>
        <mesh filename="package://ur_description/meshes/ur5e/visual/wrist3.dae"/>
      </geometry>
      <material name="LightGrey">
        <color rgba="0.7 0.7 0.7 1.0"/>
      </material>
    </visual>
    <collision>
      <origin rpy="1.5707963267948966 0 1.5707963267948966" xyz="0 0 -0.0989"/>
      <geometry>
        <mesh filename="package://ur_description/meshes/ur5e/collision/wrist3.stl"/>
      </geometry>
    </collision>
    <inertial>
      <mass value="0.1879"/>
      <origin rpy="0 0 0" xyz="0.0 0.0 -0.0229"/>
      <inertia ixx="9.890410052167731e-05" ixy="0.0" ixz="0.0" iyy="9.890410052167731e-05" iyz="0.0" izz="0.0001321171875"/>
    </inertial>
  </link>
  <!-- joints: main serial chain -->
  <joint name="base_link-base_link_inertia" type="fixed">
    <parent link="base_link"/>
    <child link="base_link_inertia"/>
    <!-- 'base_link' is REP-103 aligned (so X+ forward), while the internal
           frames of the robot/controller have X+ pointing backwards.
           Use the joint between 'base_link' and 'base_link_inertia' (a dummy
           link/frame) to introduce the necessary rotation over Z (of pi rad).
      -->
    <origin rpy="0 0 3.141592653589793" xyz="0 0 0"/>
  </joint>
  <joint name="shoulder_pan_joint" type="revolute">
    <parent link="base_link_inertia"/>
    <child link="shoulder_link"/>
    <origin rpy="0 0 0" xyz="0 0 0.1625"/>
    <axis xyz="0 0 1"/>
    <limit effort="150.0" lower="-6.283185307179586" upper="6.283185307179586" velocity="3.141592653589793"/>
    <dynamics damping="0" friction="0"/>
  </joint>
  <joint name="shoulder_lift_joint" type="revolute">
    <parent link="shoulder_link"/>
    <child link="upper_arm_link"/>
    <origin rpy="1.570796327 0 0" xyz="0 0 0"/>
    <axis xyz="0 0 1"/>
    <limit effort="150.0" lower="-6.283185307179586" upper="6.283185307179586" velocity="3.141592653589793"/>
    <dynamics damping="0" friction="0"/>
  </joint>
  <joint name="elbow_joint" type="revolute">
    <parent link="upper_arm_link"/>
    <child link="forearm_link"/>
    <origin rpy="0 0 0" xyz="-0.425 0 0"/>
    <axis xyz="0 0 1"/>
    <limit effort="150.0" lower="-3.141592653589793" upper="3.141592653589793" velocity="3.141592653589793"/>
    <dynamics damping="0" friction="0"/>
  </joint>
  <joint name="wrist_1_joint" type="revolute">
    <parent link="forearm_link"/>
    <child link="wrist_1_link"/>
    <origin rpy="0 0 0" xyz="-0.3922 0 0.1333"/>
    <axis xyz="0 0 1"/>
    <limit effort="28.0" lower="-6.283185307179586" upper="6.283185307179586" velocity="3.141592653589793"/>
    <dynamics damping="0" friction="0"/>
  </joint>
  <joint name="wrist_2_joint" type="revolute">
    <parent link="wrist_1_link"/>
    <child link="wrist_2_link"/>
    <origin rpy="1.570796327 0 0" xyz="0 -0.0997 -2.044881182297852e-11"/>
    <axis xyz="0 0 1"/>
    <limit effort="28.0" lower="-6.283185307179586" upper="6.283185307179586" velocity="3.141592653589793"/>
    <dynamics damping="0" friction="0"/>
  </joint>
  <joint name="wrist_3_joint" type="revolute">
    <parent link="wrist_2_link"/>
    <child link="wrist_3_link"/>
    <origin rpy="1.570796326589793 4.71238898018 3.141592653589793" xyz="0 0.0996 -2.042830148012698e-11"/>
    <axis xyz="0 0 1"/>
    <limit effort="28.0" lower="-6.283185307179586" upper="6.283185307179586" velocity="3.141592653589793"/>
    <dynamics damping="0" friction="0"/>
  </joint>
  <!-- ROS-Industrial 'base' frame: base_link to UR 'Base' Coordinates transform -->
  <link name="base"/>
  <joint name="base_link-base_fixed_joint" type="fixed">
    <!-- Note the rotation over Z of pi radians: as base_link is REP-103
           aligned (ie: has X+ forward, Y+ left and Z+ up), this is needed
           to correctly align 'base' with the 'Base' coordinate system of
           the UR controller.
      -->
    <origin rpy="0 0 3.141592653589793" xyz="0 0 0"/>
    <parent link="base_link"/>
    <child link="base"/>
  </joint>
  <!-- ROS-Industrial 'flange' frame: attachment point for EEF models -->
  <link name="flange"/>
  <joint name="wrist_3-flange" type="fixed">
    <parent link="wrist_3_link"/>
    <child link="flange"/>
    <origin rpy="0 -1.5707963267948966 -1.5707963267948966" xyz="0 0 0"/>
  </joint>
  <!-- ROS-Industrial 'tool0' frame: all-zeros tool frame -->
  <link name="tool0"/>
  <joint name="flange-tool0" type="fixed">
    <!-- default toolframe: X+ left, Y+ up, Z+ front -->
    <origin rpy="1.5707963267948966 0 1.5707963267948966" xyz="0 0 0"/>
    <parent link="flange"/>
    <child link="tool0"/>
  </joint>
  <joint name="robot_to_table" type="fixed">
    <parent link="robot_mount"/>
    <child link="base_link"/>
    <origin rpy="0 0 0" xyz="0 0 0"/>
  </joint>
  <link name="ur_bracket">
    <visual>
      <origin rpy="0 -0 0" xyz="0 0 0"/>
      <geometry>
        <mesh filename="package://coro_descriptions/meshes/ur_bracket.stl"/>
      </geometry>
      <material name="ur_bracket_material">
        <color rgba="0.615686 0.811765 0.929412 1.0"/>
      </material>
    </visual>
    <collision>
      <origin rpy="0 -0 0" xyz="0 0 0"/>
      <geometry>
        <mesh filename="package://coro_descriptions/meshes/ur_bracket.stl"/>
      </geometry>
      <material name="ur_bracket_material">
        <color rgba="0.615686 0.811765 0.929412 1.0"/>
      </material>
    </collision>
    <inertial>
      <origin rpy="0 0 0" xyz="0.0271498 0.0180673 -0.00967187"/>
      <mass value="0.05307"/>
      <inertia ixx="1.71151e-05" ixy="0" ixz="0" iyy="1.50513e-05" iyz="1.25799e-06" izz="2.94394e-05"/>
    </inertial>
  </link>
  <!-- Mount the coupling to the robot side -->
  <joint name="coupling_robot_fix" type="fixed">
    <origin rpy="0 0 1.5707963267948966" xyz="0 0 0.01"/>
    <parent link="tool0"/>
    <child link="ur_bracket"/>
  </joint>
  <!-- Mount the gripper to the coupling -->
  <link name="coupling_gripper_fix"/>
  <joint name="coupling_to_gripper" type="fixed">
    <parent link="ur_bracket"/>
    <child link="coupling_gripper_fix"/>
    <origin rpy="0 0 0" xyz="0 0 0"/>
  </joint>
  <!-- GRIPPER -->
  <joint name="gripper_base_joint" type="fixed">
    <origin rpy="0 0 0" xyz="0 -0.041 0.105"/>
    <parent link="coupling_gripper_fix"/>
    <child link="palm_link"/>
  </joint>
  <link name="palm_link">
    <visual>
      <origin rpy="3.14159 -0 0" xyz="0 0.034 -0.002"/>
      <geometry>
        <mesh filename="package://allegro_hand_description/meshes/g_r2.stl"/>
      </geometry>
      <material name="g_r2_material">
        <color rgba="0.2 0.2 0.2 1.0"/>
      </material>
    </visual>
    <collision>
      <origin rpy="3.14159 -0 0" xyz="0 0.034 -0.002"/>
      <geometry>
        <mesh filename="package://allegro_hand_description/meshes/g_r2.stl"/>
      </geometry>
      <material name="g_r2_material">
        <color rgba="0.2 0.2 0.2 1.0"/>
      </material>
    </collision>
    <inertial>
      <origin rpy="0 0 0" xyz="-0.00043535 0.0160404 -0.0404815"/>
      <mass value="0.404445"/>
      <inertia ixx="0.000491371" ixy="-9.01723e-06" ixz="1.17974e-05" iyy="0.000773265" iyz="-5.50867e-06" izz="0.000547843"/>
    </inertial>
  </link>
  <link name="link_0">
    <visual>
      <origin rpy="1.5708 6.16298e-33 -5.3926e-33" xyz="0 6.93889e-18 -0.0152"/>
      <geometry>
        <mesh filename="package://allegro_hand_description/meshes/extended_finger_base.stl"/>
      </geometry>
      <material name="extended_finger_base_material">
        <color rgba="0.647059 0.647059 0.647059 1.0"/>
      </material>
    </visual>
    <collision>
      <origin rpy="1.5708 6.16298e-33 -5.3926e-33" xyz="0 6.93889e-18 -0.0152"/>
      <geometry>
        <mesh filename="package://allegro_hand_description/meshes/extended_finger_base.stl"/>
      </geometry>
      <material name="extended_finger_base_material">
        <color rgba="0.647059 0.647059 0.647059 1.0"/>
      </material>
    </collision>
    <inertial>
      <origin rpy="0 0 0" xyz="-0.00041342 0.000666149 0.00960564"/>
      <mass value="0.0136672"/>
      <inertia ixx="2.13441e-06" ixy="5.86704e-10" ixz="-7.9563e-08" iyy="1.24411e-06" iyz="-6.13056e-08" izz="1.671e-06"/>
    </inertial>
  </link>
  <link name="link_1">
    <visual>
      <origin rpy="4.1618e-29 1.48353 -3.14159" xyz="-0.0182688 0 -0.0317805"/>
      <geometry>
        <mesh filename="package://allegro_hand_description/meshes/p2_r6.stl"/>
      </geometry>
      <material name="p2_r6_material">
        <color rgba="0.129412 0.129412 0.129412 1.0"/>
      </material>
    </visual>
    <collision>
      <origin rpy="4.1618e-29 1.48353 -3.14159" xyz="-0.0182688 0 -0.0317805"/>
      <geometry>
        <mesh filename="package://allegro_hand_description/meshes/p2_r6.stl"/>
      </geometry>
      <material name="p2_r6_material">
        <color rgba="0.129412 0.129412 0.129412 1.0"/>
      </material>
    </collision>
    <inertial>
      <origin rpy="0 0 0" xyz="0.027 9.54536e-05 0.0124409"/>
      <mass value="0.0418346"/>
      <inertia ixx="4.00114e-06" ixy="-1.81985e-08" ixz="-4.42841e-15" iyy="1.97927e-05" iyz="1.59578e-08" izz="1.88563e-05"/>
    </inertial>
  </link>
  <link name="link_2">
    <visual>
      <origin rpy="-4.37532e-31 1.48353 -2.11032e-30" xyz="0.0722688 -3.46945e-17 -0.0317805"/>
      <geometry>
        <mesh filename="package://allegro_hand_description/meshes/extended_fingertop.stl"/>
      </geometry>
      <material name="extended_fingertop_material">
        <color rgba="0.647059 0.647059 0.647059 1.0"/>
      </material>
    </visual>
    <collision>
      <origin rpy="-4.37532e-31 1.48353 -2.11032e-30" xyz="0.0722688 -3.46945e-17 -0.0317805"/>
      <geometry>
        <mesh filename="package://allegro_hand_description/meshes/extended_fingertop.stl"/>
      </geometry>
      <material name="extended_fingertop_material">
        <color rgba="0.647059 0.647059 0.647059 1.0"/>
      </material>
    </collision>
    <inertial>
      <origin rpy="0 0 0" xyz="-0.0294592 -0.000104104 0.0123435"/>
      <mass value="0.0318021"/>
      <inertia ixx="3.48619e-06" ixy="1.20808e-07" ixz="6.2918e-07" iyy="8.82437e-06" iyz="5.78644e-09" izz="7.34771e-06"/>
    </inertial>
  </link>
  <link name="link_3">
    <visual>
      <origin rpy="-3.14159 -2.46519e-32 -1.5708" xyz="0.1253 -5.55112e-17 0.0118"/>
      <geometry>
        <mesh filename="package://allegro_hand_description/meshes/p4_r.stl"/>
      </geometry>
      <material name="p4_r_material">
        <color rgba="0.129412 0.129412 0.129412 1.0"/>
      </material>
    </visual>
    <collision>
      <origin rpy="-3.14159 -2.46519e-32 -1.5708" xyz="0.1253 -5.55112e-17 0.0118"/>
      <geometry>
        <mesh filename="package://allegro_hand_description/meshes/p4_r.stl"/>
      </geometry>
      <material name="p4_r_material">
        <color rgba="0.129412 0.129412 0.129412 1.0"/>
      </material>
    </collision>
    <inertial>
      <origin rpy="0 0 0" xyz="-0.0100051 0.000639363 0.0123057"/>
      <mass value="0.0088374"/>
      <inertia ixx="1.08072e-06" ixy="-4.65695e-08" ixz="-3.42321e-08" iyy="1.11236e-06" iyz="-8.85024e-10" izz="5.61586e-07"/>
    </inertial>
  </link>
  <link name="ift_bracket">
    <visual>
      <origin rpy="-3.14159 -4.59709e-18 -1.08476e-31" xyz="-0.1139 -0.004 0.0135"/>
      <geometry>
        <mesh filename="package://allegro_hand_description/meshes/distal_pcbbase.stl"/>
      </geometry>
      <material name="distal_pcbbase_material">
        <color rgba="1 0.756863 0.054902 1.0"/>
      </material>
    </visual>
    <collision>
      <origin rpy="-3.14159 -4.59709e-18 -1.08476e-31" xyz="-0.1139 -0.004 0.0135"/>
      <geometry>
        <mesh filename="package://allegro_hand_description/meshes/distal_pcbbase.stl"/>
      </geometry>
      <material name="distal_pcbbase_material">
        <color rgba="1 0.756863 0.054902 1.0"/>
      </material>
    </collision>
    <inertial>
      <origin rpy="0 0 0" xyz="0.0170719 -0.00112911 0.0135244"/>
      <mass value="0.0155109"/>
      <inertia ixx="3.339e-06" ixy="-4.60426e-07" ixz="1.73449e-08" iyy="6.13257e-06" iyz="-6.39964e-10" izz="4.49513e-06"/>
    </inertial>
  </link>
  <link name="index_fingertip_main_fpcb">
    <visual>
      <origin rpy="-3.14159 -1.01561e-17 -5.74754e-32" xyz="-0.12166 0.01366 6.93889e-18"/>
      <geometry>
        <mesh filename="package://allegro_hand_description/meshes/distal_fpcb_1.stl"/>
      </geometry>
      <material name="distal_fpcb_1_material">
        <color rgba="0.768627 0.886275 0.952941 1.0"/>
      </material>
    </visual>
    <collision>
      <origin rpy="-3.14159 -1.01561e-17 -5.74754e-32" xyz="-0.12166 0.01366 6.93889e-18"/>
      <geometry>
        <mesh filename="package://allegro_hand_description/meshes/distal_fpcb_1.stl"/>
      </geometry>
      <material name="distal_fpcb_1_material">
        <color rgba="0.768627 0.886275 0.952941 1.0"/>
      </material>
    </collision>
    <inertial>
      <origin rpy="0 0 0" xyz="0.0183062 0.0208616 2.89858e-05"/>
      <mass value="0.00142203"/>
      <inertia ixx="3.14637e-07" ixy="-2.70173e-08" ixz="2.90739e-11" iyy="3.18951e-07" iyz="-3.25215e-10" izz="4.09623e-07"/>
    </inertial>
  </link>
  <joint name="joint_index_fingertip_main_fpcb" type="fixed">
    <origin rpy="3.95134e-15 -6.07352e-15 -3.889e-30" xyz="0.00776046 -0.01766 0.0135"/>
    <parent link="ift_bracket"/>
    <child link="index_fingertip_main_fpcb"/>
    <axis xyz="0 0 1"/>
    <limit effort="1" velocity="20"/>
    <joint_properties friction="0.0"/>
  </joint>
  <link name="index_fingertip_side_fpcb">
    <visual>
      <origin rpy="-1.32916e-32 6.97161e-18 -4.03248e-31" xyz="-0.153816 0.0136001 -0.0162593"/>
      <geometry>
        <mesh filename="package://allegro_hand_description/meshes/distal_fpcb_2.stl"/>
      </geometry>
      <material name="distal_fpcb_2_material">
        <color rgba="0.972549 0.529412 0.00392157 1.0"/>
      </material>
    </visual>
    <collision>
      <origin rpy="-1.32916e-32 6.97161e-18 -4.03248e-31" xyz="-0.153816 0.0136001 -0.0162593"/>
      <geometry>
        <mesh filename="package://allegro_hand_description/meshes/distal_fpcb_2.stl"/>
      </geometry>
      <material name="distal_fpcb_2_material">
        <color rgba="0.972549 0.529412 0.00392157 1.0"/>
      </material>
    </collision>
    <inertial>
      <origin rpy="0 0 0" xyz="-0.0175916 0.00317983 -0.0164175"/>
      <mass value="0.00128609"/>
      <inertia ixx="3.5341e-07" ixy="2.54188e-08" ixz="-2.1826e-09" iyy="3.67946e-07" iyz="1.2158e-09" izz="1.99436e-07"/>
    </inertial>
  </link>
  <joint name="joint_index_fingertip_side_fpcb" type="fixed">
    <origin rpy="-3.14159 1.29682e-17 1.10568e-30" xyz="0.0399163 0.0096 -0.00275858"/>
    <parent link="ift_bracket"/>
    <child link="index_fingertip_side_fpcb"/>
    <axis xyz="0 0 1"/>
    <limit effort="1" velocity="20"/>
    <joint_properties friction="0.0"/>
  </joint>
  <joint name="joint_index_fingertip_bracket" type="fixed">
    <origin rpy="3.14159 -5.14611e-15 3.14159" xyz="-0.0135 0.004 0.0254"/>
    <parent link="link_3"/>
    <child link="ift_bracket"/>
    <axis xyz="0 0 1"/>
    <limit effort="1" velocity="20"/>
    <joint_properties friction="0.0"/>
  </joint>
  <joint name="joint_3_0" type="revolute">
    <origin rpy="-4.33522e-16 1.57792e-15 -7.74196e-17" xyz="-0.04615 2.77556e-17 0.0001"/>
    <parent link="link_2"/>
    <child link="link_3"/>
    <axis xyz="0 0 1"/>
    <limit effort="15" lower="0" upper="1.47" velocity="20"/>
    <dynamics damping="1" friction="0.5"/>
    <gazebo>
      <implicitSpringDamper> true </implicitSpringDamper>
    </gazebo>
  </joint>
  <!-- *************************************Transmission************************************** -->
  <transmission name="trans_3_0">
    <type>transmission_interface/SimpleTransmission</type>
    <joint name="joint_3_0">
      <hardwareInterface>hardware_interface/EffortJointInterface</hardwareInterface>
    </joint>
    <actuator name="motor_3_0">
      <mechanicalReduction>1</mechanicalReduction>
    </actuator>
  </transmission>
  <!-- *************************************Transmission************************************** -->
  <link name="imf_bracket">
    <visual>
      <origin rpy="1.02267e-31 1.4662e-17 -1.62518e-30" xyz="-0.0755 -0.004 0.014"/>
      <geometry>
        <mesh filename="package://allegro_hand_description/meshes/medial_front.stl"/>
      </geometry>
      <material name="medial_front_material">
        <color rgba="1 0.756863 0.054902 1.0"/>
      </material>
    </visual>
    <collision>
      <origin rpy="1.02267e-31 1.4662e-17 -1.62518e-30" xyz="-0.0755 -0.004 0.014"/>
      <geometry>
        <mesh filename="package://allegro_hand_description/meshes/medial_front.stl"/>
      </geometry>
      <material name="medial_front_material">
        <color rgba="1 0.756863 0.054902 1.0"/>
      </material>
    </collision>
    <inertial>
      <origin rpy="0 0 0" xyz="0.00469281 0.00336791 0.0198072"/>
      <mass value="0.00473232"/>
      <inertia ixx="8.28869e-07" ixy="-2.96994e-07" ixz="2.53991e-07" iyy="1.55762e-06" iyz="2.23567e-07" izz="1.28629e-06"/>
    </inertial>
  </link>
  <link name="index_medial_front_fpcb">
    <visual>
      <origin rpy="-1.5708 -1.5708 0" xyz="-0.0129 0.0096 -0.1092"/>
      <geometry>
        <mesh filename="package://allegro_hand_description/meshes/medial_front_fpcb.stl"/>
      </geometry>
      <material name="medial_front_fpcb_material">
        <color rgba="0.980392 0.713725 0.00392157 1.0"/>
      </material>
    </visual>
    <collision>
      <origin rpy="-1.5708 -1.5708 0" xyz="-0.0129 0.0096 -0.1092"/>
      <geometry>
        <mesh filename="package://allegro_hand_description/meshes/medial_front_fpcb.stl"/>
      </geometry>
      <material name="medial_front_fpcb_material">
        <color rgba="0.980392 0.713725 0.00392157 1.0"/>
      </material>
    </collision>
    <inertial>
      <origin rpy="0 0 0" xyz="-0.00409182 0.0164946 -0.0268705"/>
      <mass value="0.00086951"/>
      <inertia ixx="2.73483e-07" ixy="9.10299e-08" ixz="5.0825e-08" iyy="1.4757e-07" iyz="-6.87648e-08" izz="3.07195e-07"/>
    </inertial>
  </link>
  <joint name="joint_index_medial_front_fpcb" type="fixed">
    <origin rpy="1.5708 -4.84955e-31 1.5708" xyz="0.0337 0.0089 0.0044"/>
    <parent link="imf_bracket"/>
    <child link="index_medial_front_fpcb"/>
    <axis xyz="0 0 1"/>
    <limit effort="1" velocity="20"/>
    <joint_properties friction="0.0"/>
  </joint>
  <joint name="joint_index_medial_front_bracket" type="fixed">
    <origin rpy="6.04764e-19 8.37023e-19 3.14159" xyz="-0.0215 -0.004 -0.0021"/>
    <parent link="link_2"/>
    <child link="imf_bracket"/>
    <axis xyz="0 0 1"/>
    <limit effort="1" velocity="20"/>
    <joint_properties friction="0.0"/>
  </joint>
  <link name="imb_bracket">
    <visual>
      <origin rpy="-3.14159 1.05207e-17 -8.74306e-31" xyz="-0.0755 -0.004 0.014"/>
      <geometry>
        <mesh filename="package://allegro_hand_description/meshes/medial_back.stl"/>
      </geometry>
      <material name="medial_back_material">
        <color rgba="1 0.756863 0.054902 1.0"/>
      </material>
    </visual>
    <collision>
      <origin rpy="-3.14159 1.05207e-17 -8.74306e-31" xyz="-0.0755 -0.004 0.014"/>
      <geometry>
        <mesh filename="package://allegro_hand_description/meshes/medial_back.stl"/>
      </geometry>
      <material name="medial_back_material">
        <color rgba="1 0.756863 0.054902 1.0"/>
      </material>
    </collision>
    <inertial>
      <origin rpy="0 0 0" xyz="0.0050369 0.00536951 0.0198823"/>
      <mass value="0.00531302"/>
      <inertia ixx="1.01036e-06" ixy="-2.70353e-07" ixz="2.64599e-07" iyy="1.7622e-06" iyz="2.24575e-07" izz="1.4134e-06"/>
    </inertial>
  </link>
  <link name="index_medial_back_fpcb">
    <visual>
      <origin rpy="-1.5708 -1.5708 0" xyz="0.0145 -0.014 -0.1092"/>
      <geometry>
        <mesh filename="package://allegro_hand_description/meshes/medial_back_fpcb.stl"/>
      </geometry>
      <material name="medial_back_fpcb_material">
        <color rgba="0.498039 0.498039 0.498039 1.0"/>
      </material>
    </visual>
    <collision>
      <origin rpy="-1.5708 -1.5708 0" xyz="0.0145 -0.014 -0.1092"/>
      <geometry>
        <mesh filename="package://allegro_hand_description/meshes/medial_back_fpcb.stl"/>
      </geometry>
      <material name="medial_back_fpcb_material">
        <color rgba="0.498039 0.498039 0.498039 1.0"/>
      </material>
    </collision>
    <inertial>
      <origin rpy="0 0 0" xyz="0.0031423 -0.0198367 -0.0257098"/>
      <mass value="0.000991462"/>
      <inertia ixx="2.93113e-07" ixy="-9.38799e-08" ixz="5.77704e-08" iyy="1.96504e-07" iyz="6.0309e-08" izz="3.52075e-07"/>
    </inertial>
  </link>
  <joint name="joint_index_medial_back_fpcb" type="fixed">
    <origin rpy="-1.5708 4.62281e-16 -1.5708" xyz="0.0337 0.0105 -1.73472e-16"/>
    <parent link="imb_bracket"/>
    <child link="index_medial_back_fpcb"/>
    <axis xyz="0 0 1"/>
    <limit effort="1" velocity="20"/>
    <joint_properties friction="0.0"/>
  </joint>
  <joint name="joint_index_medial_back_bracket" type="fixed">
    <origin rpy="3.14159 4.76628e-16 -3.14159" xyz="-0.0215 0.004 0.0259"/>
    <parent link="link_2"/>
    <child link="imb_bracket"/>
    <axis xyz="0 0 1"/>
    <limit effort="1" velocity="20"/>
    <joint_properties friction="0.0"/>
  </joint>
  <joint name="joint_2_0" type="revolute">
    <origin rpy="-1.93545e-14 4.22599e-15 -3.14159" xyz="0.054 2.28983e-16 7.63278e-17"/>
    <parent link="link_1"/>
    <child link="link_2"/>
    <axis xyz="0 0 1"/>
    <limit effort="15" lower="0" upper="1.5" velocity="20"/>
    <dynamics damping="1" friction="0.5"/>
    <gazebo>
      <implicitSpringDamper> true </implicitSpringDamper>
    </gazebo>
  </joint>
  <!-- *************************************Transmission************************************** -->
  <transmission name="trans_2_0">
    <type>transmission_interface/SimpleTransmission</type>
    <joint name="joint_2_0">
      <hardwareInterface>hardware_interface/EffortJointInterface</hardwareInterface>
    </joint>
    <actuator name="motor_2_0">
      <mechanicalReduction>1</mechanicalReduction>
    </actuator>
  </transmission>
  <!-- *************************************Transmission************************************** -->
  <link name="ipb_bracket">
    <visual>
      <origin rpy="-3.14159 -1.02743e-17 -5.1406e-31" xyz="-0.0249 -0.0037 0.014"/>
      <geometry>
        <mesh filename="package://allegro_hand_description/meshes/proximal_back.stl"/>
      </geometry>
      <material name="proximal_back_material">
        <color rgba="1 0.756863 0.054902 1.0"/>
      </material>
    </visual>
    <collision>
      <origin rpy="-3.14159 -1.02743e-17 -5.1406e-31" xyz="-0.0249 -0.0037 0.014"/>
      <geometry>
        <mesh filename="package://allegro_hand_description/meshes/proximal_back.stl"/>
      </geometry>
      <material name="proximal_back_material">
        <color rgba="1 0.756863 0.054902 1.0"/>
      </material>
    </collision>
    <inertial>
      <origin rpy="0 0 0" xyz="0.00190421 0.00603324 0.0192417"/>
      <mass value="0.00681742"/>
      <inertia ixx="1.33469e-06" ixy="-1.25087e-08" ixz="-1.65721e-09" iyy="2.12223e-06" iyz="3.02232e-07" izz="1.86525e-06"/>
    </inertial>
  </link>
  <link name="index_proximal_back_fpcb">
    <visual>
      <origin rpy="-1.5708 4.10881e-31 -1.43049e-17" xyz="0.0028 -0.0131 -0.0136"/>
      <geometry>
        <mesh filename="package://allegro_hand_description/meshes/proximal_back_fpcb.stl"/>
      </geometry>
      <material name="proximal_back_fpcb_material">
        <color rgba="0.917647 0.917647 0.917647 1.0"/>
      </material>
    </visual>
    <collision>
      <origin rpy="-1.5708 4.10881e-31 -1.43049e-17" xyz="0.0028 -0.0131 -0.0136"/>
      <geometry>
        <mesh filename="package://allegro_hand_description/meshes/proximal_back_fpcb.stl"/>
      </geometry>
      <material name="proximal_back_fpcb_material">
        <color rgba="0.917647 0.917647 0.917647 1.0"/>
      </material>
    </collision>
    <inertial>
      <origin rpy="0 0 0" xyz="0.0298338 -0.0157289 -0.000514151"/>
      <mass value="0.00110296"/>
      <inertia ixx="2.17583e-07" ixy="-7.11341e-10" ixz="-5.50926e-10" iyy="3.62763e-07" iyz="-5.1761e-08" izz="4.40838e-07"/>
    </inertial>
  </link>
  <joint name="joint_index_proximal_back_fpcb" type="fixed">
    <origin rpy="-1.5708 -1.40936e-17 -4.33377e-16" xyz="-0.0277 0.0099 0.0009"/>
    <parent link="ipb_bracket"/>
    <child link="index_proximal_back_fpcb"/>
    <axis xyz="0 0 1"/>
    <limit effort="1" velocity="20"/>
    <joint_properties friction="0.0"/>
  </joint>
  <joint name="joint_index_proximal_back_bracket" type="fixed">
    <origin rpy="-3.14159 -4.95527e-15 -2.49458e-28" xyz="0.0249 -0.0037 0.0253"/>
    <parent link="link_1"/>
    <child link="ipb_bracket"/>
    <axis xyz="0 0 1"/>
    <limit effort="1" velocity="20"/>
    <joint_properties friction="0.0"/>
  </joint>
  <link name="ipf_bracket">
    <visual>
      <origin rpy="3.99065e-30 -1.09742e-19 -6.90794e-32" xyz="-0.0249 -0.0077 0.014"/>
      <geometry>
        <mesh filename="package://allegro_hand_description/meshes/proximal_front.stl"/>
      </geometry>
      <material name="proximal_front_material">
        <color rgba="1 0.756863 0.054902 1.0"/>
      </material>
    </visual>
    <collision>
      <origin rpy="3.99065e-30 -1.09742e-19 -6.90794e-32" xyz="-0.0249 -0.0077 0.014"/>
      <geometry>
        <mesh filename="package://allegro_hand_description/meshes/proximal_front.stl"/>
      </geometry>
      <material name="proximal_front_material">
        <color rgba="1 0.756863 0.054902 1.0"/>
      </material>
    </collision>
    <inertial>
      <origin rpy="0 0 0" xyz="0.00266438 0.00143857 0.0191449"/>
      <mass value="0.00549452"/>
      <inertia ixx="8.30997e-07" ixy="-1.44805e-08" ixz="8.87855e-09" iyy="1.59352e-06" iyz="2.4142e-07" izz="1.37197e-06"/>
    </inertial>
  </link>
  <link name="index_proximal_front_fpcb">
    <visual>
      <origin rpy="-3.57712e-32 1.64408e-17 1.1487e-31" xyz="-0.0568 -0.013652 0.0096"/>
      <geometry>
        <mesh filename="package://allegro_hand_description/meshes/proximal_frontfpcb.stl"/>
      </geometry>
      <material name="proximal_frontfpcb_material">
        <color rgba="0.768627 0.886275 0.952941 1.0"/>
      </material>
    </visual>
    <collision>
      <origin rpy="-3.57712e-32 1.64408e-17 1.1487e-31" xyz="-0.0568 -0.013652 0.0096"/>
      <geometry>
        <mesh filename="package://allegro_hand_description/meshes/proximal_frontfpcb.stl"/>
      </geometry>
      <material name="proximal_frontfpcb_material">
        <color rgba="0.768627 0.886275 0.952941 1.0"/>
      </material>
    </collision>
    <inertial>
      <origin rpy="0 0 0" xyz="-0.0293893 -0.00228345 0.0126321"/>
      <mass value="0.000871809"/>
      <inertia ixx="1.32851e-07" ixy="-1.29621e-09" ixz="-1.28414e-09" iyy="3.08668e-07" iyz="3.73193e-08" izz="2.63246e-07"/>
    </inertial>
  </link>
  <joint name="joint_index_proximal_front_fpcb" type="fixed">
    <origin rpy="1.69568e-14 4.09448e-18 3.98238e-32" xyz="0.0319 0.00595201 0.0044"/>
    <parent link="ipf_bracket"/>
    <child link="index_proximal_front_fpcb"/>
    <axis xyz="0 0 1"/>
    <limit effort="1" velocity="20"/>
    <joint_properties friction="0.0"/>
  </joint>
  <joint name="joint_index_proximal_front_bracket" type="fixed">
    <origin rpy="1.74055e-15 -7.22547e-16 -8.65583e-16" xyz="0.0249 0.0077 -0.0017"/>
    <parent link="link_1"/>
    <child link="ipf_bracket"/>
    <axis xyz="0 0 1"/>
    <limit effort="1" velocity="20"/>
    <joint_properties friction="0.0"/>
  </joint>
  <joint name="joint_1_0" type="revolute">
    <origin rpy="-1.5708 -1.5708 0" xyz="6.93889e-18 -0.0119 0.02545"/>
    <parent link="link_0"/>
    <child link="link_1"/>
    <axis xyz="0 0 1"/>
    <limit effort="15" lower="0" upper="1.65" velocity="20"/>
    <dynamics damping="1" friction="0.5"/>
    <gazebo>
      <implicitSpringDamper> true </implicitSpringDamper>
    </gazebo>
  </joint>
  <!-- *************************************Transmission************************************** -->
  <transmission name="trans_1_0">
    <type>transmission_interface/SimpleTransmission</type>
    <joint name="joint_1_0">
      <hardwareInterface>hardware_interface/EffortJointInterface</hardwareInterface>
    </joint>
    <actuator name="motor_1_0">
      <mechanicalReduction>1</mechanicalReduction>
    </actuator>
  </transmission>
  <!-- *************************************Transmission************************************** -->
  <joint name="joint_0_0" type="revolute">
    <origin rpy="-0.0872665 -1.66533e-16 1.5708" xyz="-0.0435377 0.034 -0.00553922"/>
    <parent link="palm_link"/>
    <child link="link_0"/>
    <axis xyz="0 0 1"/>
    <limit effort="15" lower="-0.45" upper="0.55" velocity="20"/>
    <dynamics damping="1" friction="0.5"/>
    <gazebo>
      <implicitSpringDamper> true </implicitSpringDamper>
    </gazebo>
  </joint>
  <!-- *************************************Transmission************************************** -->
  <transmission name="trans_0_0">
    <type>transmission_interface/SimpleTransmission</type>
    <joint name="joint_0_0">
      <hardwareInterface>hardware_interface/EffortJointInterface</hardwareInterface>
    </joint>
    <actuator name="motor_0_0">
      <mechanicalReduction>1</mechanicalReduction>
    </actuator>
  </transmission>
  <!-- *************************************Transmission************************************** -->
  <link name="link_4">
    <visual>
      <origin rpy="1.5708 -0 1.53951e-48" xyz="0 -2.52778e-34 -0.0152"/>
      <geometry>
        <mesh filename="package://allegro_hand_description/meshes/extended_finger_base.stl"/>
      </geometry>
      <material name="extended_finger_base_material">
        <color rgba="0.647059 0.647059 0.647059 1.0"/>
      </material>
    </visual>
    <collision>
      <origin rpy="1.5708 -0 1.53951e-48" xyz="0 -2.52778e-34 -0.0152"/>
      <geometry>
        <mesh filename="package://allegro_hand_description/meshes/extended_finger_base.stl"/>
      </geometry>
      <material name="extended_finger_base_material">
        <color rgba="0.647059 0.647059 0.647059 1.0"/>
      </material>
    </collision>
    <inertial>
      <origin rpy="0 0 0" xyz="-0.00041342 0.000666149 0.00960564"/>
      <mass value="0.0136672"/>
      <inertia ixx="2.13441e-06" ixy="5.86704e-10" ixz="-7.9563e-08" iyy="1.24411e-06" iyz="-6.13056e-08" izz="1.671e-06"/>
    </inertial>
  </link>
  <link name="link_5">
    <visual>
      <origin rpy="5.013e-31 1.48353 -2.03181e-30" xyz="0.0182688 0 -0.0317805"/>
      <geometry>
        <mesh filename="package://allegro_hand_description/meshes/p2_r6.stl"/>
      </geometry>
      <material name="p2_r6_material">
        <color rgba="0.129412 0.129412 0.129412 1.0"/>
      </material>
    </visual>
    <collision>
      <origin rpy="5.013e-31 1.48353 -2.03181e-30" xyz="0.0182688 0 -0.0317805"/>
      <geometry>
        <mesh filename="package://allegro_hand_description/meshes/p2_r6.stl"/>
      </geometry>
      <material name="p2_r6_material">
        <color rgba="0.129412 0.129412 0.129412 1.0"/>
      </material>
    </collision>
    <inertial>
      <origin rpy="0 0 0" xyz="-0.027 -9.54536e-05 0.0124409"/>
      <mass value="0.0418346"/>
      <inertia ixx="4.44908e-06" ixy="2.0693e-08" ixz="2.54038e-06" iyy="1.97927e-05" iyz="1.25552e-08" izz="1.84084e-05"/>
    </inertial>
  </link>
  <link name="link_6">
    <visual>
      <origin rpy="-4.01371e-31 1.48353 4.99346e-31" xyz="0.0722688 -3.46945e-17 -0.0317805"/>
      <geometry>
        <mesh filename="package://allegro_hand_description/meshes/extended_fingertop.stl"/>
      </geometry>
      <material name="extended_fingertop_material">
        <color rgba="0.647059 0.647059 0.647059 1.0"/>
      </material>
    </visual>
    <collision>
      <origin rpy="-4.01371e-31 1.48353 4.99346e-31" xyz="0.0722688 -3.46945e-17 -0.0317805"/>
      <geometry>
        <mesh filename="package://allegro_hand_description/meshes/extended_fingertop.stl"/>
      </geometry>
      <material name="extended_fingertop_material">
        <color rgba="0.647059 0.647059 0.647059 1.0"/>
      </material>
    </collision>
    <inertial>
      <origin rpy="0 0 0" xyz="-0.0294592 -0.000104104 0.0123435"/>
      <mass value="0.0318021"/>
      <inertia ixx="3.48619e-06" ixy="1.20808e-07" ixz="6.2918e-07" iyy="8.82437e-06" iyz="5.78644e-09" izz="7.34771e-06"/>
    </inertial>
  </link>
  <link name="link_7">
    <visual>
      <origin rpy="3.14159 1.26544e-33 -1.5708" xyz="0.1253 -6.245e-17 0.0118"/>
      <geometry>
        <mesh filename="package://allegro_hand_description/meshes/p4_r.stl"/>
      </geometry>
      <material name="p4_r_material">
        <color rgba="0.129412 0.129412 0.129412 1.0"/>
      </material>
    </visual>
    <collision>
      <origin rpy="3.14159 1.26544e-33 -1.5708" xyz="0.1253 -6.245e-17 0.0118"/>
      <geometry>
        <mesh filename="package://allegro_hand_description/meshes/p4_r.stl"/>
      </geometry>
      <material name="p4_r_material">
        <color rgba="0.129412 0.129412 0.129412 1.0"/>
      </material>
    </collision>
    <inertial>
      <origin rpy="0 0 0" xyz="-0.0100051 0.000639363 0.0123057"/>
      <mass value="0.0088374"/>
      <inertia ixx="1.08072e-06" ixy="-4.65695e-08" ixz="-3.42321e-08" iyy="1.11236e-06" iyz="-8.85024e-10" izz="5.61586e-07"/>
    </inertial>
  </link>
  <link name="mft_bracket">
    <visual>
      <origin rpy="-3.14159 -1.35585e-31 -9.86076e-32" xyz="-0.1139 -0.004 0.0135"/>
      <geometry>
        <mesh filename="package://allegro_hand_description/meshes/distal_pcbbase.stl"/>
      </geometry>
      <material name="distal_pcbbase_material">
        <color rgba="1 0.756863 0.054902 1.0"/>
      </material>
    </visual>
    <collision>
      <origin rpy="-3.14159 -1.35585e-31 -9.86076e-32" xyz="-0.1139 -0.004 0.0135"/>
      <geometry>
        <mesh filename="package://allegro_hand_description/meshes/distal_pcbbase.stl"/>
      </geometry>
      <material name="distal_pcbbase_material">
        <color rgba="1 0.756863 0.054902 1.0"/>
      </material>
    </collision>
    <inertial>
      <origin rpy="0 0 0" xyz="0.0170719 -0.00112911 0.0135244"/>
      <mass value="0.0155109"/>
      <inertia ixx="3.339e-06" ixy="-4.60426e-07" ixz="1.73449e-08" iyy="6.13257e-06" iyz="-6.39964e-10" izz="4.49513e-06"/>
    </inertial>
  </link>
  <link name="middle_fingertip_main_fpcb">
    <visual>
      <origin rpy="3.14159 -1.84889e-32 2.52682e-31" xyz="-0.12166 0.01366 8.66006e-18"/>
      <geometry>
        <mesh filename="package://allegro_hand_description/meshes/distal_fpcb_1.stl"/>
      </geometry>
      <material name="distal_fpcb_1_material">
        <color rgba="0.768627 0.886275 0.952941 1.0"/>
      </material>
    </visual>
    <collision>
      <origin rpy="3.14159 -1.84889e-32 2.52682e-31" xyz="-0.12166 0.01366 8.66006e-18"/>
      <geometry>
        <mesh filename="package://allegro_hand_description/meshes/distal_fpcb_1.stl"/>
      </geometry>
      <material name="distal_fpcb_1_material">
        <color rgba="0.768627 0.886275 0.952941 1.0"/>
      </material>
    </collision>
    <inertial>
      <origin rpy="0 0 0" xyz="0.0183062 0.0208616 2.89858e-05"/>
      <mass value="0.00142203"/>
      <inertia ixx="3.14637e-07" ixy="-2.70173e-08" ixz="2.90739e-11" iyy="3.18951e-07" iyz="-3.25215e-10" izz="4.09623e-07"/>
    </inertial>
  </link>
  <joint name="joint_middle_fingertip_main_fpcb" type="fixed">
    <origin rpy="-4.82947e-15 -7.14706e-15 2.77556e-17" xyz="0.00776046 -0.01766 0.0135"/>
    <parent link="mft_bracket"/>
    <child link="middle_fingertip_main_fpcb"/>
    <axis xyz="0 0 1"/>
    <limit effort="1" velocity="20"/>
    <joint_properties friction="0.0"/>
  </joint>
  <link name="middle_fingertip_side_fpcb">
    <visual>
      <origin rpy="3.23556e-32 -3.82105e-31 -6.22461e-31" xyz="-0.153816 0.0136001 -0.0162593"/>
      <geometry>
        <mesh filename="package://allegro_hand_description/meshes/distal_fpcb_2.stl"/>
      </geometry>
      <material name="distal_fpcb_2_material">
        <color rgba="0.972549 0.529412 0.00392157 1.0"/>
      </material>
    </visual>
    <collision>
      <origin rpy="3.23556e-32 -3.82105e-31 -6.22461e-31" xyz="-0.153816 0.0136001 -0.0162593"/>
      <geometry>
        <mesh filename="package://allegro_hand_description/meshes/distal_fpcb_2.stl"/>
      </geometry>
      <material name="distal_fpcb_2_material">
        <color rgba="0.972549 0.529412 0.00392157 1.0"/>
      </material>
    </collision>
    <inertial>
      <origin rpy="0 0 0" xyz="-0.0175916 0.00317983 -0.0164175"/>
      <mass value="0.00128609"/>
      <inertia ixx="3.5341e-07" ixy="2.54188e-08" ixz="-2.1826e-09" iyy="3.67946e-07" iyz="1.2158e-09" izz="1.99436e-07"/>
    </inertial>
  </link>
  <joint name="joint_middle_fingertip_side_fpcb" type="fixed">
    <origin rpy="3.14159 -1.38778e-17 -2.77556e-17" xyz="0.0399163 0.0096 -0.00275858"/>
    <parent link="mft_bracket"/>
    <child link="middle_fingertip_side_fpcb"/>
    <axis xyz="0 0 1"/>
    <limit effort="1" velocity="20"/>
    <joint_properties friction="0.0"/>
  </joint>
  <joint name="joint_middle_fingertip_bracket" type="fixed">
    <origin rpy="3.14159 -8.32667e-16 -3.14159" xyz="-0.0135 0.004 0.0254"/>
    <parent link="link_7"/>
    <child link="mft_bracket"/>
    <axis xyz="0 0 1"/>
    <limit effort="1" velocity="20"/>
    <joint_properties friction="0.0"/>
  </joint>
  <joint name="joint_7_0" type="revolute">
    <origin rpy="-6.02043e-15 5.70882e-15 9.18658e-14" xyz="-0.04615 2.77556e-17 0.0001"/>
    <parent link="link_6"/>
    <child link="link_7"/>
    <axis xyz="0 0 1"/>
    <limit effort="15" lower="0" upper="1.47" velocity="20"/>
    <dynamics damping="1" friction="0.5"/>
    <gazebo>
      <implicitSpringDamper> true </implicitSpringDamper>
    </gazebo>
  </joint>
  <!-- *************************************Transmission************************************** -->
  <transmission name="trans_7_0">
    <type>transmission_interface/SimpleTransmission</type>
    <joint name="joint_7_0">
      <hardwareInterface>hardware_interface/EffortJointInterface</hardwareInterface>
    </joint>
    <actuator name="motor_7_0">
      <mechanicalReduction>1</mechanicalReduction>
    </actuator>
  </transmission>
  <!-- *************************************Transmission************************************** -->
  <link name="mmf_bracket">
    <visual>
      <origin rpy="7.74847e-32 -5.579e-32 3.0743e-30" xyz="-0.0755 -0.004 0.014"/>
      <geometry>
        <mesh filename="package://allegro_hand_description/meshes/medial_front.stl"/>
      </geometry>
      <material name="medial_front_material">
        <color rgba="1 0.756863 0.054902 1.0"/>
      </material>
    </visual>
    <collision>
      <origin rpy="7.74847e-32 -5.579e-32 3.0743e-30" xyz="-0.0755 -0.004 0.014"/>
      <geometry>
        <mesh filename="package://allegro_hand_description/meshes/medial_front.stl"/>
      </geometry>
      <material name="medial_front_material">
        <color rgba="1 0.756863 0.054902 1.0"/>
      </material>
    </collision>
    <inertial>
      <origin rpy="0 0 0" xyz="0.00469281 0.00336791 0.0198072"/>
      <mass value="0.00473232"/>
      <inertia ixx="8.28869e-07" ixy="-2.96994e-07" ixz="2.53991e-07" iyy="1.55762e-06" iyz="2.23567e-07" izz="1.28629e-06"/>
    </inertial>
  </link>
  <link name="middle_medial_front_fpcb">
    <visual>
      <origin rpy="-1.5708 -1.5708 0" xyz="-0.0129 0.0096 -0.1092"/>
      <geometry>
        <mesh filename="package://allegro_hand_description/meshes/medial_front_fpcb.stl"/>
      </geometry>
      <material name="medial_front_fpcb_material">
        <color rgba="0.980392 0.713725 0.00392157 1.0"/>
      </material>
    </visual>
    <collision>
      <origin rpy="-1.5708 -1.5708 0" xyz="-0.0129 0.0096 -0.1092"/>
      <geometry>
        <mesh filename="package://allegro_hand_description/meshes/medial_front_fpcb.stl"/>
      </geometry>
      <material name="medial_front_fpcb_material">
        <color rgba="0.980392 0.713725 0.00392157 1.0"/>
      </material>
    </collision>
    <inertial>
      <origin rpy="0 0 0" xyz="-0.00409182 0.0164946 -0.0268705"/>
      <mass value="0.00086951"/>
      <inertia ixx="2.73483e-07" ixy="9.10299e-08" ixz="5.0825e-08" iyy="1.4757e-07" iyz="-6.87648e-08" izz="3.07195e-07"/>
    </inertial>
  </link>
  <joint name="joint_middle_medial_front_fpcb" type="fixed">
    <origin rpy="1.5708 1.79259e-30 1.5708" xyz="0.0337 0.0089 0.0044"/>
    <parent link="mmf_bracket"/>
    <child link="middle_medial_front_fpcb"/>
    <axis xyz="0 0 1"/>
    <limit effort="1" velocity="20"/>
    <joint_properties friction="0.0"/>
  </joint>
  <joint name="joint_middle_medial_front_bracket" type="fixed">
    <origin rpy="-2.91434e-16 2.19124e-17 3.14159" xyz="-0.0215 -0.004 -0.0021"/>
    <parent link="link_6"/>
    <child link="mmf_bracket"/>
    <axis xyz="0 0 1"/>
    <limit effort="1" velocity="20"/>
    <joint_properties friction="0.0"/>
  </joint>
  <link name="mmb_bracket">
    <visual>
      <origin rpy="3.14159 6.80319e-32 5.68486e-30" xyz="-0.0755 -0.004 0.014"/>
      <geometry>
        <mesh filename="package://allegro_hand_description/meshes/medial_back.stl"/>
      </geometry>
      <material name="medial_back_material">
        <color rgba="1 0.756863 0.054902 1.0"/>
      </material>
    </visual>
    <collision>
      <origin rpy="3.14159 6.80319e-32 5.68486e-30" xyz="-0.0755 -0.004 0.014"/>
      <geometry>
        <mesh filename="package://allegro_hand_description/meshes/medial_back.stl"/>
      </geometry>
      <material name="medial_back_material">
        <color rgba="1 0.756863 0.054902 1.0"/>
      </material>
    </collision>
    <inertial>
      <origin rpy="0 0 0" xyz="0.0050369 0.00536951 0.0198823"/>
      <mass value="0.00531302"/>
      <inertia ixx="1.01036e-06" ixy="-2.70353e-07" ixz="2.64599e-07" iyy="1.7622e-06" iyz="2.24575e-07" izz="1.4134e-06"/>
    </inertial>
  </link>
  <link name="middle_medial_back_fpcb">
    <visual>
      <origin rpy="-1.5708 -1.5708 0" xyz="0.0145 -0.014 -0.1092"/>
      <geometry>
        <mesh filename="package://allegro_hand_description/meshes/medial_back_fpcb.stl"/>
      </geometry>
      <material name="medial_back_fpcb_material">
        <color rgba="0.498039 0.498039 0.498039 1.0"/>
      </material>
    </visual>
    <collision>
      <origin rpy="-1.5708 -1.5708 0" xyz="0.0145 -0.014 -0.1092"/>
      <geometry>
        <mesh filename="package://allegro_hand_description/meshes/medial_back_fpcb.stl"/>
      </geometry>
      <material name="medial_back_fpcb_material">
        <color rgba="0.498039 0.498039 0.498039 1.0"/>
      </material>
    </collision>
    <inertial>
      <origin rpy="0 0 0" xyz="0.0031423 -0.0198367 -0.0257098"/>
      <mass value="0.000991462"/>
      <inertia ixx="2.93113e-07" ixy="-9.38799e-08" ixz="5.77704e-08" iyy="1.96504e-07" iyz="6.0309e-08" izz="3.52075e-07"/>
    </inertial>
  </link>
  <joint name="joint_middle_medial_back_fpcb" type="fixed">
    <origin rpy="-1.5708 2.57582e-26 -1.5708" xyz="0.0337 0.0105 1.38778e-17"/>
    <parent link="mmb_bracket"/>
    <child link="middle_medial_back_fpcb"/>
    <axis xyz="0 0 1"/>
    <limit effort="1" velocity="20"/>
    <joint_properties friction="0.0"/>
  </joint>
  <joint name="joint_middle_medial_back_bracket" type="fixed">
    <origin rpy="-3.14159 -1.5933e-17 3.14159" xyz="-0.0215 0.004 0.0259"/>
    <parent link="link_6"/>
    <child link="mmb_bracket"/>
    <axis xyz="0 0 1"/>
    <limit effort="1" velocity="20"/>
    <joint_properties friction="0.0"/>
  </joint>
  <joint name="joint_6_0" type="revolute">
    <origin rpy="2.4529e-15 -5.42863e-15 3.19463e-15" xyz="-0.054 -1.66533e-16 -7.30319e-16"/>
    <parent link="link_5"/>
    <child link="link_6"/>
    <axis xyz="0 0 1"/>
    <limit effort="15" lower="0" upper="1.5" velocity="20"/>
    <dynamics damping="1" friction="0.5"/>
    <gazebo>
      <implicitSpringDamper> true </implicitSpringDamper>
    </gazebo>
  </joint>
  <!-- *************************************Transmission************************************** -->
  <transmission name="trans_6_0">
    <type>transmission_interface/SimpleTransmission</type>
    <joint name="joint_6_0">
      <hardwareInterface>hardware_interface/EffortJointInterface</hardwareInterface>
    </joint>
    <actuator name="motor_6_0">
      <mechanicalReduction>1</mechanicalReduction>
    </actuator>
  </transmission>
  <!-- *************************************Transmission************************************** -->
  <link name="mpb_bracket">
    <visual>
      <origin rpy="3.14159 -4.6691e-34 5.87245e-30" xyz="-0.0249 -0.0037 0.014"/>
      <geometry>
        <mesh filename="package://allegro_hand_description/meshes/proximal_back.stl"/>
      </geometry>
      <material name="proximal_back_material">
        <color rgba="1 0.756863 0.054902 1.0"/>
      </material>
    </visual>
    <collision>
      <origin rpy="3.14159 -4.6691e-34 5.87245e-30" xyz="-0.0249 -0.0037 0.014"/>
      <geometry>
        <mesh filename="package://allegro_hand_description/meshes/proximal_back.stl"/>
      </geometry>
      <material name="proximal_back_material">
        <color rgba="1 0.756863 0.054902 1.0"/>
      </material>
    </collision>
    <inertial>
      <origin rpy="0 0 0" xyz="0.00190421 0.00603324 0.0192417"/>
      <mass value="0.00681742"/>
      <inertia ixx="1.33469e-06" ixy="-1.25087e-08" ixz="-1.65721e-09" iyy="2.12223e-06" iyz="3.02232e-07" izz="1.86525e-06"/>
    </inertial>
  </link>
  <link name="middle_proximal_back_fpcb">
    <visual>
      <origin rpy="-1.5708 2.34367e-30 2.18567e-32" xyz="0.0028 -0.0131 -0.0136"/>
      <geometry>
        <mesh filename="package://allegro_hand_description/meshes/proximal_back_fpcb.stl"/>
      </geometry>
      <material name="proximal_back_fpcb_material">
        <color rgba="0.917647 0.917647 0.917647 1.0"/>
      </material>
    </visual>
    <collision>
      <origin rpy="-1.5708 2.34367e-30 2.18567e-32" xyz="0.0028 -0.0131 -0.0136"/>
      <geometry>
        <mesh filename="package://allegro_hand_description/meshes/proximal_back_fpcb.stl"/>
      </geometry>
      <material name="proximal_back_fpcb_material">
        <color rgba="0.917647 0.917647 0.917647 1.0"/>
      </material>
    </collision>
    <inertial>
      <origin rpy="0 0 0" xyz="0.0298338 -0.0157289 -0.000514151"/>
      <mass value="0.00110296"/>
      <inertia ixx="2.17583e-07" ixy="-7.11341e-10" ixz="-5.50926e-10" iyy="3.62763e-07" iyz="-5.1761e-08" izz="4.40838e-07"/>
    </inertial>
  </link>
  <joint name="joint_middle_proximal_back_fpcb" type="fixed">
    <origin rpy="-1.5708 1.69768e-31 -2.34367e-30" xyz="-0.0277 0.0099 0.0009"/>
    <parent link="mpb_bracket"/>
    <child link="middle_proximal_back_fpcb"/>
    <axis xyz="0 0 1"/>
    <limit effort="1" velocity="20"/>
    <joint_properties friction="0.0"/>
  </joint>
  <joint name="joint_middle_proximal_back_bracket" type="fixed">
    <origin rpy="-3.14159 4.05868e-15 3.14159" xyz="-0.0249 0.0037 0.0253"/>
    <parent link="link_5"/>
    <child link="mpb_bracket"/>
    <axis xyz="0 0 1"/>
    <limit effort="1" velocity="20"/>
    <joint_properties friction="0.0"/>
  </joint>
  <link name="mpf_bracket">
    <visual>
      <origin rpy="1.4926e-32 -3.38771e-31 -2.46519e-30" xyz="-0.0249 -0.0077 0.014"/>
      <geometry>
        <mesh filename="package://allegro_hand_description/meshes/proximal_front.stl"/>
      </geometry>
      <material name="proximal_front_material">
        <color rgba="1 0.756863 0.054902 1.0"/>
      </material>
    </visual>
    <collision>
      <origin rpy="1.4926e-32 -3.38771e-31 -2.46519e-30" xyz="-0.0249 -0.0077 0.014"/>
      <geometry>
        <mesh filename="package://allegro_hand_description/meshes/proximal_front.stl"/>
      </geometry>
      <material name="proximal_front_material">
        <color rgba="1 0.756863 0.054902 1.0"/>
      </material>
    </collision>
    <inertial>
      <origin rpy="0 0 0" xyz="0.00266438 0.00143857 0.0191449"/>
      <mass value="0.00549452"/>
      <inertia ixx="8.30997e-07" ixy="-1.44805e-08" ixz="8.87855e-09" iyy="1.59352e-06" iyz="2.4142e-07" izz="1.37197e-06"/>
    </inertial>
  </link>
  <link name="middle_proximal_front_fpcb">
    <visual>
      <origin rpy="-7.42927e-32 -1.59852e-31 1.64921e-29" xyz="-0.0568 -0.013652 0.0096"/>
      <geometry>
        <mesh filename="package://allegro_hand_description/meshes/proximal_frontfpcb.stl"/>
      </geometry>
      <material name="proximal_frontfpcb_material">
        <color rgba="0.768627 0.886275 0.952941 1.0"/>
      </material>
    </visual>
    <collision>
      <origin rpy="-7.42927e-32 -1.59852e-31 1.64921e-29" xyz="-0.0568 -0.013652 0.0096"/>
      <geometry>
        <mesh filename="package://allegro_hand_description/meshes/proximal_frontfpcb.stl"/>
      </geometry>
      <material name="proximal_frontfpcb_material">
        <color rgba="0.768627 0.886275 0.952941 1.0"/>
      </material>
    </collision>
    <inertial>
      <origin rpy="0 0 0" xyz="-0.0293893 -0.00228345 0.0126321"/>
      <mass value="0.000871809"/>
      <inertia ixx="1.32851e-07" ixy="-1.29621e-09" ixz="-1.28414e-09" iyy="3.08668e-07" iyz="3.73193e-08" izz="2.63246e-07"/>
    </inertial>
  </link>
  <joint name="joint_middle_proximal_front_fpcb" type="fixed">
    <origin rpy="-6.26539e-15 -5.20417e-18 5.55112e-17" xyz="0.0319 0.00595201 0.0044"/>
    <parent link="mpf_bracket"/>
    <child link="middle_proximal_front_fpcb"/>
    <axis xyz="0 0 1"/>
    <limit effort="1" velocity="20"/>
    <joint_properties friction="0.0"/>
  </joint>
  <joint name="joint_middle_proximal_front_bracket" type="fixed">
    <origin rpy="-1.96804e-15 3.74674e-16 3.14159" xyz="-0.0249 -0.0077 -0.0017"/>
    <parent link="link_5"/>
    <child link="mpf_bracket"/>
    <axis xyz="0 0 1"/>
    <limit effort="1" velocity="20"/>
    <joint_properties friction="0.0"/>
  </joint>
  <joint name="joint_5_0" type="revolute">
    <origin rpy="-1.5708 1.5708 0" xyz="-4.16334e-17 -0.0119 0.02545"/>
    <parent link="link_4"/>
    <child link="link_5"/>
    <axis xyz="0 0 1"/>
    <limit effort="15" lower="0" upper="1.65" velocity="20"/>
    <dynamics damping="1" friction="0.5"/>
    <gazebo>
      <implicitSpringDamper> true </implicitSpringDamper>
    </gazebo>
  </joint>
  <!-- *************************************Transmission************************************** -->
  <transmission name="trans_5_0">
    <type>transmission_interface/SimpleTransmission</type>
    <joint name="joint_5_0">
      <hardwareInterface>hardware_interface/EffortJointInterface</hardwareInterface>
    </joint>
    <actuator name="motor_5_0">
      <mechanicalReduction>1</mechanicalReduction>
    </actuator>
  </transmission>
  <!-- *************************************Transmission************************************** -->
  <joint name="joint_4_0" type="revolute">
    <origin rpy="0 -0 1.5708" xyz="-2.68398e-34 0.034 -0.0033"/>
    <parent link="palm_link"/>
    <child link="link_4"/>
    <axis xyz="0 0 1"/>
    <limit effort="15" lower="-0.55" upper="0.45" velocity="20"/>
    <dynamics damping="1" friction="0.5"/>
    <gazebo>
      <implicitSpringDamper> true </implicitSpringDamper>
    </gazebo>
  </joint>
  <!-- *************************************Transmission************************************** -->
  <transmission name="trans_4_0">
    <type>transmission_interface/SimpleTransmission</type>
    <joint name="joint_4_0">
      <hardwareInterface>hardware_interface/EffortJointInterface</hardwareInterface>
    </joint>
    <actuator name="motor_4_0">
      <mechanicalReduction>1</mechanicalReduction>
    </actuator>
  </transmission>
  <!-- *************************************Transmission************************************** -->
  <link name="link_8">
    <visual>
      <origin rpy="1.5708 -1.84889e-32 4.46816e-32" xyz="6.93889e-18 -6.93889e-18 -0.0152"/>
      <geometry>
        <mesh filename="package://allegro_hand_description/meshes/extended_finger_base.stl"/>
      </geometry>
      <material name="extended_finger_base_material">
        <color rgba="0.647059 0.647059 0.647059 1.0"/>
      </material>
    </visual>
    <collision>
      <origin rpy="1.5708 -1.84889e-32 4.46816e-32" xyz="6.93889e-18 -6.93889e-18 -0.0152"/>
      <geometry>
        <mesh filename="package://allegro_hand_description/meshes/extended_finger_base.stl"/>
      </geometry>
      <material name="extended_finger_base_material">
        <color rgba="0.647059 0.647059 0.647059 1.0"/>
      </material>
    </collision>
    <inertial>
      <origin rpy="0 0 0" xyz="-0.00041342 0.000666149 0.00960564"/>
      <mass value="0.0136672"/>
      <inertia ixx="2.13441e-06" ixy="5.86704e-10" ixz="-7.9563e-08" iyy="1.24411e-06" iyz="-6.13056e-08" izz="1.671e-06"/>
    </inertial>
  </link>
  <link name="link_9">
    <visual>
      <origin rpy="1.70593e-30 1.48353 -1.17581e-30" xyz="0.0182688 6.93889e-18 -0.0317805"/>
      <geometry>
        <mesh filename="package://allegro_hand_description/meshes/p2_r6.stl"/>
      </geometry>
      <material name="p2_r6_material">
        <color rgba="0.129412 0.129412 0.129412 1.0"/>
      </material>
    </visual>
    <collision>
      <origin rpy="1.70593e-30 1.48353 -1.17581e-30" xyz="0.0182688 6.93889e-18 -0.0317805"/>
      <geometry>
        <mesh filename="package://allegro_hand_description/meshes/p2_r6.stl"/>
      </geometry>
      <material name="p2_r6_material">
        <color rgba="0.129412 0.129412 0.129412 1.0"/>
      </material>
    </collision>
    <inertial>
      <origin rpy="0 0 0" xyz="-0.027 -9.54536e-05 0.0124409"/>
      <mass value="0.0418346"/>
      <inertia ixx="4.44908e-06" ixy="2.0693e-08" ixz="2.54038e-06" iyy="1.97927e-05" iyz="1.25552e-08" izz="1.84084e-05"/>
    </inertial>
  </link>
  <link name="link_10">
    <visual>
      <origin rpy="-6.3738e-31 1.48353 2.91843e-30" xyz="0.0722688 -4.16334e-17 -0.0317805"/>
      <geometry>
        <mesh filename="package://allegro_hand_description/meshes/extended_fingertop.stl"/>
      </geometry>
      <material name="extended_fingertop_material">
        <color rgba="0.647059 0.647059 0.647059 1.0"/>
      </material>
    </visual>
    <collision>
      <origin rpy="-6.3738e-31 1.48353 2.91843e-30" xyz="0.0722688 -4.16334e-17 -0.0317805"/>
      <geometry>
        <mesh filename="package://allegro_hand_description/meshes/extended_fingertop.stl"/>
      </geometry>
      <material name="extended_fingertop_material">
        <color rgba="0.647059 0.647059 0.647059 1.0"/>
      </material>
    </collision>
    <inertial>
      <origin rpy="0 0 0" xyz="-0.0294592 -0.000104104 0.0123435"/>
      <mass value="0.0318021"/>
      <inertia ixx="3.48619e-06" ixy="1.20808e-07" ixz="6.2918e-07" iyy="8.82437e-06" iyz="5.78644e-09" izz="7.34771e-06"/>
    </inertial>
  </link>
  <link name="link_11">
    <visual>
      <origin rpy="3.14159 -1.68249e-30 -1.5708" xyz="0.1253 -6.245e-17 0.0118"/>
      <geometry>
        <mesh filename="package://allegro_hand_description/meshes/p4_r.stl"/>
      </geometry>
      <material name="p4_r_material">
        <color rgba="0.129412 0.129412 0.129412 1.0"/>
      </material>
    </visual>
    <collision>
      <origin rpy="3.14159 -1.68249e-30 -1.5708" xyz="0.1253 -6.245e-17 0.0118"/>
      <geometry>
        <mesh filename="package://allegro_hand_description/meshes/p4_r.stl"/>
      </geometry>
      <material name="p4_r_material">
        <color rgba="0.129412 0.129412 0.129412 1.0"/>
      </material>
    </collision>
    <inertial>
      <origin rpy="0 0 0" xyz="-0.0100051 0.000639363 0.0123057"/>
      <mass value="0.0088374"/>
      <inertia ixx="1.08072e-06" ixy="-4.65695e-08" ixz="-3.42321e-08" iyy="1.11236e-06" iyz="-8.85024e-10" izz="5.61586e-07"/>
    </inertial>
  </link>
  <link name="pft_bracket">
    <visual>
      <origin rpy="-3.14159 1.28916e-17 -5.47827e-30" xyz="-0.1139 -0.004 0.0135"/>
      <geometry>
        <mesh filename="package://allegro_hand_description/meshes/distal_pcbbase.stl"/>
      </geometry>
      <material name="distal_pcbbase_material">
        <color rgba="1 0.756863 0.054902 1.0"/>
      </material>
    </visual>
    <collision>
      <origin rpy="-3.14159 1.28916e-17 -5.47827e-30" xyz="-0.1139 -0.004 0.0135"/>
      <geometry>
        <mesh filename="package://allegro_hand_description/meshes/distal_pcbbase.stl"/>
      </geometry>
      <material name="distal_pcbbase_material">
        <color rgba="1 0.756863 0.054902 1.0"/>
      </material>
    </collision>
    <inertial>
      <origin rpy="0 0 0" xyz="0.0170719 -0.00112911 0.0135244"/>
      <mass value="0.0155109"/>
      <inertia ixx="3.339e-06" ixy="-4.60426e-07" ixz="1.73449e-08" iyy="6.13257e-06" iyz="-6.39964e-10" izz="4.49513e-06"/>
    </inertial>
  </link>
  <link name="pinky_fingertip_main_fpcb">
    <visual>
      <origin rpy="-3.14159 1.9938e-17 -2.07776e-29" xyz="-0.12166 0.01366 1.38778e-17"/>
      <geometry>
        <mesh filename="package://allegro_hand_description/meshes/distal_fpcb_1.stl"/>
      </geometry>
      <material name="distal_fpcb_1_material">
        <color rgba="0.768627 0.886275 0.952941 1.0"/>
      </material>
    </visual>
    <collision>
      <origin rpy="-3.14159 1.9938e-17 -2.07776e-29" xyz="-0.12166 0.01366 1.38778e-17"/>
      <geometry>
        <mesh filename="package://allegro_hand_description/meshes/distal_fpcb_1.stl"/>
      </geometry>
      <material name="distal_fpcb_1_material">
        <color rgba="0.768627 0.886275 0.952941 1.0"/>
      </material>
    </collision>
    <inertial>
      <origin rpy="0 0 0" xyz="0.0183062 0.0208616 2.89858e-05"/>
      <mass value="0.00142203"/>
      <inertia ixx="3.14637e-07" ixy="-2.70173e-08" ixz="2.90739e-11" iyy="3.18951e-07" iyz="-3.25215e-10" izz="4.09623e-07"/>
    </inertial>
  </link>
  <joint name="joint_pinky_fingertip_main_fpcb" type="fixed">
    <origin rpy="-4.08652e-17 5.17584e-16 1.66533e-16" xyz="0.00776046 -0.01766 0.0135"/>
    <parent link="pft_bracket"/>
    <child link="pinky_fingertip_main_fpcb"/>
    <axis xyz="0 0 1"/>
    <limit effort="1" velocity="20"/>
    <joint_properties friction="0.0"/>
  </joint>
  <link name="pinky_fingertip_side_fpcb">
    <visual>
      <origin rpy="-3.60571e-31 -1.028e-17 -3.19673e-30" xyz="-0.153816 0.0136001 -0.0162593"/>
      <geometry>
        <mesh filename="package://allegro_hand_description/meshes/distal_fpcb_2.stl"/>
      </geometry>
      <material name="distal_fpcb_2_material">
        <color rgba="0.972549 0.529412 0.00392157 1.0"/>
      </material>
    </visual>
    <collision>
      <origin rpy="-3.60571e-31 -1.028e-17 -3.19673e-30" xyz="-0.153816 0.0136001 -0.0162593"/>
      <geometry>
        <mesh filename="package://allegro_hand_description/meshes/distal_fpcb_2.stl"/>
      </geometry>
      <material name="distal_fpcb_2_material">
        <color rgba="0.972549 0.529412 0.00392157 1.0"/>
      </material>
    </collision>
    <inertial>
      <origin rpy="0 0 0" xyz="-0.0175916 0.00317983 -0.0164175"/>
      <mass value="0.00128609"/>
      <inertia ixx="3.5341e-07" ixy="2.54188e-08" ixz="-2.1826e-09" iyy="3.67946e-07" iyz="1.2158e-09" izz="1.99436e-07"/>
    </inertial>
  </link>
  <joint name="joint_pinky_fingertip_side_fpcb" type="fixed">
    <origin rpy="-3.14159 5.15965e-17 5.55112e-17" xyz="0.0399163 0.0096 -0.00275858"/>
    <parent link="pft_bracket"/>
    <child link="pinky_fingertip_side_fpcb"/>
    <axis xyz="0 0 1"/>
    <limit effort="1" velocity="20"/>
    <joint_properties friction="0.0"/>
  </joint>
  <joint name="joint_pinky_fingertip_bracket" type="fixed">
    <origin rpy="3.14159 4.4328e-16 3.14159" xyz="-0.0135 0.004 0.0254"/>
    <parent link="link_11"/>
    <child link="pft_bracket"/>
    <axis xyz="0 0 1"/>
    <limit effort="1" velocity="20"/>
    <joint_properties friction="0.0"/>
  </joint>
  <joint name="joint_11_0" type="revolute">
    <origin rpy="-2.08897e-16 7.34965e-16 -9.23803e-14" xyz="-0.04615 2.08167e-17 0.0001"/>
    <parent link="link_10"/>
    <child link="link_11"/>
    <axis xyz="0 0 1"/>
    <limit effort="15" lower="0" upper="1.47" velocity="20"/>
    <dynamics damping="1" friction="0.5"/>
    <gazebo>
      <implicitSpringDamper> true </implicitSpringDamper>
    </gazebo>
  </joint>
  <!-- *************************************Transmission************************************** -->
  <transmission name="trans_11_0">
    <type>transmission_interface/SimpleTransmission</type>
    <joint name="joint_11_0">
      <hardwareInterface>hardware_interface/EffortJointInterface</hardwareInterface>
    </joint>
    <actuator name="motor_11_0">
      <mechanicalReduction>1</mechanicalReduction>
    </actuator>
  </transmission>
  <!-- *************************************Transmission************************************** -->
  <link name="pmf_bracket">
    <visual>
      <origin rpy="5.55513e-32 -1.31932e-17 -4.97361e-33" xyz="-0.0755 -0.004 0.014"/>
      <geometry>
        <mesh filename="package://allegro_hand_description/meshes/medial_front.stl"/>
      </geometry>
      <material name="medial_front_material">
        <color rgba="1 0.756863 0.054902 1.0"/>
      </material>
    </visual>
    <collision>
      <origin rpy="5.55513e-32 -1.31932e-17 -4.97361e-33" xyz="-0.0755 -0.004 0.014"/>
      <geometry>
        <mesh filename="package://allegro_hand_description/meshes/medial_front.stl"/>
      </geometry>
      <material name="medial_front_material">
        <color rgba="1 0.756863 0.054902 1.0"/>
      </material>
    </collision>
    <inertial>
      <origin rpy="0 0 0" xyz="0.00469281 0.00336791 0.0198072"/>
      <mass value="0.00473232"/>
      <inertia ixx="8.28869e-07" ixy="-2.96994e-07" ixz="2.53991e-07" iyy="1.55762e-06" iyz="2.23567e-07" izz="1.28629e-06"/>
    </inertial>
  </link>
  <link name="pinky_medial_front_fpcb">
    <visual>
      <origin rpy="-1.5708 -1.5708 0" xyz="-0.0129 0.0096 -0.1092"/>
      <geometry>
        <mesh filename="package://allegro_hand_description/meshes/medial_front_fpcb.stl"/>
      </geometry>
      <material name="medial_front_fpcb_material">
        <color rgba="0.980392 0.713725 0.00392157 1.0"/>
      </material>
    </visual>
    <collision>
      <origin rpy="-1.5708 -1.5708 0" xyz="-0.0129 0.0096 -0.1092"/>
      <geometry>
        <mesh filename="package://allegro_hand_description/meshes/medial_front_fpcb.stl"/>
      </geometry>
      <material name="medial_front_fpcb_material">
        <color rgba="0.980392 0.713725 0.00392157 1.0"/>
      </material>
    </collision>
    <inertial>
      <origin rpy="0 0 0" xyz="-0.00409182 0.0164946 -0.0268705"/>
      <mass value="0.00086951"/>
      <inertia ixx="2.73483e-07" ixy="9.10299e-08" ixz="5.0825e-08" iyy="1.4757e-07" iyz="-6.87648e-08" izz="3.07195e-07"/>
    </inertial>
  </link>
  <joint name="joint_pinky_medial_front_fpcb" type="fixed">
    <origin rpy="1.5708 -4.44891e-19 1.5708" xyz="0.0337 0.0089 0.0044"/>
    <parent link="pmf_bracket"/>
    <child link="pinky_medial_front_fpcb"/>
    <axis xyz="0 0 1"/>
    <limit effort="1" velocity="20"/>
    <joint_properties friction="0.0"/>
  </joint>
  <joint name="joint_pinky_medial_front_bracket" type="fixed">
    <origin rpy="5.55513e-32 -1.31932e-17 3.14159" xyz="-0.0215 -0.004 -0.0021"/>
    <parent link="link_10"/>
    <child link="pmf_bracket"/>
    <axis xyz="0 0 1"/>
    <limit effort="1" velocity="20"/>
    <joint_properties friction="0.0"/>
  </joint>
  <link name="pmb_bracket">
    <visual>
      <origin rpy="-3.14159 1.31932e-17 4.97361e-33" xyz="-0.0755 -0.004 0.014"/>
      <geometry>
        <mesh filename="package://allegro_hand_description/meshes/medial_back.stl"/>
      </geometry>
      <material name="medial_back_material">
        <color rgba="1 0.756863 0.054902 1.0"/>
      </material>
    </visual>
    <collision>
      <origin rpy="-3.14159 1.31932e-17 4.97361e-33" xyz="-0.0755 -0.004 0.014"/>
      <geometry>
        <mesh filename="package://allegro_hand_description/meshes/medial_back.stl"/>
      </geometry>
      <material name="medial_back_material">
        <color rgba="1 0.756863 0.054902 1.0"/>
      </material>
    </collision>
    <inertial>
      <origin rpy="0 0 0" xyz="0.0050369 0.00536951 0.0198823"/>
      <mass value="0.00531302"/>
      <inertia ixx="1.01036e-06" ixy="-2.70353e-07" ixz="2.64599e-07" iyy="1.7622e-06" iyz="2.24575e-07" izz="1.4134e-06"/>
    </inertial>
  </link>
  <link name="pinky_medial_back_fpcb">
    <visual>
      <origin rpy="-1.5708 -1.5708 0" xyz="0.0145 -0.014 -0.1092"/>
      <geometry>
        <mesh filename="package://allegro_hand_description/meshes/medial_back_fpcb.stl"/>
      </geometry>
      <material name="medial_back_fpcb_material">
        <color rgba="0.498039 0.498039 0.498039 1.0"/>
      </material>
    </visual>
    <collision>
      <origin rpy="-1.5708 -1.5708 0" xyz="0.0145 -0.014 -0.1092"/>
      <geometry>
        <mesh filename="package://allegro_hand_description/meshes/medial_back_fpcb.stl"/>
      </geometry>
      <material name="medial_back_fpcb_material">
        <color rgba="0.498039 0.498039 0.498039 1.0"/>
      </material>
    </collision>
    <inertial>
      <origin rpy="0 0 0" xyz="0.0031423 -0.0198367 -0.0257098"/>
      <mass value="0.000991462"/>
      <inertia ixx="2.93113e-07" ixy="-9.38799e-08" ixz="5.77704e-08" iyy="1.96504e-07" iyz="6.0309e-08" izz="3.52075e-07"/>
    </inertial>
  </link>
  <joint name="joint_pinky_medial_back_fpcb" type="fixed">
    <origin rpy="-1.5708 4.44891e-19 -1.5708" xyz="0.0337 0.0105 -4.51028e-17"/>
    <parent link="pmb_bracket"/>
    <child link="pinky_medial_back_fpcb"/>
    <axis xyz="0 0 1"/>
    <limit effort="1" velocity="20"/>
    <joint_properties friction="0.0"/>
  </joint>
  <joint name="joint_pinky_medial_back_bracket" type="fixed">
    <origin rpy="-3.14159 -1.31932e-17 3.14159" xyz="-0.0215 0.004 0.0259"/>
    <parent link="link_10"/>
    <child link="pmb_bracket"/>
    <axis xyz="0 0 1"/>
    <limit effort="1" velocity="20"/>
    <joint_properties friction="0.0"/>
  </joint>
  <joint name="joint_10_0" type="revolute">
    <origin rpy="7.38677e-17 -5.80172e-16 -7.55426e-16" xyz="-0.054 1.38778e-17 -1.249e-16"/>
    <parent link="link_9"/>
    <child link="link_10"/>
    <axis xyz="0 0 1"/>
    <limit effort="15" lower="0" upper="1.5" velocity="20"/>
    <dynamics damping="1" friction="0.5"/>
    <gazebo>
      <implicitSpringDamper> true </implicitSpringDamper>
    </gazebo>
  </joint>
  <!-- *************************************Transmission************************************** -->
  <transmission name="trans_10_0">
    <type>transmission_interface/SimpleTransmission</type>
    <joint name="joint_10_0">
      <hardwareInterface>hardware_interface/EffortJointInterface</hardwareInterface>
    </joint>
    <actuator name="motor_10_0">
      <mechanicalReduction>1</mechanicalReduction>
    </actuator>
  </transmission>
  <!-- *************************************Transmission************************************** -->
  <link name="ppb_bracket">
    <visual>
      <origin rpy="-3.14159 -1.11271e-19 2.71125e-32" xyz="-0.0249 -0.0037 0.014"/>
      <geometry>
        <mesh filename="package://allegro_hand_description/meshes/proximal_back.stl"/>
      </geometry>
      <material name="proximal_back_material">
        <color rgba="1 0.756863 0.054902 1.0"/>
      </material>
    </visual>
    <collision>
      <origin rpy="-3.14159 -1.11271e-19 2.71125e-32" xyz="-0.0249 -0.0037 0.014"/>
      <geometry>
        <mesh filename="package://allegro_hand_description/meshes/proximal_back.stl"/>
      </geometry>
      <material name="proximal_back_material">
        <color rgba="1 0.756863 0.054902 1.0"/>
      </material>
    </collision>
    <inertial>
      <origin rpy="0 0 0" xyz="0.00190421 0.00603324 0.0192417"/>
      <mass value="0.00681742"/>
      <inertia ixx="1.33469e-06" ixy="-1.25087e-08" ixz="-1.65721e-09" iyy="2.12223e-06" iyz="3.02232e-07" izz="1.86525e-06"/>
    </inertial>
  </link>
  <link name="pinky_proximal_back_fpcb">
    <visual>
      <origin rpy="-1.5708 2.2395e-32 5.32313e-18" xyz="0.0028 -0.0131 -0.0136"/>
      <geometry>
        <mesh filename="package://allegro_hand_description/meshes/proximal_back_fpcb.stl"/>
      </geometry>
      <material name="proximal_back_fpcb_material">
        <color rgba="0.917647 0.917647 0.917647 1.0"/>
      </material>
    </visual>
    <collision>
      <origin rpy="-1.5708 2.2395e-32 5.32313e-18" xyz="0.0028 -0.0131 -0.0136"/>
      <geometry>
        <mesh filename="package://allegro_hand_description/meshes/proximal_back_fpcb.stl"/>
      </geometry>
      <material name="proximal_back_fpcb_material">
        <color rgba="0.917647 0.917647 0.917647 1.0"/>
      </material>
    </collision>
    <inertial>
      <origin rpy="0 0 0" xyz="0.0298338 -0.0157289 -0.000514151"/>
      <mass value="0.00110296"/>
      <inertia ixx="2.17583e-07" ixy="-7.11341e-10" ixz="-5.50926e-10" iyy="3.62763e-07" iyz="-5.1761e-08" izz="4.40838e-07"/>
    </inertial>
  </link>
  <joint name="joint_pinky_proximal_back_fpcb" type="fixed">
    <origin rpy="-1.5708 -8.3852e-18 -7.27119e-30" xyz="-0.0277 0.0099 0.0009"/>
    <parent link="ppb_bracket"/>
    <child link="pinky_proximal_back_fpcb"/>
    <axis xyz="0 0 1"/>
    <limit effort="1" velocity="20"/>
    <joint_properties friction="0.0"/>
  </joint>
  <joint name="joint_pinky_proximal_back_bracket" type="fixed">
    <origin rpy="-3.14159 5.61195e-15 3.14159" xyz="-0.0249 0.0037 0.0253"/>
    <parent link="link_9"/>
    <child link="ppb_bracket"/>
    <axis xyz="0 0 1"/>
    <limit effort="1" velocity="20"/>
    <joint_properties friction="0.0"/>
  </joint>
  <link name="ppf_bracket">
    <visual>
      <origin rpy="-4.46045e-31 1.1948e-18 7.49935e-32" xyz="-0.0249 -0.0077 0.014"/>
      <geometry>
        <mesh filename="package://allegro_hand_description/meshes/proximal_front.stl"/>
      </geometry>
      <material name="proximal_front_material">
        <color rgba="1 0.756863 0.054902 1.0"/>
      </material>
    </visual>
    <collision>
      <origin rpy="-4.46045e-31 1.1948e-18 7.49935e-32" xyz="-0.0249 -0.0077 0.014"/>
      <geometry>
        <mesh filename="package://allegro_hand_description/meshes/proximal_front.stl"/>
      </geometry>
      <material name="proximal_front_material">
        <color rgba="1 0.756863 0.054902 1.0"/>
      </material>
    </collision>
    <inertial>
      <origin rpy="0 0 0" xyz="0.00266438 0.00143857 0.0191449"/>
      <mass value="0.00549452"/>
      <inertia ixx="8.30997e-07" ixy="-1.44805e-08" ixz="8.87855e-09" iyy="1.59352e-06" iyz="2.4142e-07" izz="1.37197e-06"/>
    </inertial>
  </link>
  <link name="pinky_proximal_front_fpcb">
    <visual>
      <origin rpy="1.31965e-30 -3.67426e-19 -1.38914e-31" xyz="-0.0568 -0.013652 0.0096"/>
      <geometry>
        <mesh filename="package://allegro_hand_description/meshes/proximal_frontfpcb.stl"/>
      </geometry>
      <material name="proximal_frontfpcb_material">
        <color rgba="0.768627 0.886275 0.952941 1.0"/>
      </material>
    </visual>
    <collision>
      <origin rpy="1.31965e-30 -3.67426e-19 -1.38914e-31" xyz="-0.0568 -0.013652 0.0096"/>
      <geometry>
        <mesh filename="package://allegro_hand_description/meshes/proximal_frontfpcb.stl"/>
      </geometry>
      <material name="proximal_frontfpcb_material">
        <color rgba="0.768627 0.886275 0.952941 1.0"/>
      </material>
    </collision>
    <inertial>
      <origin rpy="0 0 0" xyz="-0.0293893 -0.00228345 0.0126321"/>
      <mass value="0.000871809"/>
      <inertia ixx="1.32851e-07" ixy="-1.29621e-09" ixz="-1.28414e-09" iyy="3.08668e-07" iyz="3.73193e-08" izz="2.63246e-07"/>
    </inertial>
  </link>
  <joint name="joint_pinky_proximal_front_fpcb" type="fixed">
    <origin rpy="-5.00673e-15 6.88757e-19 -5.55112e-17" xyz="0.0319 0.00595201 0.0044"/>
    <parent link="ppf_bracket"/>
    <child link="pinky_proximal_front_fpcb"/>
    <axis xyz="0 0 1"/>
    <limit effort="1" velocity="20"/>
    <joint_properties friction="0.0"/>
  </joint>
  <joint name="joint_pinky_proximal_front_bracket" type="fixed">
    <origin rpy="-1.96935e-15 3.88558e-16 3.14159" xyz="-0.0249 -0.0077 -0.0017"/>
    <parent link="link_9"/>
    <child link="ppf_bracket"/>
    <axis xyz="0 0 1"/>
    <limit effort="1" velocity="20"/>
    <joint_properties friction="0.0"/>
  </joint>
  <joint name="joint_9_0" type="revolute">
    <origin rpy="-1.5708 1.5708 0" xyz="-1.38778e-17 -0.0119 0.02545"/>
    <parent link="link_8"/>
    <child link="link_9"/>
    <axis xyz="0 0 1"/>
    <limit effort="15" lower="0" upper="1.65" velocity="20"/>
    <dynamics damping="1" friction="0.5"/>
    <gazebo>
      <implicitSpringDamper> true </implicitSpringDamper>
    </gazebo>
  </joint>
  <!-- *************************************Transmission************************************** -->
  <transmission name="trans_9_0">
    <type>transmission_interface/SimpleTransmission</type>
    <joint name="joint_9_0">
      <hardwareInterface>hardware_interface/EffortJointInterface</hardwareInterface>
    </joint>
    <actuator name="motor_9_0">
      <mechanicalReduction>1</mechanicalReduction>
    </actuator>
  </transmission>
  <!-- *************************************Transmission************************************** -->
  <joint name="joint_8_0" type="revolute">
    <origin rpy="0.0872665 4.16334e-17 1.5708" xyz="0.0435377 0.034 -0.00553922"/>
    <parent link="palm_link"/>
    <child link="link_8"/>
    <axis xyz="0 0 1"/>
    <limit effort="15" lower="-0.45" upper="0.55" velocity="20"/>
    <dynamics damping="1" friction="0.5"/>
    <gazebo>
      <implicitSpringDamper> true </implicitSpringDamper>
    </gazebo>
  </joint>
  <!-- *************************************Transmission************************************** -->
  <transmission name="trans_8_0">
    <type>transmission_interface/SimpleTransmission</type>
    <joint name="joint_8_0">
      <hardwareInterface>hardware_interface/EffortJointInterface</hardwareInterface>
    </joint>
    <actuator name="motor_8_0">
      <mechanicalReduction>1</mechanicalReduction>
    </actuator>
  </transmission>
  <!-- *************************************Transmission************************************** -->
  <link name="link_12">
    <visual>
      <origin rpy="-2.48535e-33 -0.0872665 -2.25407e-32" xyz="0.0232805 -0.0182 -0.0808312"/>
      <geometry>
        <mesh filename="package://allegro_hand_description/meshes/f1_r.stl"/>
      </geometry>
      <material name="f1_r_material">
        <color rgba="0.129412 0.129412 0.129412 1.0"/>
      </material>
    </visual>
    <collision>
      <origin rpy="-2.48535e-33 -0.0872665 -2.25407e-32" xyz="0.0232805 -0.0182 -0.0808312"/>
      <geometry>
        <mesh filename="package://allegro_hand_description/meshes/f1_r.stl"/>
      </geometry>
      <material name="f1_r_material">
        <color rgba="0.129412 0.129412 0.129412 1.0"/>
      </material>
    </collision>
    <inertial>
      <origin rpy="0 0 0" xyz="-0.0151161 -0.00905831 -0.0192298"/>
      <mass value="0.0660275"/>
      <inertia ixx="1.44344e-05" ixy="1.24597e-06" ixz="3.47822e-08" iyy="1.76386e-05" iyz="6.49531e-07" izz="1.41981e-05"/>
    </inertial>
  </link>
  <link name="link_13">
    <visual>
      <origin rpy="1.5708 2.06898e-17 1.5708" xyz="-3.46945e-18 0 -0.0152"/>
      <geometry>
        <mesh filename="package://allegro_hand_description/meshes/extended_finger_base.stl"/>
      </geometry>
      <material name="extended_finger_base_material">
        <color rgba="0.647059 0.647059 0.647059 1.0"/>
      </material>
    </visual>
    <collision>
      <origin rpy="1.5708 2.06898e-17 1.5708" xyz="-3.46945e-18 0 -0.0152"/>
      <geometry>
        <mesh filename="package://allegro_hand_description/meshes/extended_finger_base.stl"/>
      </geometry>
      <material name="extended_finger_base_material">
        <color rgba="0.647059 0.647059 0.647059 1.0"/>
      </material>
    </collision>
    <inertial>
      <origin rpy="0 0 0" xyz="-0.000666149 -0.00041342 0.00960564"/>
      <mass value="0.0136672"/>
      <inertia ixx="1.671e-06" ixy="6.13056e-08" ixz="7.9563e-08" iyy="1.24411e-06" iyz="5.86704e-10" izz="2.13441e-06"/>
    </inertial>
  </link>
  <link name="link_14">
    <visual>
      <origin rpy="-1.5708 -6.24879e-32 0.0872665" xyz="0.0787805 -0.0716312 0.0251"/>
      <geometry>
        <mesh filename="package://allegro_hand_description/meshes/f3_r.stl"/>
      </geometry>
      <material name="f3_r_material">
        <color rgba="0.129412 0.129412 0.129412 1.0"/>
      </material>
    </visual>
    <collision>
      <origin rpy="-1.5708 -6.24879e-32 0.0872665" xyz="0.0787805 -0.0716312 0.0251"/>
      <geometry>
        <mesh filename="package://allegro_hand_description/meshes/f3_r.stl"/>
      </geometry>
      <material name="f3_r_material">
        <color rgba="0.129412 0.129412 0.129412 1.0"/>
      </material>
    </collision>
    <inertial>
      <origin rpy="0 0 0" xyz="-0.0169218 0.00050045 0.012098"/>
      <mass value="0.0307701"/>
      <inertia ixx="3.26297e-06" ixy="-7.80105e-07" ixz="4.19183e-07" iyy="9.45316e-06" iyz="7.40454e-08" izz="8.27249e-06"/>
    </inertial>
  </link>
  <link name="link_15">
    <visual>
      <origin rpy="-1.5708 -4.16204e-32 0.0872665" xyz="0.13018 -0.0716312 0.0252"/>
      <geometry>
        <mesh filename="package://allegro_hand_description/meshes/f4_r.stl"/>
      </geometry>
      <material name="f4_r_material">
        <color rgba="0.2 0.2 0.2 1.0"/>
      </material>
    </visual>
    <collision>
      <origin rpy="-1.5708 -4.16204e-32 0.0872665" xyz="0.13018 -0.0716312 0.0252"/>
      <geometry>
        <mesh filename="package://allegro_hand_description/meshes/f4_r.stl"/>
      </geometry>
      <material name="f4_r_material">
        <color rgba="0.2 0.2 0.2 1.0"/>
      </material>
    </collision>
    <inertial>
      <origin rpy="0 0 0" xyz="-0.0146717 0.000106021 0.012196"/>
      <mass value="0.0326938"/>
      <inertia ixx="2.85763e-06" ixy="-2.76566e-07" ixz="3.76274e-07" iyy="6.11217e-06" iyz="5.74019e-08" izz="5.36876e-06"/>
    </inertial>
  </link>
  <link name="tft_bracket">
    <visual>
      <origin rpy="-3.14159 -8.50715e-32 5.33917e-18" xyz="-0.1139 -0.004 0.0135"/>
      <geometry>
        <mesh filename="package://allegro_hand_description/meshes/distal_pcbbase.stl"/>
      </geometry>
      <material name="distal_pcbbase_material">
        <color rgba="1 0.756863 0.054902 1.0"/>
      </material>
    </visual>
    <collision>
      <origin rpy="-3.14159 -8.50715e-32 5.33917e-18" xyz="-0.1139 -0.004 0.0135"/>
      <geometry>
        <mesh filename="package://allegro_hand_description/meshes/distal_pcbbase.stl"/>
      </geometry>
      <material name="distal_pcbbase_material">
        <color rgba="1 0.756863 0.054902 1.0"/>
      </material>
    </collision>
    <inertial>
      <origin rpy="0 0 0" xyz="0.0170719 -0.00112911 0.0135244"/>
      <mass value="0.0155109"/>
      <inertia ixx="3.339e-06" ixy="-4.60426e-07" ixz="1.73449e-08" iyy="6.13257e-06" iyz="-6.39964e-10" izz="4.49513e-06"/>
    </inertial>
  </link>
  <link name="thumb_fingertip_main_fpcb">
    <visual>
      <origin rpy="-3.14159 1.09657e-31 8.05637e-18" xyz="-0.12166 0.01366 6.93889e-18"/>
      <geometry>
        <mesh filename="package://allegro_hand_description/meshes/distal_fpcb_1.stl"/>
      </geometry>
      <material name="distal_fpcb_1_material">
        <color rgba="0.768627 0.886275 0.952941 1.0"/>
      </material>
    </visual>
    <collision>
      <origin rpy="-3.14159 1.09657e-31 8.05637e-18" xyz="-0.12166 0.01366 6.93889e-18"/>
      <geometry>
        <mesh filename="package://allegro_hand_description/meshes/distal_fpcb_1.stl"/>
      </geometry>
      <material name="distal_fpcb_1_material">
        <color rgba="0.768627 0.886275 0.952941 1.0"/>
      </material>
    </collision>
    <inertial>
      <origin rpy="0 0 0" xyz="0.0183062 0.0208616 2.89858e-05"/>
      <mass value="0.00142203"/>
      <inertia ixx="3.14637e-07" ixy="-2.70173e-08" ixz="2.90739e-11" iyy="3.18951e-07" iyz="-3.25215e-10" izz="4.09623e-07"/>
    </inertial>
  </link>
  <joint name="joint_thumb_fingertip_main_fpcb" type="fixed">
    <origin rpy="8.63584e-16 -5.01319e-16 5.12794e-18" xyz="0.00776046 -0.01766 0.0135"/>
    <parent link="tft_bracket"/>
    <child link="thumb_fingertip_main_fpcb"/>
    <axis xyz="0 0 1"/>
    <limit effort="1" velocity="20"/>
    <joint_properties friction="0.0"/>
  </joint>
  <link name="thumb_fingertip_side_fpcb">
    <visual>
      <origin rpy="4.39229e-31 9.58935e-32 3.22237e-18" xyz="-0.153816 0.0136001 -0.0162593"/>
      <geometry>
        <mesh filename="package://allegro_hand_description/meshes/distal_fpcb_2.stl"/>
      </geometry>
      <material name="distal_fpcb_2_material">
        <color rgba="0.972549 0.529412 0.00392157 1.0"/>
      </material>
    </visual>
    <collision>
      <origin rpy="4.39229e-31 9.58935e-32 3.22237e-18" xyz="-0.153816 0.0136001 -0.0162593"/>
      <geometry>
        <mesh filename="package://allegro_hand_description/meshes/distal_fpcb_2.stl"/>
      </geometry>
      <material name="distal_fpcb_2_material">
        <color rgba="0.972549 0.529412 0.00392157 1.0"/>
      </material>
    </collision>
    <inertial>
      <origin rpy="0 0 0" xyz="-0.0175916 0.00317983 -0.0164175"/>
      <mass value="0.00128609"/>
      <inertia ixx="3.5341e-07" ixy="2.54188e-08" ixz="-2.1826e-09" iyy="3.67946e-07" iyz="1.2158e-09" izz="1.99436e-07"/>
    </inertial>
  </link>
  <joint name="joint_thumb_fingertip_side_fpcb" type="fixed">
    <origin rpy="-3.14159 -9.5307e-16 5.18075e-18" xyz="0.0399163 0.0096 -0.00275858"/>
    <parent link="tft_bracket"/>
    <child link="thumb_fingertip_side_fpcb"/>
    <axis xyz="0 0 1"/>
    <limit effort="1" velocity="20"/>
    <joint_properties friction="0.0"/>
  </joint>
  <joint name="joint_thumb_fingertip_bracket" type="fixed">
    <origin rpy="3.14159 5.80134e-16 -3.14159" xyz="-0.0291 0.0037 0.0253"/>
    <parent link="link_15"/>
    <child link="tft_bracket"/>
    <axis xyz="0 0 1"/>
    <limit effort="1" velocity="20"/>
    <joint_properties friction="0.0"/>
  </joint>
  <joint name="joint_15_0" type="revolute">
    <origin rpy="-4.53557e-16 3.39461e-16 2.07948e-13" xyz="-0.0514 -9.00668e-15 -0.0001"/>
    <parent link="link_14"/>
    <child link="link_15"/>
    <axis xyz="0 0 1"/>
    <limit effort="15" lower="0" upper="1.7" velocity="20"/>
    <dynamics damping="1" friction="0.5"/>
    <gazebo>
      <implicitSpringDamper> true </implicitSpringDamper>
    </gazebo>
  </joint>
  <!-- *************************************Transmission************************************** -->
  <transmission name="trans_15_0">
    <type>transmission_interface/SimpleTransmission</type>
    <joint name="joint_15_0">
      <hardwareInterface>hardware_interface/EffortJointInterface</hardwareInterface>
    </joint>
    <actuator name="motor_15_0">
      <mechanicalReduction>1</mechanicalReduction>
    </actuator>
  </transmission>
  <!-- *************************************Transmission************************************** -->
  <link name="tmb_bracket">
    <visual>
      <origin rpy="1.5708 2.25088e-31 -7.6622e-21" xyz="0.004 0.0329 0.014"/>
      <geometry>
        <mesh filename="package://allegro_hand_description/meshes/thumb_medial_back_bracket.stl"/>
      </geometry>
      <material name="thumb_medial_back_bracket_material">
        <color rgba="0.917647 0.917647 0.917647 1.0"/>
      </material>
    </visual>
    <collision>
      <origin rpy="1.5708 2.25088e-31 -7.6622e-21" xyz="0.004 0.0329 0.014"/>
      <geometry>
        <mesh filename="package://allegro_hand_description/meshes/thumb_medial_back_bracket.stl"/>
      </geometry>
      <material name="thumb_medial_back_bracket_material">
        <color rgba="0.917647 0.917647 0.917647 1.0"/>
      </material>
    </collision>
    <inertial>
      <origin rpy="0 0 0" xyz="-0.00600734 0.00588203 0.0181482"/>
      <mass value="0.00473763"/>
      <inertia ixx="1.11799e-06" ixy="-2.9649e-08" ixz="1.65587e-07" iyy="9.60308e-07" iyz="-6.32913e-08" izz="7.92445e-07"/>
    </inertial>
  </link>
  <link name="thumb_medial_back_fpcb">
    <visual>
      <origin rpy="3.14159 -5.47552e-15 -1.15148e-31" xyz="0.0148 -0.014 0.0052"/>
      <geometry>
        <mesh filename="package://allegro_hand_description/meshes/part_5.stl"/>
      </geometry>
      <material name="part_5_material">
        <color rgba="0.498039 0.498039 0.498039 1.0"/>
      </material>
    </visual>
    <collision>
      <origin rpy="3.14159 -5.47552e-15 -1.15148e-31" xyz="0.0148 -0.014 0.0052"/>
      <geometry>
        <mesh filename="package://allegro_hand_description/meshes/part_5.stl"/>
      </geometry>
      <material name="part_5_material">
        <color rgba="0.498039 0.498039 0.498039 1.0"/>
      </material>
    </collision>
    <inertial>
      <origin rpy="0 0 0" xyz="0.00190074 -0.0175205 -0.0182577"/>
      <mass value="0.000612423"/>
      <inertia ixx="1.31741e-07" ixy="2.80463e-08" ixz="-2.97582e-10" iyy="9.0628e-08" iyz="-2.06208e-08" izz="1.18557e-07"/>
    </inertial>
  </link>
  <joint name="joint_thumb_medial_back_fpcb" type="fixed">
    <origin rpy="-1.5708 7.27098e-31 -7.93211e-15" xyz="-0.0108 0.0277 -2.68882e-17"/>
    <parent link="tmb_bracket"/>
    <child link="thumb_medial_back_fpcb"/>
    <axis xyz="0 0 1"/>
    <limit effort="1" velocity="20"/>
    <joint_properties friction="0.0"/>
  </joint>
  <joint name="joint_thumb_medial_back_bracket" type="fixed">
    <origin rpy="-6.46681e-16 -1.5186e-15 -1.5708" xyz="-0.0249 0.004 -0.0022"/>
    <parent link="link_14"/>
    <child link="tmb_bracket"/>
    <axis xyz="0 0 1"/>
    <limit effort="1" velocity="20"/>
    <joint_properties friction="0.0"/>
  </joint>
  <link name="tmf_bracket">
    <visual>
      <origin rpy="-1.5708 -2.03975e-31 -2.00332e-19" xyz="-0.004 -0.0329 0.014"/>
      <geometry>
        <mesh filename="package://allegro_hand_description/meshes/thumb_medial_front_bracket.stl"/>
      </geometry>
      <material name="thumb_medial_front_bracket_material">
        <color rgba="0.917647 0.917647 0.917647 1.0"/>
      </material>
    </visual>
    <collision>
      <origin rpy="-1.5708 -2.03975e-31 -2.00332e-19" xyz="-0.004 -0.0329 0.014"/>
      <geometry>
        <mesh filename="package://allegro_hand_description/meshes/thumb_medial_front_bracket.stl"/>
      </geometry>
      <material name="thumb_medial_front_bracket_material">
        <color rgba="0.917647 0.917647 0.917647 1.0"/>
      </material>
    </collision>
    <inertial>
      <origin rpy="0 0 0" xyz="0.00534582 -0.00527635 0.0171061"/>
      <mass value="0.0040514"/>
      <inertia ixx="9.13083e-07" ixy="-5.82508e-09" ixz="-1.21819e-07" iyy="6.82814e-07" iyz="1.23951e-07" izz="5.97236e-07"/>
    </inertial>
  </link>
  <link name="thumb_medial_front_fpcb">
    <visual>
      <origin rpy="7.38033e-33 1.42291e-18 -4.44322e-31" xyz="-0.0140023 -0.007 -0.0052"/>
      <geometry>
        <mesh filename="package://allegro_hand_description/meshes/part_6.stl"/>
      </geometry>
      <material name="part_6_material">
        <color rgba="0.980392 0.713725 0.00392157 1.0"/>
      </material>
    </visual>
    <collision>
      <origin rpy="7.38033e-33 1.42291e-18 -4.44322e-31" xyz="-0.0140023 -0.007 -0.0052"/>
      <geometry>
        <mesh filename="package://allegro_hand_description/meshes/part_6.stl"/>
      </geometry>
      <material name="part_6_material">
        <color rgba="0.980392 0.713725 0.00392157 1.0"/>
      </material>
    </collision>
    <inertial>
      <origin rpy="0 0 0" xyz="-0.00221105 -0.0114519 0.0177349"/>
      <mass value="0.000462123"/>
      <inertia ixx="7.18561e-08" ixy="-1.49488e-08" ixz="-9.74587e-10" iyy="5.37528e-08" iyz="8.76508e-09" izz="5.33116e-08"/>
    </inertial>
  </link>
  <joint name="joint_thumb_medial_front_fpcb" type="fixed">
    <origin rpy="-1.5708 -5.1393e-32 5.59764e-15" xyz="0.0100023 -0.0277 0.007"/>
    <parent link="tmf_bracket"/>
    <child link="thumb_medial_front_fpcb"/>
    <axis xyz="0 0 1"/>
    <limit effort="1" velocity="20"/>
    <joint_properties friction="0.0"/>
  </joint>
  <joint name="joint_thumb_medial_front_bracket" type="fixed">
    <origin rpy="3.14159 -7.73741e-17 -1.5708" xyz="-0.0249 -0.004 0.0258"/>
    <parent link="link_14"/>
    <child link="tmf_bracket"/>
    <axis xyz="0 0 1"/>
    <limit effort="1" velocity="20"/>
    <joint_properties friction="0.0"/>
  </joint>
  <joint name="joint_14_0" type="revolute">
    <origin rpy="3.14159 1.5708 0" xyz="0.0119 -1.38778e-17 0.02545"/>
    <parent link="link_13"/>
    <child link="link_14"/>
    <axis xyz="0 0 1"/>
    <limit effort="15" lower="0" upper="1.45" velocity="20"/>
    <dynamics damping="1" friction="0.5"/>
    <gazebo>
      <implicitSpringDamper> true </implicitSpringDamper>
    </gazebo>
  </joint>
  <!-- *************************************Transmission************************************** -->
  <transmission name="trans_14_0">
    <type>transmission_interface/SimpleTransmission</type>
    <joint name="joint_14_0">
      <hardwareInterface>hardware_interface/EffortJointInterface</hardwareInterface>
    </joint>
    <actuator name="motor_14_0">
      <mechanicalReduction>1</mechanicalReduction>
    </actuator>
  </transmission>
  <!-- *************************************Transmission************************************** -->
  <joint name="joint_13_0" type="revolute">
    <origin rpy="-1.5708 -3.01469e-15 1.5708" xyz="-0.0375 -0.005 -0.0092"/>
    <parent link="link_12"/>
    <child link="link_13"/>
    <axis xyz="0 0 1"/>
    <limit effort="15" lower="-1.3" upper="1.15" velocity="20"/>
    <dynamics damping="1" friction="0.5"/>
    <gazebo>
      <implicitSpringDamper> true </implicitSpringDamper>
    </gazebo>
  </joint>
  <!-- *************************************Transmission************************************** -->
  <transmission name="trans_13_0">
    <type>transmission_interface/SimpleTransmission</type>
    <joint name="joint_13_0">
      <hardwareInterface>hardware_interface/EffortJointInterface</hardwareInterface>
    </joint>
    <actuator name="motor_13_0">
      <mechanicalReduction>1</mechanicalReduction>
    </actuator>
  </transmission>
  <!-- *************************************Transmission************************************** -->
  <joint name="joint_12_0" type="revolute">
    <origin rpy="-3.14159 -0.0872665 1.84398e-16" xyz="-0.0161208 0.0158 -0.0848515"/>
    <parent link="palm_link"/>
    <child link="link_12"/>
    <axis xyz="0 0 1"/>
    <limit effort="15" lower="0.35" upper="1.57" velocity="20"/>
    <dynamics damping="1" friction="0.5"/>
    <gazebo>
      <implicitSpringDamper> true </implicitSpringDamper>
    </gazebo>
  </joint>
  <!-- *************************************Transmission************************************** -->
  <transmission name="trans_12_0">
    <type>transmission_interface/SimpleTransmission</type>
    <joint name="joint_12_0">
      <hardwareInterface>hardware_interface/EffortJointInterface</hardwareInterface>
    </joint>
    <actuator name="motor_12_0">
      <mechanicalReduction>1</mechanicalReduction>
    </actuator>
  </transmission>
  <!-- *************************************Transmission************************************** -->
  <link name="boh_bracket">
    <visual>
      <origin rpy="-1.5708 -1.5708 0" xyz="0.02 0.007 0.0435"/>
      <geometry>
        <mesh filename="package://allegro_hand_description/meshes/part_4.stl"/>
      </geometry>
      <material name="part_4_material">
        <color rgba="0.980392 0.713725 0.00392157 1.0"/>
      </material>
    </visual>
    <collision>
      <origin rpy="-1.5708 -1.5708 0" xyz="0.02 0.007 0.0435"/>
      <geometry>
        <mesh filename="package://allegro_hand_description/meshes/part_4.stl"/>
      </geometry>
      <material name="part_4_material">
        <color rgba="0.980392 0.713725 0.00392157 1.0"/>
      </material>
    </collision>
    <inertial>
      <origin rpy="0 0 0" xyz="0.0205425 -0.0333769 -0.00325"/>
      <mass value="0.0385521"/>
      <inertia ixx="5.89511e-05" ixy="3.11147e-09" ixz="-3.78027e-07" iyy="9.09733e-05" iyz="4.84151e-09" izz="3.60656e-05"/>
    </inertial>
  </link>
  <link name="boh">
    <visual>
      <origin rpy="-1.5708 -1.5708 0" xyz="3.94708e-06 0.038896 0.0528"/>
      <geometry>
        <mesh filename="package://allegro_hand_description/meshes/boh_fpcb.stl"/>
      </geometry>
      <material name="boh_fpcb_material">
        <color rgba="0.615686 0.811765 0.929412 1.0"/>
      </material>
    </visual>
    <collision>
      <origin rpy="-1.5708 -1.5708 0" xyz="3.94708e-06 0.038896 0.0528"/>
      <geometry>
        <mesh filename="package://allegro_hand_description/meshes/boh_fpcb.stl"/>
      </geometry>
      <material name="boh_fpcb_material">
        <color rgba="0.615686 0.811765 0.929412 1.0"/>
      </material>
    </collision>
    <inertial>
      <origin rpy="0 0 0" xyz="3.00678e-07 -0.00328019 -3.42586e-05"/>
      <mass value="0.00784811"/>
      <inertia ixx="7.95811e-06" ixy="6.60039e-08" ixz="1.42447e-09" iyy="1.30113e-05" iyz="-6.22082e-12" izz="5.06377e-06"/>
    </inertial>
  </link>
  <joint name="joint_boh" type="fixed">
    <origin rpy="0 -0 0" xyz="0.019996 -0.0318962 -0.0093"/>
    <parent link="boh_bracket"/>
    <child link="boh"/>
    <axis xyz="0 0 1"/>
    <limit effort="1" velocity="20"/>
    <joint_properties friction="0.0"/>
  </joint>
  <joint name="joint_boh_bracket" type="fixed">
    <origin rpy="1.5708 -0 3.14159" xyz="0.02 -0.0094 -0.009"/>
    <parent link="palm_link"/>
    <child link="boh_bracket"/>
    <axis xyz="0 0 1"/>
    <limit effort="1" velocity="20"/>
    <joint_properties friction="0.0"/>
  </joint>
  <link name="palm_bracket">
    <visual>
      <origin rpy="1.5708 1.5708 0" xyz="-0.000254584 -0.095 0.0113"/>
      <geometry>
        <mesh filename="package://allegro_hand_description/meshes/palm_bracket.stl"/>
      </geometry>
      <material name="palm_bracket_material">
        <color rgba="0.231373 0.380392 0.705882 1.0"/>
      </material>
    </visual>
    <collision>
      <origin rpy="1.5708 1.5708 0" xyz="-0.000254584 -0.095 0.0113"/>
      <geometry>
        <mesh filename="package://allegro_hand_description/meshes/palm_bracket.stl"/>
      </geometry>
      <material name="palm_bracket_material">
        <color rgba="0.231373 0.380392 0.705882 1.0"/>
      </material>
    </collision>
    <inertial>
      <origin rpy="0 0 0" xyz="-0.0117692 -0.0440058 -0.00328358"/>
      <mass value="0.0366468"/>
      <inertia ixx="3.0726e-05" ixy="3.33674e-07" ixz="-2.90867e-06" iyy="5.36054e-05" iyz="1.29147e-07" izz="2.31158e-05"/>
    </inertial>
  </link>
  <link name="palm_fpcb">
    <visual>
      <origin rpy="1.5708 1.5708 0" xyz="0.02 -0.007 0.0173"/>
      <geometry>
        <mesh filename="package://allegro_hand_description/meshes/palm_fpcb.stl"/>
      </geometry>
      <material name="palm_fpcb_material">
        <color rgba="0.972549 0.529412 0.00392157 1.0"/>
      </material>
    </visual>
    <collision>
      <origin rpy="1.5708 1.5708 0" xyz="0.02 -0.007 0.0173"/>
      <geometry>
        <mesh filename="package://allegro_hand_description/meshes/palm_fpcb.stl"/>
      </geometry>
      <material name="palm_fpcb_material">
        <color rgba="0.972549 0.529412 0.00392157 1.0"/>
      </material>
    </collision>
    <inertial>
      <origin rpy="0 0 0" xyz="0.0127906 0.0241481 0.000227194"/>
      <mass value="0.00098458"/>
      <inertia ixx="7.85784e-07" ixy="-7.28774e-09" ixz="-1.89434e-07" iyy="1.25428e-06" iyz="-2.66202e-09" izz="4.70119e-07"/>
    </inertial>
  </link>
  <joint name="joint_palm_fpcb" type="fixed">
    <origin rpy="0 -0 0" xyz="-0.0202546 -0.088 -0.006"/>
    <parent link="palm_bracket"/>
    <child link="palm_fpcb"/>
    <axis xyz="0 0 1"/>
    <limit effort="1" velocity="20"/>
    <joint_properties friction="0.0"/>
  </joint>
  <joint name="joint_palm_bracket" type="fixed">
    <origin rpy="-1.5708 -0 3.14159" xyz="-0.000254584 0.0453 -0.097"/>
    <parent link="palm_link"/>
    <child link="palm_bracket"/>
    <axis xyz="0 0 1"/>
    <limit effort="1" velocity="20"/>
    <joint_properties friction="0.0"/>
  </joint>
  <link name="tcp"/>
  <joint name="tcp_to_gripper" type="fixed">
    <parent link="tool0"/>
    <child link="tcp"/>
    <origin rpy="0 0 0" xyz="0 0 0.165"/>
  </joint>
  <!-- OBJECT TO GRASP -->
  <link name="cubic_object_link">
    <visual>
      <origin rpy="0 -0 1.5708" xyz="0 0 0"/>
      <geometry>
        <mesh filename="package://coro_descriptions/meshes/cubic_object.stl"/>
      </geometry>
      <material name="link_testing_cube_material">
        <color rgba="0.615686 0.811765 0.929412 1.0"/>
      </material>
    </visual>
    <collision>
      <origin rpy="0 -0 1.5708" xyz="0 0 0"/>
      <geometry>
        <mesh filename="package://coro_descriptions/meshes/cubic_object.stl"/>
      </geometry>
      <material name="link_testing_cube_material">
        <color rgba="0.615686 0.811765 0.929412 1.0"/>
      </material>
    </collision>
    <inertial>
      <origin rpy="0 0 0" xyz="-1.02566e-17 9.23364e-19 0.1075"/>
      <mass value="0.0770781"/>
      <inertia ixx="0.000307188" ixy="0" ixz="0" iyy="0.000307188" iyz="0" izz="2.05542e-05"/>
    </inertial>
  </link>
  <joint name="object_to_table" type="fixed">
    <origin rpy="0 0 0" xyz="0.004217 -0.201201 1.016225"/>
    <parent link="table_base"/>
    <child link="cubic_object_link"/>
  </joint>
  <!-- GAZEBO -->
  <gazebo>
    <plugin filename="libgazebo_ros_control.so" name="gazebo_ros_control">
      <robotNamespace>/</robotNamespace>
      <robotSimType>gazebo_ros_control/DefaultRobotHWSim</robotSimType>
    </plugin>
  </gazebo>
</robot>

