<sdf version='1.7'>  
  <model name='allegro_hand_right'>
<!--*************************Experimental***************************************-->
      
<!--********************Experimental********************************************-->
      <joint name='world_to_palm_link_joint' type='fixed'>
        <pose relative_to='__model__'>0 0 0.095 0 -0 0</pose>
        <parent>world</parent>
        <child>palm_link</child>
      </joint>
      <link name='palm_link'>
        <pose relative_to='world_to_palm_link_joint'>0 0 0 0 -0 0</pose>
        <inertial>
          <pose>0.000469 0.016221 -0.04159 0 -0 0</pose>
          <mass>0.479644</mass>
          <inertia>
            <ixx>0.000656864</ixx>
            <ixy>-2.58397e-05</ixy>
            <ixz>1.7119e-05</ixz>
            <iyy>0.000842575</iyy>
            <iyz>7.35565e-06</iyz>
            <izz>0.000767792</izz>
          </inertia>
        </inertial>
        <collision name='palm_link_collision'>
          <pose>0 0.034 -0.002 3.14159 -0 0</pose>
          <geometry>
            <mesh>
              <scale>1 1 1</scale>
              <uri>model://allegro_hand_description/meshes/g_r2.stl</uri>
            </mesh>
          </geometry>
          <surface>
            <contact>
              <ode>
                <kp>1e15</kp>
                <kd>1e13</kd>
                <max_vel>0.01</max_vel>
                <min_depth>0.00</min_depth>
              </ode>
            </contact>
          </surface>
        </collision>
        <collision name='boh_bracket'>
          <pose>0 0.0341 -0.002 -4e-06 4e-06 1.57079</pose>
          <geometry>
            <mesh>
              <scale>1 1 1</scale>
              <uri>model://allegro_hand_description/meshes/part_4.dae</uri>
            </mesh>
          </geometry>
          <surface>
            <contact>
              <ode>
                <kp>1e15</kp>
                <kd>1e13</kd>
                <max_vel>0.01</max_vel>
                <min_depth>0.00</min_depth>
              </ode>
            </contact>
          </surface>
          <max_contacts>100</max_contacts>
        </collision>
<!--******************************************* -->
        <sensor name='boh' type='contact'>
          <contact>
            <collision>boh_bracket</collision>
          </contact>
        <update_rate> 5 </update_rate>
        <visualize> true </visualize>
        </sensor>    
<!--******************************************* -->
        <collision name='palm_bracket'>
          <pose>-0 0.034 -0.002 4e-06 -4e-06 1.57079</pose>
          <geometry>
            <mesh>
              <scale>1 1 1</scale>
              <uri>model://allegro_hand_description/meshes/palm_bracket.dae</uri>
            </mesh>
          </geometry>
          <surface>
            <contact>
              <ode>
                <kp>1e15</kp>
                <kd>1e13</kd>
                <max_vel>0.01</max_vel>
                <min_depth>0.00</min_depth>
              </ode>
            </contact>
          </surface>
          <max_contacts>100</max_contacts>
        </collision>
<!--******************************************* -->
        <sensor name='palm' type='contact'>
          <contact>
            <collision>palm_bracket</collision>
          </contact>
        <update_rate> 5 </update_rate>
        <visualize> true </visualize>
        </sensor>    
<!--******************************************* -->
        <visual name='palm_link_visual'>
          <pose>0 0.034 -0.002 3.14159 -0 0</pose>
          <geometry>
            <mesh>
              <scale>1 1 1</scale>
              <uri>model://allegro_hand_description/meshes/g_r2.stl</uri>
            </mesh>
          </geometry>
        </visual>
        <visual name='palm_link_fixed_joint_lump__boh_bracket_visual_1'>
          <pose>0 0.0341 -0.002 -4e-06 4e-06 1.57079</pose>
          <geometry>
            <mesh>
              <scale>1 1 1</scale>
              <uri>model://allegro_hand_description/meshes/part_4.dae</uri>
            </mesh>
          </geometry>
        </visual>
        <visual name='palm_link_fixed_joint_lump__palm_bracket_visual_2'>
          <pose>-0 0.034 -0.002 4e-06 -4e-06 1.57079</pose>
          <geometry>
            <mesh>
              <scale>1 1 1</scale>
              <uri>model://allegro_hand_description/meshes/palm_bracket.dae</uri>
            </mesh>
          </geometry>
        </visual>
        <self_collide>true</self_collide>
      </link>
      <joint name='joint_0_0' type='revolute'>
        <pose relative_to='palm_link'>-0.043538 0.034 -0.005539 -0.087267 -0 1.5708</pose>
        <parent>palm_link</parent>
        <child>link_0</child>
        <axis>
          <xyz>0 0 1</xyz>
          <limit>
            <lower>-1.57</lower>
            <upper>1.57</upper>
            <effort>15</effort>
            <velocity>20</velocity>
          </limit>
          <dynamics>
            <friction>0.5</friction>
            <damping>0</damping>
          </dynamics>
        </axis>
        <physics>
          <implicit_spring_damper> true </implicit_spring_damper>
        </physics> 
      </joint>
      <link name='link_0'>
        <pose relative_to='joint_0_0'>0 0 0 0 -0 0</pose>
        <inertial>
          <pose>-0.000413 0.000666 0.009606 0 -0 0</pose>
          <mass>0.0136672</mass>
          <inertia>
            <ixx>2.13441e-06</ixx>
            <ixy>5.86704e-10</ixy>
            <ixz>-7.9563e-08</ixz>
            <iyy>1.24411e-06</iyy>
            <iyz>-6.13056e-08</iyz>
            <izz>1.671e-06</izz>
          </inertia>
        </inertial>
        <collision name='link_0_collision'>
          <pose>0 0 -0.0152 1.5708 0 -0</pose>
          <geometry>
            <mesh>
              <scale>1 1 1</scale>
              <uri>model://allegro_hand_description/meshes/extended_finger_base.stl</uri>
            </mesh>
          </geometry>
          <surface>
            <contact>
              <ode>
                <kp>1e15</kp>
                <kd>1e13</kd>
                <max_vel>0.01</max_vel>
                <min_depth>0.00</min_depth>
              </ode>
            </contact>
          </surface>
        </collision>
        <visual name='link_0_visual'>
          <pose>0 0 -0.0152 1.5708 0 -0</pose>
          <geometry>
            <mesh>
              <scale>1 1 1</scale>
              <uri>model://allegro_hand_description/meshes/extended_finger_base.stl</uri>
            </mesh>
          </geometry>
        </visual>
        <self_collide>true</self_collide>
      </link>
      <joint name='joint_1_0' type='revolute'>
        <pose relative_to='link_0'>0 -0.0119 0.02545 1.57079 -1.57079 3.14159</pose>
        <parent>link_0</parent>
        <child>link_1</child>
        <axis>
          <xyz>0 0 1</xyz>
          <limit>
            <lower>0</lower>
            <upper>1.57</upper>
            <effort>15</effort>
            <velocity>20</velocity>
          </limit>
          <dynamics>
            <friction>0.5</friction>
            <damping>0</damping>
          </dynamics>
        </axis>
        <physics>
          <implicit_spring_damper> true </implicit_spring_damper>
        </physics> 
      </joint>
      <link name='link_1'>
        <pose relative_to='joint_1_0'>0 0 0 0 -0 0</pose>
        <inertial>
          <pose>0.027033 -0.000224 0.012145 0 -0 0</pose>
          <mass>0.0541465</mass>
          <inertia>
            <ixx>7.67977e-06</ixx>
            <ixy>-6.1897e-08</ixy>
            <ixz>-1.40235e-08</ixz>
            <iyy>2.3921e-05</iyy>
            <iyz>-1.11576e-07</iyz>
            <izz>2.31978e-05</izz>
          </inertia>
        </inertial>
        <collision name='link_1_collision'>
          <pose>-0.018269 0 -0.031781 0 1.48353 -3.14159</pose>
          <geometry>
            <mesh>
              <scale>1 1 1</scale>
              <uri>model://allegro_hand_description/meshes/p2_r6.stl</uri>
            </mesh>
          </geometry>
          <surface>
            <contact>
              <ode>
                <kp>1e15</kp>
                <kd>1e13</kd>
                <max_vel>0.01</max_vel>
                <min_depth>0.00</min_depth>
              </ode>
            </contact>
          </surface>
        </collision>
        <collision name='link_1_fixed_joint_lump__ipb_bracket_collision_1'>
          <pose>-0 0 0.0113 5e-06 0 0</pose>
          <geometry>
            <mesh>
              <scale>1 1 1</scale>
              <uri>model://allegro_hand_description/meshes/proximal_back.stl</uri>
            </mesh>
          </geometry>
          <surface>
            <contact>
              <ode>
                <kp>1e15</kp>
                <kd>1e13</kd>
                <max_vel>0.01</max_vel>
                <min_depth>0.00</min_depth>
              </ode>
            </contact>
          </surface>
          <max_contacts>100</max_contacts>
        </collision>
        <collision name='ipf_bracket'>
          <pose>0 0 0.0123 -0 0 -0</pose>
          <geometry>
            <mesh>
              <scale>1 1 1</scale>
              <uri>model://allegro_hand_description/meshes/proximal_front.dae</uri>
            </mesh>
          </geometry>
          <surface>
            <contact>
              <ode>
                <kp>1e15</kp>
                <kd>1e13</kd>
                <max_vel>0.01</max_vel>
                <min_depth>0.00</min_depth>
              </ode>
            </contact>
          </surface>
          <max_contacts>100</max_contacts>
        </collision>
<!--******************************************* -->
        <sensor name='ipf' type='contact'>
          <contact>
            <collision>ipf_bracket</collision>
          </contact>
        <update_rate> 5 </update_rate>
        <visualize> true </visualize>
        </sensor>    
<!--******************************************* -->        
        <visual name='link_1_visual'>
          <pose>-0.018269 0 -0.031781 0 1.48353 -3.14159</pose>
          <geometry>
            <mesh>
              <scale>1 1 1</scale>
              <uri>model://allegro_hand_description/meshes/p2_r6.stl</uri>
            </mesh>
          </geometry>
        </visual>
        <visual name='link_1_fixed_joint_lump__ipb_bracket_visual_1'>
          <pose>-0 0 0.0113 5e-06 0 0</pose>
          <geometry>
            <mesh>
              <scale>1 1 1</scale>
              <uri>model://allegro_hand_description/meshes/proximal_back.stl</uri>
            </mesh>
          </geometry>
        </visual>
        <visual name='link_1_fixed_joint_lump__ipf_bracket_visual_2'>
          <pose>0 0 0.0123 -0 0 -0</pose>
          <geometry>
            <mesh>
              <scale>1 1 1</scale>
              <uri>model://allegro_hand_description/meshes/proximal_front.dae</uri>
            </mesh>
          </geometry>
        </visual>
        <self_collide>true</self_collide>
      </link>
      <joint name='joint_2_0' type='revolute'>
        <pose relative_to='link_1'>0.054 -0 0 0 -0 -3.14159</pose>
        <parent>link_1</parent>
        <child>link_2</child>
        <axis>
          <xyz>0 0 1</xyz>
          <limit>
            <lower>0</lower>
            <upper>1.57</upper>
            <effort>15</effort>
            <velocity>20</velocity>
          </limit>
          <dynamics>
            <friction>0.5</friction>
            <damping>0</damping>
          </dynamics>
        </axis>
        <physics>
          <implicit_spring_damper> true </implicit_spring_damper>
        </physics> 
      </joint>
      <link name='link_2'>
        <pose relative_to='joint_2_0'>0 0 0 0 -0 0</pose>
        <inertial>
          <pose>-0.028719 0.000277 0.012147 0 -0 0</pose>
          <mass>0.0418474</mass>
          <inertia>
            <ixx>6.393e-06</ixx>
            <ixy>7.11754e-08</ixy>
            <ixz>6.49003e-07</ixz>
            <iyy>1.25642e-05</iyy>
            <iyz>5.72797e-08</iyz>
            <izz>1.08408e-05</izz>
          </inertia>
        </inertial>
        <collision name='link_2_collision'>
          <pose>0.072269 -0 -0.031781 -0 1.48353 0</pose>
          <geometry>
            <mesh>
              <scale>1 1 1</scale>
              <uri>model://allegro_hand_description/meshes/extended_fingertop.stl</uri>
            </mesh>
          </geometry>
          <surface>
            <contact>
              <ode>
                <kp>1e15</kp>
                <kd>1e13</kd>
                <max_vel>0.01</max_vel>
                <min_depth>0.00</min_depth>
              </ode>
            </contact>
          </surface>
        </collision>
        <collision name='link_2_fixed_joint_lump__imb_bracket_collision_1'>
          <pose>0.054 -0 0.0119 5e-06 -0 3.14159</pose>
          <geometry>
            <mesh>
              <scale>1 1 1</scale>
              <uri>model://allegro_hand_description/meshes/medial_back.stl</uri>
            </mesh>
          </geometry>
          <surface>
            <contact>
              <ode>
                <kp>1e15</kp>
                <kd>1e13</kd>
                <max_vel>0.01</max_vel>
                <min_depth>0.00</min_depth>
              </ode>
            </contact>
          </surface>
          <max_contacts>100</max_contacts>
        </collision>
        <collision name='imf_bracket'>
          <pose>0.054 0 0.0119 0 0 -3.14159</pose>
          <geometry>
            <mesh>
              <scale>1 1 1</scale>
              <uri>model://allegro_hand_description/meshes/medial_front.dae</uri>
            </mesh>
          </geometry>
          <surface>
            <contact>
              <ode>
                <kp>1e15</kp>
                <kd>1e13</kd>
                <max_vel>0.01</max_vel>
                <min_depth>0.00</min_depth>
              </ode>
            </contact>
          </surface>
          <max_contacts>100</max_contacts>
        </collision>
<!--******************************************* -->
        <sensor name='imf' type='contact'>
          <contact>
            <collision>imf_bracket</collision>
          </contact>
        <update_rate> 5 </update_rate>
        <visualize> true </visualize>
        </sensor>    
<!--******************************************* -->
        <visual name='link_2_visual'>
          <pose>0.072269 -0 -0.031781 -0 1.48353 0</pose>
          <geometry>
            <mesh>
              <scale>1 1 1</scale>
              <uri>model://allegro_hand_description/meshes/extended_fingertop.stl</uri>
            </mesh>
          </geometry>
        </visual>
        <visual name='link_2_fixed_joint_lump__imb_bracket_visual_1'>
          <pose>0.054 -0 0.0119 5e-06 -0 3.14159</pose>
          <geometry>
            <mesh>
              <scale>1 1 1</scale>
              <uri>model://allegro_hand_description/meshes/medial_back.stl</uri>
            </mesh>
          </geometry>
        </visual>
        <visual name='link_2_fixed_joint_lump__imf_bracket_visual_2'>
          <pose>0.054 0 0.0119 0 0 -3.14159</pose>
          <geometry>
            <mesh>
              <scale>1 1 1</scale>
              <uri>model://allegro_hand_description/meshes/medial_front.dae</uri>
            </mesh>
          </geometry>
        </visual>
        <self_collide>true</self_collide>
      </link>
      <joint name='joint_3_0' type='revolute'>
        <pose relative_to='link_2'>-0.04615 0 0.0001 0 -0 -0</pose>
        <parent>link_2</parent>
        <child>link_3</child>
        <axis>
          <xyz>0 0 1</xyz>
          <limit>
            <lower>0</lower>
            <upper>1.57</upper>
            <effort>15</effort>
            <velocity>20</velocity>
          </limit>
          <dynamics>
            <friction>0.5</friction>
            <damping>0</damping>
          </dynamics>
        </axis>
        <physics>
          <implicit_spring_damper> true </implicit_spring_damper>
        </physics> 
      </joint>
      <link name='link_3'>
        <pose relative_to='joint_3_0'>0 0 0 0 -0 0</pose>
        <inertial>
          <pose>-0.023107 0.002061 0.012032 0 -0 0</pose>
          <mass>0.0243483</mass>
          <inertia>
            <ixx>4.44879e-06</ixx>
            <ixy>6.72221e-07</ixy>
            <ixz>-6.6688e-08</ixz>
            <iyy>9.62734e-06</iyy>
            <iyz>5.15377e-09</iyz>
            <izz>7.46611e-06</izz>
          </inertia>
        </inertial>
        <collision name='link_3_collision'>
          <pose>0.1253 -0 0.0118 -3.14159 -0 -1.5708</pose>
          <geometry>
            <mesh>
              <scale>1 1 1</scale>
              <uri>model://allegro_hand_description/meshes/p4_r.stl</uri>
            </mesh>
          </geometry>
          <surface>
            <contact>
              <ode>
                <kp>1e15</kp>
                <kd>1e13</kd>
                <max_vel>0.01</max_vel>
                <min_depth>0.00</min_depth>
              </ode>
            </contact>
          </surface>
        </collision>
        <collision name='ift_bracket'>
          <pose>0.1004 0 0.0119 5e-06 -0 -3.14159</pose>
          <geometry>
            <mesh>
              <scale>1 1 1</scale>
              <uri>model://allegro_hand_description/meshes/distal_pcbbase.stl</uri>
            </mesh>
          </geometry>
          <surface>
            <contact>
              <ode>
                <kp>1e15</kp>
                <kd>1e13</kd>
                <max_vel>0.01</max_vel>
                <min_depth>0.00</min_depth>
              </ode>
            </contact>
          </surface>
          <max_contacts>100</max_contacts>
        </collision>
<!--******************************************* -->
        <sensor name='ift' type='contact'>
          <contact>
            <collision>ift_bracket</collision>
          </contact>
        <update_rate> 5 </update_rate>
        <visualize> true </visualize>
        </sensor>    
<!--******************************************* -->
        <visual name='link_3_visual'>
          <pose>0.1253 -0 0.0118 -3.14159 -0 -1.5708</pose>
          <geometry>
            <mesh>
              <scale>1 1 1</scale>
              <uri>model://allegro_hand_description/meshes/p4_r.stl</uri>
            </mesh>
          </geometry>
        </visual>
        <visual name='link_3_fixed_joint_lump__ift_bracket_visual_1'>
          <pose>0.1004 0 0.0119 5e-06 -0 -3.14159</pose>
          <geometry>
            <mesh>
              <scale>1 1 1</scale>
              <uri>model://allegro_hand_description/meshes/distal_pcbbase.stl</uri>
            </mesh>
          </geometry>
        </visual>
        <self_collide>true</self_collide>
      </link>
      <joint name='joint_12_0' type='revolute'>
        <pose relative_to='palm_link'>-0.016121 0.0158 -0.084852 -3.14159 -0.087267 0</pose>
        <parent>palm_link</parent>
        <child>link_12</child>
        <axis>
          <xyz>0 0 1</xyz>
          <limit>
            <lower>0</lower>
            <upper>1.57</upper>
            <effort>15</effort>
            <velocity>20</velocity>
          </limit>
          <dynamics>
            <friction>0.5</friction>
            <damping>0</damping>
          </dynamics>
        </axis>
        <physics>
          <implicit_spring_damper> true </implicit_spring_damper>
        </physics> 
      </joint>
      <link name='link_12'>
        <pose relative_to='joint_12_0'>0 0 0 0 -0 0</pose>
        <inertial>
          <pose>-0.015116 -0.009058 -0.01923 0 -0 0</pose>
          <mass>0.0660275</mass>
          <inertia>
            <ixx>1.44344e-05</ixx>
            <ixy>1.24597e-06</ixy>
            <ixz>3.47822e-08</ixz>
            <iyy>1.76386e-05</iyy>
            <iyz>6.49531e-07</iyz>
            <izz>1.41981e-05</izz>
          </inertia>
        </inertial>
        <collision name='link_12_collision'>
          <pose>0.023281 -0.0182 -0.080831 -0 -0.087267 -0</pose>
          <geometry>
            <mesh>
              <scale>1 1 1</scale>
              <uri>model://allegro_hand_description/meshes/f1_r.stl</uri>
            </mesh>
          </geometry>
          <surface>
            <contact>
              <ode>
                <kp>1e15</kp>
                <kd>1e13</kd>
                <max_vel>0.01</max_vel>
                <min_depth>0.00</min_depth>
              </ode>
            </contact>
          </surface>
        </collision>
        <visual name='link_12_visual'>
          <pose>0.023281 -0.0182 -0.080831 -0 -0.087267 -0</pose>
          <geometry>
            <mesh>
              <scale>1 1 1</scale>
              <uri>model://allegro_hand_description/meshes/f1_r.stl</uri>
            </mesh>
          </geometry>
        </visual>
        <self_collide>true</self_collide>
      </link>
      <joint name='joint_13_0' type='revolute'>
        <pose relative_to='link_12'>-0.0375 -0.005 -0.0092 -1.5708 -0 1.5708</pose>
        <parent>link_12</parent>
        <child>link_13</child>
        <axis>
          <xyz>0 0 1</xyz>
          <limit>
            <lower>0</lower>
            <upper>2</upper>
            <effort>15</effort>
            <velocity>20</velocity>
          </limit>
          <dynamics>
            <friction>0.5</friction>
            <damping>0</damping>
          </dynamics>
        </axis>
        <physics>
          <implicit_spring_damper> true </implicit_spring_damper>
        </physics> 
      </joint>
      <link name='link_13'>
        <pose relative_to='joint_13_0'>0 0 0 0 -0 0</pose>
        <inertial>
          <pose>-0.000666 -0.000413 0.009606 0 -0 0</pose>
          <mass>0.0136672</mass>
          <inertia>
            <ixx>1.671e-06</ixx>
            <ixy>6.13056e-08</ixy>
            <ixz>7.9563e-08</ixz>
            <iyy>1.24411e-06</iyy>
            <iyz>5.86704e-10</iyz>
            <izz>2.13441e-06</izz>
          </inertia>
        </inertial>
        <collision name='link_13_collision'>
          <pose>-0 0 -0.0152 1.5708 -0 1.5708</pose>
          <geometry>
            <mesh>
              <scale>1 1 1</scale>
              <uri>model://allegro_hand_description/meshes/extended_finger_base.stl</uri>
            </mesh>
          </geometry>
          <surface>
            <contact>
              <ode>
                <kp>1e15</kp>
                <kd>1e13</kd>
                <max_vel>0.01</max_vel>
                <min_depth>0.00</min_depth>
              </ode>
            </contact>
          </surface>
        </collision>
        <visual name='link_13_visual'>
          <pose>-0 0 -0.0152 1.5708 -0 1.5708</pose>
          <geometry>
            <mesh>
              <scale>1 1 1</scale>
              <uri>model://allegro_hand_description/meshes/extended_finger_base.stl</uri>
            </mesh>
          </geometry>
        </visual>
        <self_collide>true</self_collide>
      </link>
      <joint name='joint_14_0' type='revolute'>
        <pose relative_to='link_13'>0.0119 0 0.02545 3e-06 1.57079 3.14159</pose>
        <parent>link_13</parent>
        <child>link_14</child>
        <axis>
          <xyz>0 0 1</xyz>
          <limit>
            <lower>0</lower>
            <upper>1.57</upper>
            <effort>15</effort>
            <velocity>20</velocity>
          </limit>
          <dynamics>
            <friction>0.5</friction>
            <damping>0</damping>
          </dynamics>
        </axis>
        <physics>
          <implicit_spring_damper> true </implicit_spring_damper>
        </physics> 
      </joint>
      <link name='link_14'>
        <pose relative_to='joint_14_0'>0 0 0 0 -0 0</pose>
        <inertial>
          <pose>-0.01745 0.000631 0.01221 0 -0 0</pose>
          <mass>0.0395591</mass>
          <inertia>
            <ixx>5.84307e-06</ixx>
            <ixy>-7.72369e-07</ixy>
            <ixz>4.78465e-07</ixz>
            <iyy>1.16403e-05</iyy>
            <iyz>-5.21989e-07</iyz>
            <izz>1.05218e-05</izz>
          </inertia>
        </inertial>
        <collision name='link_14_collision'>
          <pose>0.078781 -0.071631 0.0251 -1.5708 -0 0.087267</pose>
          <geometry>
            <mesh>
              <scale>1 1 1</scale>
              <uri>model://allegro_hand_description/meshes/f3_r.stl</uri>
            </mesh>
          </geometry>
          <surface>
            <contact>
              <ode>
                <kp>1e15</kp>
                <kd>1e13</kd>
                <max_vel>0.01</max_vel>
                <min_depth>0.00</min_depth>
              </ode>
            </contact>
          </surface>
        </collision>
        <collision name='link_14_fixed_joint_lump__tmb_bracket_collision_1'>
          <pose>0.008 -0 0.0118 1.5708 0 -1.5708</pose>
          <geometry>
            <mesh>
              <scale>1 1 1</scale>
              <uri>model://allegro_hand_description/meshes/thumb_medial_back_bracket.stl</uri>
            </mesh>
          </geometry>
          <surface>
            <contact>
              <ode>
                <kp>1e15</kp>
                <kd>1e13</kd>
                <max_vel>0.01</max_vel>
                <min_depth>0.00</min_depth>
              </ode>
            </contact>
          </surface>
          <max_contacts>100</max_contacts>
        </collision>
        <collision name='link_14_fixed_joint_lump__tmf_bracket_collision_2'>
          <pose>0.008 -0 0.0118 1.57079 0 -1.5708</pose>
          <geometry>
            <mesh>
              <scale>1 1 1</scale>
              <uri>model://allegro_hand_description/meshes/thumb_medial_front_bracket.stl</uri>
            </mesh>
          </geometry>
          <surface>
            <contact>
              <ode>
                <kp>1e15</kp>
                <kd>1e13</kd>
                <max_vel>0.01</max_vel>
                <min_depth>0.00</min_depth>
              </ode>
            </contact>
          </surface>
          <max_contacts>100</max_contacts>
        </collision>
        <visual name='link_14_visual'>
          <pose>0.078781 -0.071631 0.0251 -1.5708 -0 0.087267</pose>
          <geometry>
            <mesh>
              <scale>1 1 1</scale>
              <uri>model://allegro_hand_description/meshes/f3_r.stl</uri>
            </mesh>
          </geometry>
        </visual>
        <visual name='link_14_fixed_joint_lump__tmb_bracket_visual_1'>
          <pose>0.008 -0 0.0118 1.5708 0 -1.5708</pose>
          <geometry>
            <mesh>
              <scale>1 1 1</scale>
              <uri>model://allegro_hand_description/meshes/thumb_medial_back_bracket.stl</uri>
            </mesh>
          </geometry>
        </visual>
        <visual name='link_14_fixed_joint_lump__tmf_bracket_visual_2'>
          <pose>0.008 -0 0.0118 1.57079 0 -1.5708</pose>
          <geometry>
            <mesh>
              <scale>1 1 1</scale>
              <uri>model://allegro_hand_description/meshes/thumb_medial_front_bracket.stl</uri>
            </mesh>
          </geometry>
        </visual>
        <self_collide>true</self_collide>
      </link>
      <joint name='joint_15_0' type='revolute'>
        <pose relative_to='link_14'>-0.0514 -0 -0.0001 0 0 0</pose>
        <parent>link_14</parent>
        <child>link_15</child>
        <axis>
          <xyz>0 0 1</xyz>
          <limit>
            <lower>0</lower>
            <upper>1.57</upper>
            <effort>15</effort>
            <velocity>20</velocity>
          </limit>
          <dynamics>
            <friction>0.5</friction>
            <damping>0</damping>
          </dynamics>
        </axis>
        <physics>
          <implicit_spring_damper> true </implicit_spring_damper>
        </physics> 
      </joint>
      <link name='link_15'>
        <pose relative_to='joint_15_0'>0 0 0 0 -0 0</pose>
        <inertial>
          <pose>-0.024808 0.000899 0.012061 0 -0 0</pose>
          <mass>0.0482047</mass>
          <inertia>
            <ixx>6.2624e-06</ixx>
            <ixy>1.00066e-06</ixy>
            <ixz>2.54307e-07</ixz>
            <iyy>2.26851e-05</iyy>
            <iyz>6.89474e-08</iyz>
            <izz>2.03663e-05</izz>
          </inertia>
        </inertial>
        <collision name='link_15_collision'>
          <pose>0.13018 -0.071631 0.0252 -1.5708 -0 0.087267</pose>
          <geometry>
            <mesh>
              <scale>1 1 1</scale>
              <uri>model://allegro_hand_description/meshes/f4_r.stl</uri>
            </mesh>
          </geometry>
          <surface>
            <contact>
              <ode>
                <kp>1e15</kp>
                <kd>1e13</kd>
                <max_vel>0.01</max_vel>
                <min_depth>0.00</min_depth>
              </ode>
            </contact>
          </surface>
        </collision>
        <collision name='tft_bracket'>
          <pose>0.0848 -0.0003 0.0118 -0 0 -3.14159</pose>
          <geometry>
            <mesh>
              <scale>1 1 1</scale>
              <uri>model://allegro_hand_description/meshes/distal_pcbbase.stl</uri>
            </mesh>
          </geometry>
          <surface>
            <contact>
              <ode>
                <kp>1e15</kp>
                <kd>1e13</kd>
                <max_vel>0.01</max_vel>
                <min_depth>0.00</min_depth>
              </ode>
            </contact>
          </surface>
          <max_contacts>100</max_contacts>
        </collision>
<!--******************************************* -->
        <sensor name='tft' type='contact'>
          <contact>
            <collision>tft_bracket</collision>
          </contact>
        <update_rate> 5 </update_rate>
        <visualize> true </visualize>
        </sensor>    
<!--******************************************* -->
        <visual name='link_15_visual'>
          <pose>0.13018 -0.071631 0.0252 -1.5708 -0 0.087267</pose>
          <geometry>
            <mesh>
              <scale>1 1 1</scale>
              <uri>model://allegro_hand_description/meshes/f4_r.stl</uri>
            </mesh>
          </geometry>
        </visual>
        <visual name='link_15_fixed_joint_lump__tft_bracket_visual_1'>
          <pose>0.0848 -0.0003 0.0118 -0 0 -3.14159</pose>
          <geometry>
            <mesh>
              <scale>1 1 1</scale>
              <uri>model://allegro_hand_description/meshes/distal_pcbbase.stl</uri>
            </mesh>
          </geometry>
        </visual>
        <self_collide>true</self_collide>
      </link>
      <joint name='joint_4_0' type='revolute'>
        <pose relative_to='palm_link'>-0 0.034 -0.0033 0 -0 1.5708</pose>
        <parent>palm_link</parent>
        <child>link_4</child>
        <axis>
          <xyz>0 0 1</xyz>
          <limit>
            <lower>-1.57</lower>
            <upper>1.57</upper>
            <effort>15</effort>
            <velocity>20</velocity>
          </limit>
          <dynamics>
            <friction>0.5</friction>
            <damping>0</damping>
          </dynamics>
        </axis>
        <physics>
          <implicit_spring_damper> true </implicit_spring_damper>
        </physics> 
      </joint>
      <link name='link_4'>
        <pose relative_to='joint_4_0'>0 0 0 0 -0 0</pose>
        <inertial>
          <pose>-0.000413 0.000666 0.009606 0 -0 0</pose>
          <mass>0.0136672</mass>
          <inertia>
            <ixx>2.13441e-06</ixx>
            <ixy>5.86704e-10</ixy>
            <ixz>-7.9563e-08</ixz>
            <iyy>1.24411e-06</iyy>
            <iyz>-6.13056e-08</iyz>
            <izz>1.671e-06</izz>
          </inertia>
        </inertial>
        <collision name='link_4_collision'>
          <pose>0 -0 -0.0152 1.5708 -0 0</pose>
          <geometry>
            <mesh>
              <scale>1 1 1</scale>
              <uri>model://allegro_hand_description/meshes/extended_finger_base.stl</uri>
            </mesh>
          </geometry>
          <surface>
            <contact>
              <ode>
                <kp>1e15</kp>
                <kd>1e13</kd>
                <max_vel>0.01</max_vel>
                <min_depth>0.00</min_depth>
              </ode>
            </contact>
          </surface>
        </collision>
        <visual name='link_4_visual'>
          <pose>0 -0 -0.0152 1.5708 -0 0</pose>
          <geometry>
            <mesh>
              <scale>1 1 1</scale>
              <uri>model://allegro_hand_description/meshes/extended_finger_base.stl</uri>
            </mesh>
          </geometry>
        </visual>
        <self_collide>true</self_collide>
      </link>
      <joint name='joint_5_0' type='revolute'>
        <pose relative_to='link_4'>0 -0.0119 0.02545 1.57079 1.57079 -3.14159</pose>
        <parent>link_4</parent>
        <child>link_5</child>
        <axis>
          <xyz>0 0 1</xyz>
          <limit>
            <lower>0</lower>
            <upper>1.57</upper>
            <effort>15</effort>
            <velocity>20</velocity>
          </limit>
          <dynamics>
            <friction>0.5</friction>
            <damping>0</damping>
          </dynamics>
        </axis>
        <physics>
          <implicit_spring_damper> true </implicit_spring_damper>
        </physics> 
      </joint>
      <link name='link_5'>
        <pose relative_to='joint_5_0'>0 0 0 0 -0 0</pose>
        <inertial>
          <pose>-0.027033 0.000224 0.012145 0 -0 0</pose>
          <mass>0.0541465</mass>
          <inertia>
            <ixx>8.12772e-06</ixx>
            <ixy>-2.30048e-08</ixy>
            <ixz>2.5544e-06</ixz>
            <iyy>2.3921e-05</iyy>
            <iyz>1.40092e-07</iyz>
            <izz>2.275e-05</izz>
          </inertia>
        </inertial>
        <collision name='link_5_collision'>
          <pose>0.018269 0 -0.031781 -0 1.48353 0</pose>
          <geometry>
            <mesh>
              <scale>1 1 1</scale>
              <uri>model://allegro_hand_description/meshes/p2_r6.stl</uri>
            </mesh>
          </geometry>
          <surface>
            <contact>
              <ode>
                <kp>1e15</kp>
                <kd>1e13</kd>
                <max_vel>0.01</max_vel>
                <min_depth>0.00</min_depth>
              </ode>
            </contact>
          </surface>
        </collision>
        <collision name='link_5_fixed_joint_lump__mpb_bracket_collision_1'>
          <pose>0 0 0.0113 -5e-06 -0 -3.14159</pose>
          <geometry>
            <mesh>
              <scale>1 1 1</scale>
              <uri>model://allegro_hand_description/meshes/proximal_back.stl</uri>
            </mesh>
          </geometry>
          <surface>
            <contact>
              <ode>
                <kp>1e15</kp>
                <kd>1e13</kd>
                <max_vel>0.01</max_vel>
                <min_depth>0.00</min_depth>
              </ode>
            </contact>
          </surface>
          <max_contacts>100</max_contacts>
        </collision>
        <collision name='mpf_bracket'>
          <pose>0 -0 0.0123 -0 -0 3.14159</pose>
          <geometry>
            <mesh>
              <scale>1 1 1</scale>
              <uri>model://allegro_hand_description/meshes/proximal_front.dae</uri>
            </mesh>
          </geometry>
          <surface>
            <contact>
              <ode>
                <kp>1e15</kp>
                <kd>1e13</kd>
                <max_vel>0.01</max_vel>
                <min_depth>0.00</min_depth>
              </ode>
            </contact>
          </surface>
          <max_contacts>100</max_contacts>
        </collision>
<!--******************************************* -->
        <sensor name='mpf' type='contact'>
          <contact>
            <collision>mpf_bracket</collision>
          </contact>
        <update_rate> 5 </update_rate>
        <visualize> true </visualize>
        </sensor>    
<!--******************************************* -->  
        <visual name='link_5_visual'>
          <pose>0.018269 0 -0.031781 -0 1.48353 0</pose>
          <geometry>
            <mesh>
              <scale>1 1 1</scale>
              <uri>model://allegro_hand_description/meshes/p2_r6.stl</uri>
            </mesh>
          </geometry>
        </visual>
        <visual name='link_5_fixed_joint_lump__mpb_bracket_visual_1'>
          <pose>0 0 0.0113 -5e-06 -0 -3.14159</pose>
          <geometry>
            <mesh>
              <scale>1 1 1</scale>
              <uri>model://allegro_hand_description/meshes/proximal_back.stl</uri>
            </mesh>
          </geometry>
        </visual>
        <visual name='link_5_fixed_joint_lump__mpf_bracket_visual_2'>
          <pose>0 -0 0.0123 -0 -0 3.14159</pose>
          <geometry>
            <mesh>
              <scale>1 1 1</scale>
              <uri>model://allegro_hand_description/meshes/proximal_front.dae</uri>
            </mesh>
          </geometry>
        </visual>
        <self_collide>true</self_collide>
      </link>
      <joint name='joint_6_0' type='revolute'>
        <pose relative_to='link_5'>-0.054 0 -0 0 -0 -0</pose>
        <parent>link_5</parent>
        <child>link_6</child>
        <axis>
          <xyz>0 0 1</xyz>
          <limit>
            <lower>0</lower>
            <upper>1.57</upper>
            <effort>15</effort>
            <velocity>20</velocity>
          </limit>
          <dynamics>
            <friction>0.5</friction>
            <damping>0</damping>
          </dynamics>
        </axis>
        <physics>
          <implicit_spring_damper> true </implicit_spring_damper>
        </physics> 
      </joint>
      <link name='link_6'>
        <pose relative_to='joint_6_0'>0 0 0 0 -0 0</pose>
        <inertial>
          <pose>-0.028719 0.000277 0.012147 0 -0 0</pose>
          <mass>0.0418474</mass>
          <inertia>
            <ixx>6.39299e-06</ixx>
            <ixy>7.11783e-08</ixy>
            <ixz>6.49002e-07</ixz>
            <iyy>1.25642e-05</iyy>
            <iyz>5.72804e-08</iyz>
            <izz>1.08408e-05</izz>
          </inertia>
        </inertial>
        <collision name='link_6_collision'>
          <pose>0.072269 -0 -0.031781 0 1.48353 -0</pose>
          <geometry>
            <mesh>
              <scale>1 1 1</scale>
              <uri>model://allegro_hand_description/meshes/extended_fingertop.stl</uri>
            </mesh>
          </geometry>
          <surface>
            <contact>
              <ode>
                <kp>1e15</kp>
                <kd>1e13</kd>
                <max_vel>0.01</max_vel>
                <min_depth>0.00</min_depth>
              </ode>
            </contact>
          </surface>
        </collision>
        <collision name='link_6_fixed_joint_lump__mmb_bracket_collision_1'>
          <pose>0.054 -0 0.0119 5e-06 -0 3.14159</pose>
          <geometry>
            <mesh>
              <scale>1 1 1</scale>
              <uri>model://allegro_hand_description/meshes/medial_back.stl</uri>
            </mesh>
          </geometry>
          <surface>
            <contact>
              <ode>
                <kp>1e15</kp>
                <kd>1e13</kd>
                <max_vel>0.01</max_vel>
                <min_depth>0.00</min_depth>
              </ode>
            </contact>
          </surface>
          <max_contacts>100</max_contacts>
        </collision>
        <collision name='mmf_bracket'>
          <pose>0.054 -0 0.0119 -0 0 3.14159</pose>
          <geometry>
            <mesh>
              <scale>1 1 1</scale>
              <uri>model://allegro_hand_description/meshes/medial_front.dae</uri>
            </mesh>
          </geometry>
          <surface>
            <contact>
              <ode>
                <kp>1e15</kp>
                <kd>1e13</kd>
                <max_vel>0.01</max_vel>
                <min_depth>0.00</min_depth>
              </ode>
            </contact>
          </surface>
          <max_contacts>100</max_contacts>
        </collision>
<!--******************************************* -->
        <sensor name='mmf' type='contact'>
          <contact>
            <collision>mmf_bracket</collision>
          </contact>
        <update_rate> 5 </update_rate>
        <visualize> true </visualize>
        </sensor>    
<!--******************************************* -->
        <visual name='link_6_visual'>
          <pose>0.072269 -0 -0.031781 0 1.48353 -0</pose>
          <geometry>
            <mesh>
              <scale>1 1 1</scale>
              <uri>model://allegro_hand_description/meshes/extended_fingertop.stl</uri>
            </mesh>
          </geometry>
        </visual>
        <visual name='link_6_fixed_joint_lump__mmb_bracket_visual_1'>
          <pose>0.054 -0 0.0119 5e-06 -0 3.14159</pose>
          <geometry>
            <mesh>
              <scale>1 1 1</scale>
              <uri>model://allegro_hand_description/meshes/medial_back.stl</uri>
            </mesh>
          </geometry>
        </visual>
        <visual name='link_6_fixed_joint_lump__mmf_bracket_visual_2'>
          <pose>0.054 -0 0.0119 -0 0 3.14159</pose>
          <geometry>
            <mesh>
              <scale>1 1 1</scale>
              <uri>model://allegro_hand_description/meshes/medial_front.dae</uri>
            </mesh>
          </geometry>
        </visual>
        <self_collide>true</self_collide>
      </link>
      <joint name='joint_7_0' type='revolute'>
        <pose relative_to='link_6'>-0.04615 0 0.0001 0 0 -0</pose>
        <parent>link_6</parent>
        <child>link_7</child>
        <axis>
          <xyz>0 0 1</xyz>
          <limit>
            <lower>0</lower>
            <upper>1.57</upper>
            <effort>15</effort>
            <velocity>20</velocity>
          </limit>
          <dynamics>
            <friction>0.5</friction>
            <damping>0</damping>
          </dynamics>
        </axis>
        <physics>
          <implicit_spring_damper> true </implicit_spring_damper>
        </physics> 
      </joint>
      <link name='link_7'>
        <pose relative_to='joint_7_0'>0 0 0 0 -0 0</pose>
        <inertial>
          <pose>-0.023107 0.002061 0.012032 0 -0 0</pose>
          <mass>0.0243483</mass>
          <inertia>
            <ixx>4.44879e-06</ixx>
            <ixy>6.72221e-07</ixy>
            <ixz>-6.6688e-08</ixz>
            <iyy>9.62734e-06</iyy>
            <iyz>5.15377e-09</iyz>
            <izz>7.46611e-06</izz>
          </inertia>
        </inertial>
        <collision name='link_7_collision'>
          <pose>0.1253 -0 0.0118 3.14159 -0 -1.5708</pose>
          <geometry>
            <mesh>
              <scale>1 1 1</scale>
              <uri>model://allegro_hand_description/meshes/p4_r.stl</uri>
            </mesh>
          </geometry>
          <surface>
            <contact>
              <ode>
                <kp>1e15</kp>
                <kd>1e13</kd>
                <max_vel>0.01</max_vel>
                <min_depth>0.00</min_depth>
              </ode>
            </contact>
          </surface>
        </collision>
        <collision name='mft_bracket'>
          <pose>0.1004 0 0.0119 5e-06 -0 -3.14159</pose>
          <geometry>
            <mesh>
              <scale>1 1 1</scale>
              <uri>model://allegro_hand_description/meshes/distal_pcbbase.stl</uri>
            </mesh>
          </geometry>
          <surface>
            <contact>
              <ode>
                <kp>1e15</kp>
                <kd>1e13</kd>
                <max_vel>0.01</max_vel>
                <min_depth>0.00</min_depth>
              </ode>
            </contact>
          </surface>
          <max_contacts>100</max_contacts>
        </collision>
<!--******************************************* -->
        <sensor name='mft' type='contact'>
          <contact>
            <collision>mft_bracket</collision>
          </contact>
        <update_rate> 5 </update_rate>
        <visualize> true </visualize>
        </sensor>    
<!--******************************************* -->
        <visual name='link_7_visual'>
          <pose>0.1253 -0 0.0118 3.14159 -0 -1.5708</pose>
          <geometry>
            <mesh>
              <scale>1 1 1</scale>
              <uri>model://allegro_hand_description/meshes/p4_r.stl</uri>
            </mesh>
          </geometry>
        </visual>
        <visual name='link_7_fixed_joint_lump__mft_bracket_visual_1'>
          <pose>0.1004 0 0.0119 5e-06 -0 -3.14159</pose>
          <geometry>
            <mesh>
              <scale>1 1 1</scale>
              <uri>model://allegro_hand_description/meshes/distal_pcbbase.stl</uri>
            </mesh>
          </geometry>
        </visual>
        <self_collide>true</self_collide>
      </link>
      <joint name='joint_8_0' type='revolute'>
        <pose relative_to='palm_link'>0.043538 0.034 -0.005539 0.087266 0 1.5708</pose>
        <parent>palm_link</parent>
        <child>link_8</child>
        <axis>
          <xyz>0 0 1</xyz>
          <limit>
            <lower>-1.57</lower>
            <upper>1.57</upper>
            <effort>15</effort>
            <velocity>20</velocity>
          </limit>
          <dynamics>
            <damping>0</damping>
            <friction>0.5</friction>
          </dynamics>
        </axis>
        <physics>
          <implicit_spring_damper> true </implicit_spring_damper>
        </physics>  
      </joint>
      <link name='link_8'>
        <pose relative_to='joint_8_0'>0 0 0 0 -0 0</pose>
        <inertial>
          <pose>-0.000413 0.000666 0.009606 0 -0 0</pose>
          <mass>0.0136672</mass>
          <inertia>
            <ixx>2.13441e-06</ixx>
            <ixy>5.86704e-10</ixy>
            <ixz>-7.9563e-08</ixz>
            <iyy>1.24411e-06</iyy>
            <iyz>-6.13056e-08</iyz>
            <izz>1.671e-06</izz>
          </inertia>
        </inertial>
        <collision name='link_8_collision'>
          <pose>0 -0 -0.0152 1.5708 -0 0</pose>
          <geometry>
            <mesh>
              <scale>1 1 1</scale>
              <uri>model://allegro_hand_description/meshes/extended_finger_base.stl</uri>
            </mesh>
          </geometry>
          <surface>
            <contact>
              <ode>
                <kp>1e15</kp>
                <kd>1e13</kd>
                <max_vel>0.01</max_vel>
                <min_depth>0.00</min_depth>
              </ode>
            </contact>
          </surface>
        </collision>
        <visual name='link_8_visual'>
          <pose>0 -0 -0.0152 1.5708 -0 0</pose>
          <geometry>
            <mesh>
              <scale>1 1 1</scale>
              <uri>model://allegro_hand_description/meshes/extended_finger_base.stl</uri>
            </mesh>
          </geometry>
        </visual>
        <self_collide>true</self_collide>
      </link>
      <joint name='joint_9_0' type='revolute'>
        <pose relative_to='link_8'>-0 -0.0119 0.02545 1.57079 1.57079 -3.14159</pose>
        <parent>link_8</parent>
        <child>link_9</child>
        <axis>
          <xyz>0 0 1</xyz>
          <limit>
            <lower>0</lower>
            <upper>1.57</upper>
            <effort>15</effort>
            <velocity>20</velocity>
          </limit>
          <dynamics>
            <friction>0.5</friction>
            <damping>0</damping>
          </dynamics>
        </axis>
        <physics>
          <ode>
            <implicit_spring_damper> true </implicit_spring_damper>
          </ode>
        </physics>
      </joint>
      <link name='link_9'>
        <pose relative_to='joint_9_0'>0 0 0 0 -0 0</pose>
        <inertial>
          <pose>-0.027033 0.000224 0.012145 0 -0 0</pose>
          <mass>0.0541465</mass>
          <inertia>
            <ixx>8.12772e-06</ixx>
            <ixy>-2.30028e-08</ixy>
            <ixz>2.5544e-06</ixz>
            <iyy>2.3921e-05</iyy>
            <iyz>1.40093e-07</iyz>
            <izz>2.275e-05</izz>
          </inertia>
        </inertial>
        <collision name='link_9_collision'>
          <pose>0.018269 -0 -0.031781 -0 1.48353 0</pose>
          <geometry>
            <mesh>
              <scale>1 1 1</scale>
              <uri>model://allegro_hand_description/meshes/p2_r6.stl</uri>
            </mesh>
          </geometry>
          <surface>
            <contact>
              <ode>
                <kp>1e15</kp>
                <kd>1e13</kd>
                <max_vel>0.01</max_vel>
                <min_depth>0.00</min_depth>
              </ode>
            </contact>
          </surface>
        </collision>
        <collision name='link_9_fixed_joint_lump__ppb_bracket_collision_1'>
          <pose>-0 -0 0.0113 0 0 3.14159</pose>
          <geometry>
            <mesh>
              <scale>1 1 1</scale>
              <uri>model://allegro_hand_description/meshes/proximal_back.stl</uri>
            </mesh>
          </geometry>
          <surface>
            <contact>
              <ode>
                <kp>1e15</kp>
                <kd>1e13</kd>
                <max_vel>0.01</max_vel>
                <min_depth>0.00</min_depth>
              </ode>
            </contact>
          </surface>
          <max_contacts>100</max_contacts>
        </collision>
        <collision name='ppf_bracket'>
          <pose>0 -0 0.0123 -0 0 3.14159</pose>
          <geometry>
            <mesh>
              <scale>1 1 1</scale>
              <uri>model://allegro_hand_description/meshes/proximal_front.dae</uri>
            </mesh>
          </geometry>
          <surface>
            <contact>
              <ode>
                <kp>1e15</kp>
                <kd>1e13</kd>
                <max_vel>0.01</max_vel>
                <min_depth>0.00</min_depth>
              </ode>
            </contact>
          </surface>
          <max_contacts>100</max_contacts>
        </collision>
<!--******************************************* -->
        <sensor name='ppf' type='contact'>
          <contact>
            <collision>ppf_bracket</collision>
          </contact>
        <update_rate> 5 </update_rate>
        <visualize> true </visualize>
        </sensor>    
<!--******************************************* -->
        <visual name='link_9_visual'>
          <pose>0.018269 -0 -0.031781 -0 1.48353 0</pose>
          <geometry>
            <mesh>
              <scale>1 1 1</scale>
              <uri>model://allegro_hand_description/meshes/p2_r6.stl</uri>
            </mesh>
          </geometry>
        </visual>
        <visual name='link_9_fixed_joint_lump__ppb_bracket_visual_1'>
          <pose>-0 -0 0.0113 0 0 3.14159</pose>
          <geometry>
            <mesh>
              <scale>1 1 1</scale>
              <uri>model://allegro_hand_description/meshes/proximal_back.stl</uri>
            </mesh>
          </geometry>
        </visual>
        <visual name='link_9_fixed_joint_lump__ppf_bracket_visual_2'>
          <pose>0 -0 0.0123 -0 0 3.14159</pose>
          <geometry>
            <mesh>
              <scale>1 1 1</scale>
              <uri>model://allegro_hand_description/meshes/proximal_front.dae</uri>
            </mesh>
          </geometry>
        </visual>
        <self_collide>true</self_collide>
      </link>
      <joint name='joint_10_0' type='revolute'>
        <pose relative_to='link_9'>-0.054 0 0 0 -0 -0</pose>
        <parent>link_9</parent>
        <child>link_10</child>
        <axis>
          <xyz>0 0 1</xyz>
          <limit>
            <lower>0</lower>
            <upper>1.57</upper>
            <effort>15</effort>
            <velocity>20</velocity>
          </limit>
          <dynamics>
            <friction>0.5</friction>
            <damping>0</damping>
          </dynamics>
        </axis>
        <physics>
          <implicit_spring_damper> true </implicit_spring_damper>
        </physics> 
      </joint>
      <link name='link_10'>
        <pose relative_to='joint_10_0'>0 0 0 0 -0 0</pose>
        <inertial>
          <pose>-0.028719 0.000277 0.012147 0 -0 0</pose>
          <mass>0.0418474</mass>
          <inertia>
            <ixx>6.393e-06</ixx>
            <ixy>7.11757e-08</ixy>
            <ixz>6.49003e-07</ixz>
            <iyy>1.25642e-05</iyy>
            <iyz>5.72843e-08</iyz>
            <izz>1.08408e-05</izz>
          </inertia>
        </inertial>
        <collision name='link_10_collision'>
          <pose>0.072269 -0 -0.031781 0 1.48353 -0</pose>
          <geometry>
            <mesh>
              <scale>1 1 1</scale>
              <uri>model://allegro_hand_description/meshes/extended_fingertop.stl</uri>
            </mesh>
          </geometry>
          <surface>
            <contact>
              <ode>
                <kp>1e15</kp>
                <kd>1e13</kd>
                <max_vel>0.01</max_vel>
                <min_depth>0.00</min_depth>
              </ode>
            </contact>
          </surface>
        </collision>
        <collision name='link_10_fixed_joint_lump__pmb_bracket_collision_1'>
          <pose>0.054 -0 0.0119 0 -0 3.14159</pose>
          <geometry>
            <mesh>
              <scale>1 1 1</scale>
              <uri>model://allegro_hand_description/meshes/medial_back.stl</uri>
            </mesh>
          </geometry>
          <surface>
            <contact>
              <ode>
                <kp>1e15</kp>
                <kd>1e13</kd>
                <max_vel>0.01</max_vel>
                <min_depth>0.00</min_depth>
              </ode>
            </contact>
          </surface>
          <max_contacts>100</max_contacts>
        </collision>
        <collision name='pmf_bracket'>
          <pose>0.054 -0 0.0119 -0 0 3.14159</pose>
          <geometry>
            <mesh>
              <scale>1 1 1</scale>
              <uri>model://allegro_hand_description/meshes/medial_front.dae</uri>
            </mesh>
          </geometry>
          <surface>
            <contact>
              <ode>
                <kp>1e15</kp>
                <kd>1e13</kd>
                <max_vel>0.01</max_vel>
                <min_depth>0.00</min_depth>
              </ode>
            </contact>
          </surface>
          <max_contacts>100</max_contacts>
        </collision>
<!--******************************************* -->
        <sensor name='pmf' type='contact'>
          <contact>
            <collision>pmf_bracket</collision>
          </contact>
        <update_rate> 5 </update_rate>
        <visualize> true </visualize>
        </sensor>    
<!--******************************************* -->
        <visual name='link_10_visual'>
          <pose>0.072269 -0 -0.031781 0 1.48353 -0</pose>
          <geometry>
            <mesh>
              <scale>1 1 1</scale>
              <uri>model://allegro_hand_description/meshes/extended_fingertop.stl</uri>
            </mesh>
          </geometry>
        </visual>
        <visual name='link_10_fixed_joint_lump__pmb_bracket_visual_1'>
          <pose>0.054 -0 0.0119 0 -0 3.14159</pose>
          <geometry>
            <mesh>
              <scale>1 1 1</scale>
              <uri>model://allegro_hand_description/meshes/medial_back.stl</uri>
            </mesh>
          </geometry>
        </visual>
        <visual name='link_10_fixed_joint_lump__pmf_bracket_visual_2'>
          <pose>0.054 -0 0.0119 -0 0 3.14159</pose>
          <geometry>
            <mesh>
              <scale>1 1 1</scale>
              <uri>model://allegro_hand_description/meshes/medial_front.dae</uri>
            </mesh>
          </geometry>
        </visual>
        <self_collide>true</self_collide>
      </link>
      <joint name='joint_11_0' type='revolute'>
        <pose relative_to='link_10'>-0.04615 0 0.0001 0 0 -0</pose>
        <parent>link_10</parent>
        <child>link_11</child>
        <axis>
          <xyz>0 0 1</xyz>
          <limit>
            <lower>0</lower>
            <upper>1.57</upper>
            <effort>15</effort>
            <velocity>20</velocity>
          </limit>
          <dynamics>
            <friction>0.5</friction>
            <damping>0</damping>
          </dynamics>
        </axis>
        <physics>
          <implicit_spring_damper> true </implicit_spring_damper>
        </physics> 
      </joint>
      <link name='link_11'>
        <pose relative_to='joint_11_0'>0 0 0 0 -0 0</pose>
        <inertial>
          <pose>-0.023107 0.002061 0.012032 0 -0 0</pose>
          <mass>0.0243483</mass>
          <inertia>
            <ixx>4.44879e-06</ixx>
            <ixy>6.72221e-07</ixy>
            <ixz>-6.6688e-08</ixz>
            <iyy>9.62734e-06</iyy>
            <iyz>5.15377e-09</iyz>
            <izz>7.46611e-06</izz>
          </inertia>
        </inertial>
        <collision name='link_11_collision'>
          <pose>0.1253 -0 0.0118 3.14159 -0 -1.5708</pose>
          <geometry>
            <mesh>
              <scale>1 1 1</scale>
              <uri>model://allegro_hand_description/meshes/p4_r.stl</uri>
            </mesh>
          </geometry>
          <surface>
            <contact>
              <ode>
                <kp>1e15</kp>
                <kd>1e13</kd>
                <max_vel>0.01</max_vel>
                <min_depth>0.00</min_depth>
              </ode>
            </contact>
          </surface>
        </collision>
        <collision name='pft_bracket'>
          <pose>0.1004 0 0.0119 0 -0 -3.14159</pose>
          <geometry>
            <mesh>
              <scale>1 1 1</scale>
              <uri>model://allegro_hand_description/meshes/distal_pcbbase.stl</uri>
            </mesh>
          </geometry>
          <surface>
            <contact>
              <ode>
                <kp>1e15</kp>
                <kd>1e13</kd>
                <max_vel>0.01</max_vel>
                <min_depth>0.00</min_depth>
              </ode>
            </contact>
          </surface>
          <max_contacts>100</max_contacts>
        </collision>
<!--******************************************* -->
        <sensor name='pft' type='contact'>
          <contact>
            <collision>pft_bracket</collision>
          </contact>
        <update_rate> 5 </update_rate>
        <visualize> true </visualize>
        </sensor>    
<!--******************************************* -->
        <visual name='link_11_visual'>
          <pose>0.1253 -0 0.0118 3.14159 -0 -1.5708</pose>
          <geometry>
            <mesh>
              <scale>1 1 1</scale>
              <uri>model://allegro_hand_description/meshes/p4_r.stl</uri>
            </mesh>
          </geometry>
        </visual>
        <visual name='link_11_fixed_joint_lump__pft_bracket_visual_1'>
          <pose>0.1004 0 0.0119 0 -0 -3.14159</pose>
          <geometry>
            <mesh>
              <scale>1 1 1</scale>
              <uri>model://allegro_hand_description/meshes/distal_pcbbase.stl</uri>
            </mesh>
          </geometry>
        </visual>
        <self_collide>true</self_collide>
      </link>

      <plugin name="contact_coordinates_plugin" filename="/home/abed/Documents/BICI_Project/BICI_SENSORS_ROS/Gazebo_Simulation/Contact_Sensor/build/libcoordinates.so"/>
      <plugin name="gazebo_ros_control" filename="/opt/ros/noetic/lib/libgazebo_ros_control.so">
        <robotNamespace>/allegro_hand_right</robotNamespace>
        <robotSimType>gazebo_ros_control/DefaultRobotHWSim</robotSimType> 
        <legacyModeNS>true</legacyModeNS> 
      </plugin>
      
  </model>
</sdf>