<?xml version="1.0" ?>
<robot name="allegro_hand_right">

    <link name="world"/>
    <link name="palm_link">
    <visual>
    <origin xyz="0 0.034 -0.002" rpy="3.14159 -0 0" />
    <geometry>
    <mesh filename="package://allegro_hand_description/meshes/g_r2.stl"/>
    </geometry>
    <material name="g_r2_material">
    <color rgba="0.2 0.2 0.2 1.0"/>
    </material>
    </visual>
    <collision>
    <origin xyz="0 0.034 -0.002" rpy="3.14159 -0 0" />
    <geometry>
    <mesh filename="package://allegro_hand_description/meshes/g_r2.stl"/>
    </geometry>
    <material name="g_r2_material">
    <color rgba="0.2 0.2 0.2 1.0"/>
    </material>
    </collision>
    <inertial>
    <origin xyz="-0.00043535 0.0160404 -0.0404815" rpy="0 0 0"/>
    <mass value="0.404445" />
    <inertia ixx="0.000491371" ixy="-9.01723e-06"  ixz="1.17974e-05" iyy="0.000773265" iyz="-5.50867e-06" izz="0.000547843" />
    </inertial>
    </link>

    <joint name="world_to_palm_link_joint" type="fixed">
        <origin xyz="0 0 0.095" rpy="0 0 0"/>
        <parent link="world"/>
        <child link="palm_link"/>
    </joint>
    
    <link name="link_0">
    <visual>
    <origin xyz="0 6.93889e-18 -0.0152" rpy="1.5708 6.16298e-33 -5.3926e-33" />
    <geometry>
    <mesh filename="package://allegro_hand_description/meshes/extended_finger_base.stl"/>
    </geometry>
    <material name="extended_finger_base_material">
    <color rgba="0.647059 0.647059 0.647059 1.0"/>
    </material>
    </visual>
    <collision>
    <origin xyz="0 6.93889e-18 -0.0152" rpy="1.5708 6.16298e-33 -5.3926e-33" />
    <geometry>
    <mesh filename="package://allegro_hand_description/meshes/extended_finger_base.stl"/>
    </geometry>
    <material name="extended_finger_base_material">
    <color rgba="0.647059 0.647059 0.647059 1.0"/>
    </material>
    </collision>
    <inertial>
    <origin xyz="-0.00041342 0.000666149 0.00960564" rpy="0 0 0"/>
    <mass value="0.0136672" />
    <inertia ixx="2.13441e-06" ixy="5.86704e-10"  ixz="-7.9563e-08" iyy="1.24411e-06" iyz="-6.13056e-08" izz="1.671e-06" />
    </inertial>
    </link>

    <link name="link_1">
    <visual>
    <origin xyz="-0.0182688 6.93889e-18 -0.0317805" rpy="-9.26798e-31 1.48353 -3.14159" />
    <geometry>
    <mesh filename="package://allegro_hand_description/meshes/p2_r6.stl"/>
    </geometry>
    <material name="p2_r6_material">
    <color rgba="0.129412 0.129412 0.129412 1.0"/>
    </material>
    </visual>
    <collision>
    <origin xyz="-0.0182688 6.93889e-18 -0.0317805" rpy="-9.26798e-31 1.48353 -3.14159" />
    <geometry>
    <mesh filename="package://allegro_hand_description/meshes/p2_r6.stl"/>
    </geometry>
    <material name="p2_r6_material">
    <color rgba="0.129412 0.129412 0.129412 1.0"/>
    </material>
    </collision>
    <inertial>
    <origin xyz="0.027 9.54536e-05 0.0124409" rpy="0 0 0"/>
    <mass value="0.0418346" />
    <inertia ixx="4.00114e-06" ixy="-1.81985e-08"  ixz="-4.42841e-15" iyy="1.97927e-05" iyz="1.59578e-08" izz="1.88563e-05" />
    </inertial>
    </link>

    <link name="link_2">
    <visual>
    <origin xyz="0.0722688 -4.16334e-17 -0.0317805" rpy="-7.19385e-31 1.48353 1.67955e-30" />
    <geometry>
    <mesh filename="package://allegro_hand_description/meshes/extended_fingertop.stl"/>
    </geometry>
    <material name="extended_fingertop_material">
    <color rgba="0.647059 0.647059 0.647059 1.0"/>
    </material>
    </visual>
    <collision>
    <origin xyz="0.0722688 -4.16334e-17 -0.0317805" rpy="-7.19385e-31 1.48353 1.67955e-30" />
    <geometry>
    <mesh filename="package://allegro_hand_description/meshes/extended_fingertop.stl"/>
    </geometry>
    <material name="extended_fingertop_material">
    <color rgba="0.647059 0.647059 0.647059 1.0"/>
    </material>
    </collision>
    <inertial>
    <origin xyz="-0.0294592 -0.000104104 0.0123435" rpy="0 0 0"/>
    <mass value="0.0318021" />
    <inertia ixx="3.48619e-06" ixy="1.20808e-07"  ixz="6.2918e-07" iyy="8.82437e-06" iyz="5.78644e-09" izz="7.34771e-06" />
    </inertial>
    </link>

    <link name="link_3">
    <visual>
    <origin xyz="0.1253 -5.55112e-17 0.0118" rpy="-3.14159 8.09265e-31 -1.5708" />
    <geometry>
    <mesh filename="package://allegro_hand_description/meshes/p4_r.stl"/>
    </geometry>
    <material name="p4_r_material">
    <color rgba="0.129412 0.129412 0.129412 1.0"/>
    </material>
    </visual>
    <collision>
    <origin xyz="0.1253 -5.55112e-17 0.0118" rpy="-3.14159 8.09265e-31 -1.5708" />
    <geometry>
    <mesh filename="package://allegro_hand_description/meshes/p4_r.stl"/>
    </geometry>
    <material name="p4_r_material">
    <color rgba="0.129412 0.129412 0.129412 1.0"/>
    </material>
    </collision>
    <inertial>
    <origin xyz="-0.0100051 0.000639363 0.0123057" rpy="0 0 0"/>
    <mass value="0.0088374" />
    <inertia ixx="1.08072e-06" ixy="-4.65695e-08"  ixz="-3.42321e-08" iyy="1.11236e-06" iyz="-8.85024e-10" izz="5.61586e-07" />
    </inertial>
    </link>

    <link name="ift_bracket">
    <visual>
    <origin xyz="-0.1139 -0.004 0.0135" rpy="-3.14159 -1.1025e-17 2.98637e-30" />
    <geometry>
    <mesh filename="package://allegro_hand_description/meshes/distal_pcbbase.stl"/>
    </geometry>
    <material name="distal_pcbbase_material">
    <color rgba="1 0.756863 0.054902 1.0"/>
    </material>
    </visual>
    <collision>
    <origin xyz="-0.1139 -0.004 0.0135" rpy="-3.14159 -1.1025e-17 2.98637e-30" />
    <geometry>
    <mesh filename="package://allegro_hand_description/meshes/distal_pcbbase.stl"/>
    </geometry>
    <material name="distal_pcbbase_material">
    <color rgba="1 0.756863 0.054902 1.0"/>
    </material>
    </collision>
    <inertial>
    <origin xyz="0.0170719 -0.00112911 0.0135244" rpy="0 0 0"/>
    <mass value="0.0155109" />
    <inertia ixx="3.339e-06" ixy="-4.60426e-07"  ixz="1.73449e-08" iyy="6.13257e-06" iyz="-6.39964e-10" izz="4.49513e-06" />
    </inertial>
    </link>

    <joint name="joint_index_fingertip_bracket" type="fixed">
    <origin xyz="-0.0135 0.004 0.0254" rpy="-3.14159 -1.01255e-15 -3.14159" />
    <parent link="link_3" />
    <child link="ift_bracket" />
    <axis xyz="0 0 1"/>
    <limit effort="1" velocity="20" />
    <joint_properties friction="0.0"/>
    </joint>

    <joint name="joint_3_0" type="revolute">
    <origin xyz="-0.04615 1.38778e-17 0.0001" rpy="2.47521e-16 -2.87243e-16 -9.91762e-14" />
    <parent link="link_2" />
    <child link="link_3" />
    <axis xyz="0 0 1"/>
    <limit effort="1" velocity="20" />
    <joint_properties friction="0.0"/>
    </joint>

    <link name="imf_bracket">
    <visual>
    <origin xyz="-0.0755 -0.004 0.014" rpy="3.70821e-32 2.66331e-18 9.59804e-32" />
    <geometry>
    <mesh filename="package://allegro_hand_description/meshes/medial_front.stl"/>
    </geometry>
    <material name="medial_front_material">
    <color rgba="1 0.756863 0.054902 1.0"/>
    </material>
    </visual>
    <collision>
    <origin xyz="-0.0755 -0.004 0.014" rpy="3.70821e-32 2.66331e-18 9.59804e-32" />
    <geometry>
    <mesh filename="package://allegro_hand_description/meshes/medial_front.stl"/>
    </geometry>
    <material name="medial_front_material">
    <color rgba="1 0.756863 0.054902 1.0"/>
    </material>
    </collision>
    <inertial>
    <origin xyz="0.00469281 0.00336791 0.0198072" rpy="0 0 0"/>
    <mass value="0.00473232" />
    <inertia ixx="8.28869e-07" ixy="-2.96994e-07"  ixz="2.53991e-07" iyy="1.55762e-06" iyz="2.23567e-07" izz="1.28629e-06" />
    </inertial>
    </link>

    <joint name="joint_index_medial_front_bracket" type="fixed">
    <origin xyz="-0.0215 -0.004 -0.0021" rpy="1.55523e-28 1.64355e-17 -3.14159" />
    <parent link="link_2" />
    <child link="imf_bracket" />
    <axis xyz="0 0 1"/>
    <limit effort="1" velocity="20" />
    <joint_properties friction="0.0"/>
    </joint>

    <link name="imb_bracket">
    <visual>
    <origin xyz="-0.0755 -0.004 0.014" rpy="-3.14159 9.1762e-18 2.03448e-31" />
    <geometry>
    <mesh filename="package://allegro_hand_description/meshes/medial_back.stl"/>
    </geometry>
    <material name="medial_back_material">
    <color rgba="1 0.756863 0.054902 1.0"/>
    </material>
    </visual>
    <collision>
    <origin xyz="-0.0755 -0.004 0.014" rpy="-3.14159 9.1762e-18 2.03448e-31" />
    <geometry>
    <mesh filename="package://allegro_hand_description/meshes/medial_back.stl"/>
    </geometry>
    <material name="medial_back_material">
    <color rgba="1 0.756863 0.054902 1.0"/>
    </material>
    </collision>
    <inertial>
    <origin xyz="0.0050369 0.00536951 0.0198823" rpy="0 0 0"/>
    <mass value="0.00531302" />
    <inertia ixx="1.01036e-06" ixy="-2.70353e-07"  ixz="2.64599e-07" iyy="1.7622e-06" iyz="2.24575e-07" izz="1.4134e-06" />
    </inertial>
    </link>

    <joint name="joint_index_medial_back_bracket" type="fixed">
    <origin xyz="-0.0215 0.004 0.0259" rpy="-3.14159 -1.66749e-15 3.14159" />
    <parent link="link_2" />
    <child link="imb_bracket" />
    <axis xyz="0 0 1"/>
    <limit effort="1" velocity="20" />
    <joint_properties friction="0.0"/>
    </joint>

    <joint name="joint_2_0" type="revolute">
    <origin xyz="0.054 -2.08167e-17 0" rpy="3.51153e-16 -1.76861e-16 -3.14159" />
    <parent link="link_1" />
    <child link="link_2" />
    <axis xyz="0 0 1"/>
    <limit effort="1" velocity="20" />
    <joint_properties friction="0.0"/>
    </joint>

    <link name="ipb_bracket">
    <visual>
    <origin xyz="-0.0249 -0.0037 0.014" rpy="-3.14159 -9.52926e-18 1.00291e-30" />
    <geometry>
    <mesh filename="package://allegro_hand_description/meshes/proximal_back.stl"/>
    </geometry>
    <material name="proximal_back_material">
    <color rgba="1 0.756863 0.054902 1.0"/>
    </material>
    </visual>
    <collision>
    <origin xyz="-0.0249 -0.0037 0.014" rpy="-3.14159 -9.52926e-18 1.00291e-30" />
    <geometry>
    <mesh filename="package://allegro_hand_description/meshes/proximal_back.stl"/>
    </geometry>
    <material name="proximal_back_material">
    <color rgba="1 0.756863 0.054902 1.0"/>
    </material>
    </collision>
    <inertial>
    <origin xyz="0.00190421 0.00603324 0.0192417" rpy="0 0 0"/>
    <mass value="0.00681742" />
    <inertia ixx="1.33469e-06" ixy="-1.25087e-08"  ixz="-1.65721e-09" iyy="2.12223e-06" iyz="3.02232e-07" izz="1.86525e-06" />
    </inertial>
    </link>

    <joint name="joint_index_proximal_back_bracket" type="fixed">
    <origin xyz="0.0249 -0.0037 0.0253" rpy="-3.14159 1.75587e-16 3.12083e-29" />
    <parent link="link_1" />
    <child link="ipb_bracket" />
    <axis xyz="0 0 1"/>
    <limit effort="1" velocity="20" />
    <joint_properties friction="0.0"/>
    </joint>

    <link name="ipf_bracket">
    <visual>
    <origin xyz="-0.0249 -0.0077 0.014" rpy="8.39712e-30 1.01964e-17 -7.67956e-32" />
    <geometry>
    <mesh filename="package://allegro_hand_description/meshes/proximal_front.stl"/>
    </geometry>
    <material name="proximal_front_material">
    <color rgba="1 0.756863 0.054902 1.0"/>
    </material>
    </visual>
    <collision>
    <origin xyz="-0.0249 -0.0077 0.014" rpy="8.39712e-30 1.01964e-17 -7.67956e-32" />
    <geometry>
    <mesh filename="package://allegro_hand_description/meshes/proximal_front.stl"/>
    </geometry>
    <material name="proximal_front_material">
    <color rgba="1 0.756863 0.054902 1.0"/>
    </material>
    </collision>
    <inertial>
    <origin xyz="0.00266438 0.00143857 0.0191449" rpy="0 0 0"/>
    <mass value="0.00549452" />
    <inertia ixx="8.30997e-07" ixy="-1.44805e-08"  ixz="8.87855e-09" iyy="1.59352e-06" iyz="2.4142e-07" izz="1.37197e-06" />
    </inertial>
    </link>

    <joint name="joint_index_proximal_front_bracket" type="fixed">
    <origin xyz="0.0249 0.0077 -0.0017" rpy="-5.29761e-14 6.49973e-18 -2.65051e-30" />
    <parent link="link_1" />
    <child link="ipf_bracket" />
    <axis xyz="0 0 1"/>
    <limit effort="1" velocity="20" />
    <joint_properties friction="0.0"/>
    </joint>

    <joint name="joint_1_0" type="revolute">
    <origin xyz="0 -0.0119 0.02545" rpy="-1.5708 -1.5708 0" />
    <parent link="link_0" />
    <child link="link_1" />
    <axis xyz="0 0 1"/>
    <limit effort="1" velocity="20" />
    <joint_properties friction="0.0"/>
    </joint>

    <joint name="joint_0_0" type="revolute">
    <origin xyz="-0.0435377 0.034 -0.00553922" rpy="-0.0872665 -1.66533e-16 1.5708" />
    <parent link="palm_link" />
    <child link="link_0" />
    <axis xyz="0 0 1"/>
    <limit effort="1" velocity="20" />
    <joint_properties friction="0.0"/>
    </joint>

    <link name="link_4">
    <visual>
    <origin xyz="0 -2.52778e-34 -0.0152" rpy="1.5708 -0 1.53951e-48" />
    <geometry>
    <mesh filename="package://allegro_hand_description/meshes/extended_finger_base.stl"/>
    </geometry>
    <material name="extended_finger_base_material">
    <color rgba="0.647059 0.647059 0.647059 1.0"/>
    </material>
    </visual>
    <collision>
    <origin xyz="0 -2.52778e-34 -0.0152" rpy="1.5708 -0 1.53951e-48" />
    <geometry>
    <mesh filename="package://allegro_hand_description/meshes/extended_finger_base.stl"/>
    </geometry>
    <material name="extended_finger_base_material">
    <color rgba="0.647059 0.647059 0.647059 1.0"/>
    </material>
    </collision>
    <inertial>
    <origin xyz="-0.00041342 0.000666149 0.00960564" rpy="0 0 0"/>
    <mass value="0.0136672" />
    <inertia ixx="2.13441e-06" ixy="5.86704e-10"  ixz="-7.9563e-08" iyy="1.24411e-06" iyz="-6.13056e-08" izz="1.671e-06" />
    </inertial>
    </link>

    <link name="link_5">
    <visual>
    <origin xyz="0.0182688 6.93889e-18 -0.0317805" rpy="-4.20659e-34 1.48353 4.31224e-31" />
    <geometry>
    <mesh filename="package://allegro_hand_description/meshes/p2_r6.stl"/>
    </geometry>
    <material name="p2_r6_material">
    <color rgba="0.129412 0.129412 0.129412 1.0"/>
    </material>
    </visual>
    <collision>
    <origin xyz="0.0182688 6.93889e-18 -0.0317805" rpy="-4.20659e-34 1.48353 4.31224e-31" />
    <geometry>
    <mesh filename="package://allegro_hand_description/meshes/p2_r6.stl"/>
    </geometry>
    <material name="p2_r6_material">
    <color rgba="0.129412 0.129412 0.129412 1.0"/>
    </material>
    </collision>
    <inertial>
    <origin xyz="-0.027 -9.54536e-05 0.0124409" rpy="0 0 0"/>
    <mass value="0.0418346" />
    <inertia ixx="4.44908e-06" ixy="2.0693e-08"  ixz="2.54038e-06" iyy="1.97927e-05" iyz="1.25552e-08" izz="1.84084e-05" />
    </inertial>
    </link>

    <link name="link_6">
    <visual>
    <origin xyz="0.0722688 -4.16334e-17 -0.0317805" rpy="9.86282e-31 1.48353 -7.49973e-31" />
    <geometry>
    <mesh filename="package://allegro_hand_description/meshes/extended_fingertop.stl"/>
    </geometry>
    <material name="extended_fingertop_material">
    <color rgba="0.647059 0.647059 0.647059 1.0"/>
    </material>
    </visual>
    <collision>
    <origin xyz="0.0722688 -4.16334e-17 -0.0317805" rpy="9.86282e-31 1.48353 -7.49973e-31" />
    <geometry>
    <mesh filename="package://allegro_hand_description/meshes/extended_fingertop.stl"/>
    </geometry>
    <material name="extended_fingertop_material">
    <color rgba="0.647059 0.647059 0.647059 1.0"/>
    </material>
    </collision>
    <inertial>
    <origin xyz="-0.0294592 -0.000104104 0.0123435" rpy="0 0 0"/>
    <mass value="0.0318021" />
    <inertia ixx="3.48619e-06" ixy="1.20808e-07"  ixz="6.2918e-07" iyy="8.82437e-06" iyz="5.78644e-09" izz="7.34771e-06" />
    </inertial>
    </link>

    <link name="link_7">
    <visual>
    <origin xyz="0.1253 -6.245e-17 0.0118" rpy="3.14159 1.191e-31 -1.5708" />
    <geometry>
    <mesh filename="package://allegro_hand_description/meshes/p4_r.stl"/>
    </geometry>
    <material name="p4_r_material">
    <color rgba="0.129412 0.129412 0.129412 1.0"/>
    </material>
    </visual>
    <collision>
    <origin xyz="0.1253 -6.245e-17 0.0118" rpy="3.14159 1.191e-31 -1.5708" />
    <geometry>
    <mesh filename="package://allegro_hand_description/meshes/p4_r.stl"/>
    </geometry>
    <material name="p4_r_material">
    <color rgba="0.129412 0.129412 0.129412 1.0"/>
    </material>
    </collision>
    <inertial>
    <origin xyz="-0.0100051 0.000639363 0.0123057" rpy="0 0 0"/>
    <mass value="0.0088374" />
    <inertia ixx="1.08072e-06" ixy="-4.65695e-08"  ixz="-3.42321e-08" iyy="1.11236e-06" iyz="-8.85024e-10" izz="5.61586e-07" />
    </inertial>
    </link>

    <link name="mft_bracket">
    <visual>
    <origin xyz="-0.1139 -0.004 0.0135" rpy="-3.14159 -2.86226e-33 8.46292e-32" />
    <geometry>
    <mesh filename="package://allegro_hand_description/meshes/distal_pcbbase.stl"/>
    </geometry>
    <material name="distal_pcbbase_material">
    <color rgba="1 0.756863 0.054902 1.0"/>
    </material>
    </visual>
    <collision>
    <origin xyz="-0.1139 -0.004 0.0135" rpy="-3.14159 -2.86226e-33 8.46292e-32" />
    <geometry>
    <mesh filename="package://allegro_hand_description/meshes/distal_pcbbase.stl"/>
    </geometry>
    <material name="distal_pcbbase_material">
    <color rgba="1 0.756863 0.054902 1.0"/>
    </material>
    </collision>
    <inertial>
    <origin xyz="0.0170719 -0.00112911 0.0135244" rpy="0 0 0"/>
    <mass value="0.0155109" />
    <inertia ixx="3.339e-06" ixy="-4.60426e-07"  ixz="1.73449e-08" iyy="6.13257e-06" iyz="-6.39964e-10" izz="4.49513e-06" />
    </inertial>
    </link>

    <joint name="joint_middle_fingertip_bracket" type="fixed">
    <origin xyz="-0.0135 0.004 0.0254" rpy="-3.14159 -5.9952e-15 -3.14159" />
    <parent link="link_7" />
    <child link="mft_bracket" />
    <axis xyz="0 0 1"/>
    <limit effort="1" velocity="20" />
    <joint_properties friction="0.0"/>
    </joint>

    <joint name="joint_7_0" type="revolute">
    <origin xyz="-0.04615 2.08167e-17 0.0001" rpy="7.63278e-16 5.80199e-16 -9.4334e-27" />
    <parent link="link_6" />
    <child link="link_7" />
    <axis xyz="0 0 1"/>
    <limit effort="1" velocity="20" />
    <joint_properties friction="0.0"/>
    </joint>

    <link name="mmf_bracket">
    <visual>
    <origin xyz="-0.0755 -0.004 0.014" rpy="1.16303e-31 -0 0" />
    <geometry>
    <mesh filename="package://allegro_hand_description/meshes/medial_front.stl"/>
    </geometry>
    <material name="medial_front_material">
    <color rgba="1 0.756863 0.054902 1.0"/>
    </material>
    </visual>
    <collision>
    <origin xyz="-0.0755 -0.004 0.014" rpy="1.16303e-31 -0 0" />
    <geometry>
    <mesh filename="package://allegro_hand_description/meshes/medial_front.stl"/>
    </geometry>
    <material name="medial_front_material">
    <color rgba="1 0.756863 0.054902 1.0"/>
    </material>
    </collision>
    <inertial>
    <origin xyz="0.00469281 0.00336791 0.0198072" rpy="0 0 0"/>
    <mass value="0.00473232" />
    <inertia ixx="8.28869e-07" ixy="-2.96994e-07"  ixz="2.53991e-07" iyy="1.55762e-06" iyz="2.23567e-07" izz="1.28629e-06" />
    </inertial>
    </link>

    <joint name="joint_middle_medial_front_bracket" type="fixed">
    <origin xyz="-0.0215 -0.004 -0.0021" rpy="-4.39991e-17 5.71587e-18 3.14159" />
    <parent link="link_6" />
    <child link="mmf_bracket" />
    <axis xyz="0 0 1"/>
    <limit effort="1" velocity="20" />
    <joint_properties friction="0.0"/>
    </joint>

    <link name="mmb_bracket">
    <visual>
    <origin xyz="-0.0755 -0.004 0.014" rpy="-3.14159 1.10699e-32 -3.44224e-32" />
    <geometry>
    <mesh filename="package://allegro_hand_description/meshes/medial_back.stl"/>
    </geometry>
    <material name="medial_back_material">
    <color rgba="1 0.756863 0.054902 1.0"/>
    </material>
    </visual>
    <collision>
    <origin xyz="-0.0755 -0.004 0.014" rpy="-3.14159 1.10699e-32 -3.44224e-32" />
    <geometry>
    <mesh filename="package://allegro_hand_description/meshes/medial_back.stl"/>
    </geometry>
    <material name="medial_back_material">
    <color rgba="1 0.756863 0.054902 1.0"/>
    </material>
    </collision>
    <inertial>
    <origin xyz="0.0050369 0.00536951 0.0198823" rpy="0 0 0"/>
    <mass value="0.00531302" />
    <inertia ixx="1.01036e-06" ixy="-2.70353e-07"  ixz="2.64599e-07" iyy="1.7622e-06" iyz="2.24575e-07" izz="1.4134e-06" />
    </inertial>
    </link>

    <joint name="joint_middle_medial_back_bracket" type="fixed">
    <origin xyz="-0.0215 0.004 0.0259" rpy="-3.14159 -9.53737e-16 3.14159" />
    <parent link="link_6" />
    <child link="mmb_bracket" />
    <axis xyz="0 0 1"/>
    <limit effort="1" velocity="20" />
    <joint_properties friction="0.0"/>
    </joint>

    <joint name="joint_6_0" type="revolute">
    <origin xyz="-0.054 2.56739e-16 -1.76074e-15" rpy="5.58159e-16 -7.32724e-16 -3.32379e-15" />
    <parent link="link_5" />
    <child link="link_6" />
    <axis xyz="0 0 1"/>
    <limit effort="1" velocity="20" />
    <joint_properties friction="0.0"/>
    </joint>

    <link name="mpf_bracket">
    <visual>
    <origin xyz="-0.0249 -0.0077 0.014" rpy="-6.58054e-35 -0 0" />
    <geometry>
    <mesh filename="package://allegro_hand_description/meshes/proximal_front.stl"/>
    </geometry>
    <material name="proximal_front_material">
    <color rgba="1 0.756863 0.054902 1.0"/>
    </material>
    </visual>
    <collision>
    <origin xyz="-0.0249 -0.0077 0.014" rpy="-6.58054e-35 -0 0" />
    <geometry>
    <mesh filename="package://allegro_hand_description/meshes/proximal_front.stl"/>
    </geometry>
    <material name="proximal_front_material">
    <color rgba="1 0.756863 0.054902 1.0"/>
    </material>
    </collision>
    <inertial>
    <origin xyz="0.00266438 0.00143857 0.0191449" rpy="0 0 0"/>
    <mass value="0.00549452" />
    <inertia ixx="8.30997e-07" ixy="-1.44805e-08"  ixz="8.87855e-09" iyy="1.59352e-06" iyz="2.4142e-07" izz="1.37197e-06" />
    </inertial>
    </link>

    <joint name="joint_middle_proximal_front_bracket" type="fixed">
    <origin xyz="-0.0249 -0.0077 -0.0017" rpy="-5.38894e-32 -1.09608e-17 3.14159" />
    <parent link="link_5" />
    <child link="mpf_bracket" />
    <axis xyz="0 0 1"/>
    <limit effort="1" velocity="20" />
    <joint_properties friction="0.0"/>
    </joint>

    <link name="mpb_bracket">
    <visual>
    <origin xyz="-0.0249 -0.0037 0.014" rpy="3.14159 1.12086e-44 -2.66386e-31" />
    <geometry>
    <mesh filename="package://allegro_hand_description/meshes/proximal_back.stl"/>
    </geometry>
    <material name="proximal_back_material">
    <color rgba="1 0.756863 0.054902 1.0"/>
    </material>
    </visual>
    <collision>
    <origin xyz="-0.0249 -0.0037 0.014" rpy="3.14159 1.12086e-44 -2.66386e-31" />
    <geometry>
    <mesh filename="package://allegro_hand_description/meshes/proximal_back.stl"/>
    </geometry>
    <material name="proximal_back_material">
    <color rgba="1 0.756863 0.054902 1.0"/>
    </material>
    </collision>
    <inertial>
    <origin xyz="0.00190421 0.00603324 0.0192417" rpy="0 0 0"/>
    <mass value="0.00681742" />
    <inertia ixx="1.33469e-06" ixy="-1.25087e-08"  ixz="-1.65721e-09" iyy="2.12223e-06" iyz="3.02232e-07" izz="1.86525e-06" />
    </inertial>
    </link>

    <joint name="joint_middle_proximal_back_bracket" type="fixed">
    <origin xyz="-0.0249 0.0037 0.0253" rpy="3.14159 -5.25942e-17 -3.14159" />
    <parent link="link_5" />
    <child link="mpb_bracket" />
    <axis xyz="0 0 1"/>
    <limit effort="1" velocity="20" />
    <joint_properties friction="0.0"/>
    </joint>

    <joint name="joint_5_0" type="revolute">
    <origin xyz="6.93889e-18 -0.0119 0.02545" rpy="-1.5708 1.5708 0" />
    <parent link="link_4" />
    <child link="link_5" />
    <axis xyz="0 0 1"/>
    <limit effort="1" velocity="20" />
    <joint_properties friction="0.0"/>
    </joint>

    <joint name="joint_4_0" type="revolute">
    <origin xyz="-2.68398e-34 0.034 -0.0033" rpy="0 -0 1.5708" />
    <parent link="palm_link" />
    <child link="link_4" />
    <axis xyz="0 0 1"/>
    <limit effort="1" velocity="20" />
    <joint_properties friction="0.0"/>
    </joint>

    <link name="link_8">
    <visual>
    <origin xyz="6.93889e-18 -6.93889e-18 -0.0152" rpy="1.5708 -1.84889e-32 4.46816e-32" />
    <geometry>
    <mesh filename="package://allegro_hand_description/meshes/extended_finger_base.stl"/>
    </geometry>
    <material name="extended_finger_base_material">
    <color rgba="0.647059 0.647059 0.647059 1.0"/>
    </material>
    </visual>
    <collision>
    <origin xyz="6.93889e-18 -6.93889e-18 -0.0152" rpy="1.5708 -1.84889e-32 4.46816e-32" />
    <geometry>
    <mesh filename="package://allegro_hand_description/meshes/extended_finger_base.stl"/>
    </geometry>
    <material name="extended_finger_base_material">
    <color rgba="0.647059 0.647059 0.647059 1.0"/>
    </material>
    </collision>
    <inertial>
    <origin xyz="-0.00041342 0.000666149 0.00960564" rpy="0 0 0"/>
    <mass value="0.0136672" />
    <inertia ixx="2.13441e-06" ixy="5.86704e-10"  ixz="-7.9563e-08" iyy="1.24411e-06" iyz="-6.13056e-08" izz="1.671e-06" />
    </inertial>
    </link>

    <link name="link_9">
    <visual>
    <origin xyz="0.0182688 -6.93889e-18 -0.0317805" rpy="-9.9881e-31 1.48353 6.61585e-31" />
    <geometry>
    <mesh filename="package://allegro_hand_description/meshes/p2_r6.stl"/>
    </geometry>
    <material name="p2_r6_material">
    <color rgba="0.129412 0.129412 0.129412 1.0"/>
    </material>
    </visual>
    <collision>
    <origin xyz="0.0182688 -6.93889e-18 -0.0317805" rpy="-9.9881e-31 1.48353 6.61585e-31" />
    <geometry>
    <mesh filename="package://allegro_hand_description/meshes/p2_r6.stl"/>
    </geometry>
    <material name="p2_r6_material">
    <color rgba="0.129412 0.129412 0.129412 1.0"/>
    </material>
    </collision>
    <inertial>
    <origin xyz="-0.027 -9.54536e-05 0.0124409" rpy="0 0 0"/>
    <mass value="0.0418346" />
    <inertia ixx="4.44908e-06" ixy="2.0693e-08"  ixz="2.54038e-06" iyy="1.97927e-05" iyz="1.25552e-08" izz="1.84084e-05" />
    </inertial>
    </link>

    <link name="link_10">
    <visual>
    <origin xyz="0.0722688 -4.16334e-17 -0.0317805" rpy="8.79483e-31 1.48353 -9.22514e-31" />
    <geometry>
    <mesh filename="package://allegro_hand_description/meshes/extended_fingertop.stl"/>
    </geometry>
    <material name="extended_fingertop_material">
    <color rgba="0.647059 0.647059 0.647059 1.0"/>
    </material>
    </visual>
    <collision>
    <origin xyz="0.0722688 -4.16334e-17 -0.0317805" rpy="8.79483e-31 1.48353 -9.22514e-31" />
    <geometry>
    <mesh filename="package://allegro_hand_description/meshes/extended_fingertop.stl"/>
    </geometry>
    <material name="extended_fingertop_material">
    <color rgba="0.647059 0.647059 0.647059 1.0"/>
    </material>
    </collision>
    <inertial>
    <origin xyz="-0.0294592 -0.000104104 0.0123435" rpy="0 0 0"/>
    <mass value="0.0318021" />
    <inertia ixx="3.48619e-06" ixy="1.20808e-07"  ixz="6.2918e-07" iyy="8.82437e-06" iyz="5.78644e-09" izz="7.34771e-06" />
    </inertial>
    </link>

    <link name="link_11">
    <visual>
    <origin xyz="0.1253 -6.245e-17 0.0118" rpy="3.14159 2.28724e-32 -1.5708" />
    <geometry>
    <mesh filename="package://allegro_hand_description/meshes/p4_r.stl"/>
    </geometry>
    <material name="p4_r_material">
    <color rgba="0.129412 0.129412 0.129412 1.0"/>
    </material>
    </visual>
    <collision>
    <origin xyz="0.1253 -6.245e-17 0.0118" rpy="3.14159 2.28724e-32 -1.5708" />
    <geometry>
    <mesh filename="package://allegro_hand_description/meshes/p4_r.stl"/>
    </geometry>
    <material name="p4_r_material">
    <color rgba="0.129412 0.129412 0.129412 1.0"/>
    </material>
    </collision>
    <inertial>
    <origin xyz="-0.0100051 0.000639363 0.0123057" rpy="0 0 0"/>
    <mass value="0.0088374" />
    <inertia ixx="1.08072e-06" ixy="-4.65695e-08"  ixz="-3.42321e-08" iyy="1.11236e-06" iyz="-8.85024e-10" izz="5.61586e-07" />
    </inertial>
    </link>

    <link name="pft_bracket">
    <visual>
    <origin xyz="-0.1139 -0.004 0.0135" rpy="3.14159 -1.23888e-17 1.26676e-30" />
    <geometry>
    <mesh filename="package://allegro_hand_description/meshes/distal_pcbbase.stl"/>
    </geometry>
    <material name="distal_pcbbase_material">
    <color rgba="1 0.756863 0.054902 1.0"/>
    </material>
    </visual>
    <collision>
    <origin xyz="-0.1139 -0.004 0.0135" rpy="3.14159 -1.23888e-17 1.26676e-30" />
    <geometry>
    <mesh filename="package://allegro_hand_description/meshes/distal_pcbbase.stl"/>
    </geometry>
    <material name="distal_pcbbase_material">
    <color rgba="1 0.756863 0.054902 1.0"/>
    </material>
    </collision>
    <inertial>
    <origin xyz="0.0170719 -0.00112911 0.0135244" rpy="0 0 0"/>
    <mass value="0.0155109" />
    <inertia ixx="3.339e-06" ixy="-4.60426e-07"  ixz="1.73449e-08" iyy="6.13257e-06" iyz="-6.39964e-10" izz="4.49513e-06" />
    </inertial>
    </link>

    <joint name="joint_pinky_fingertip_bracket" type="fixed">
    <origin xyz="-0.0135 0.004 0.0254" rpy="-3.14159 -6.33477e-16 -3.14159" />
    <parent link="link_11" />
    <child link="pft_bracket" />
    <axis xyz="0 0 1"/>
    <limit effort="1" velocity="20" />
    <joint_properties friction="0.0"/>
    </joint>

    <joint name="joint_11_0" type="revolute">
    <origin xyz="-0.04615 6.93889e-18 0.0001" rpy="9.68157e-16 1.44316e-15 -1.10006e-18" />
    <parent link="link_10" />
    <child link="link_11" />
    <axis xyz="0 0 1"/>
    <limit effort="1" velocity="20" />
    <joint_properties friction="0.0"/>
    </joint>

    <link name="pmf_bracket">
    <visual>
    <origin xyz="-0.0755 -0.004 0.014" rpy="-4.60875e-31 -1.57247e-17 4.68304e-31" />
    <geometry>
    <mesh filename="package://allegro_hand_description/meshes/medial_front.stl"/>
    </geometry>
    <material name="medial_front_material">
    <color rgba="1 0.756863 0.054902 1.0"/>
    </material>
    </visual>
    <collision>
    <origin xyz="-0.0755 -0.004 0.014" rpy="-4.60875e-31 -1.57247e-17 4.68304e-31" />
    <geometry>
    <mesh filename="package://allegro_hand_description/meshes/medial_front.stl"/>
    </geometry>
    <material name="medial_front_material">
    <color rgba="1 0.756863 0.054902 1.0"/>
    </material>
    </collision>
    <inertial>
    <origin xyz="0.00469281 0.00336791 0.0198072" rpy="0 0 0"/>
    <mass value="0.00473232" />
    <inertia ixx="8.28869e-07" ixy="-2.96994e-07"  ixz="2.53991e-07" iyy="1.55762e-06" iyz="2.23567e-07" izz="1.28629e-06" />
    </inertial>
    </link>

    <joint name="joint_pinky_medial_front_bracket" type="fixed">
    <origin xyz="-0.0215 -0.004 -0.0021" rpy="-4.41528e-16 3.94696e-17 3.14159" />
    <parent link="link_10" />
    <child link="pmf_bracket" />
    <axis xyz="0 0 1"/>
    <limit effort="1" velocity="20" />
    <joint_properties friction="0.0"/>
    </joint>

    <link name="pmb_bracket">
    <visual>
    <origin xyz="-0.0755 -0.004 0.014" rpy="-3.14159 -1.43313e-17 5.8017e-31" />
    <geometry>
    <mesh filename="package://allegro_hand_description/meshes/medial_back.stl"/>
    </geometry>
    <material name="medial_back_material">
    <color rgba="1 0.756863 0.054902 1.0"/>
    </material>
    </visual>
    <collision>
    <origin xyz="-0.0755 -0.004 0.014" rpy="-3.14159 -1.43313e-17 5.8017e-31" />
    <geometry>
    <mesh filename="package://allegro_hand_description/meshes/medial_back.stl"/>
    </geometry>
    <material name="medial_back_material">
    <color rgba="1 0.756863 0.054902 1.0"/>
    </material>
    </collision>
    <inertial>
    <origin xyz="0.0050369 0.00536951 0.0198823" rpy="0 0 0"/>
    <mass value="0.00531302" />
    <inertia ixx="1.01036e-06" ixy="-2.70353e-07"  ixz="2.64599e-07" iyy="1.7622e-06" iyz="2.24575e-07" izz="1.4134e-06" />
    </inertial>
    </link>

    <joint name="joint_pinky_medial_back_bracket" type="fixed">
    <origin xyz="-0.0215 0.004 0.0259" rpy="3.14159 -4.42051e-16 3.14159" />
    <parent link="link_10" />
    <child link="pmb_bracket" />
    <axis xyz="0 0 1"/>
    <limit effort="1" velocity="20" />
    <joint_properties friction="0.0"/>
    </joint>

    <joint name="joint_10_0" type="revolute">
    <origin xyz="-0.054 1.8735e-16 6.93889e-18" rpy="1.89044e-16 -3.19266e-15 -2.31621e-15" />
    <parent link="link_9" />
    <child link="link_10" />
    <axis xyz="0 0 1"/>
    <limit effort="1" velocity="20" />
    <joint_properties friction="0.0"/>
    </joint>

    <link name="ppb_bracket">
    <visual>
    <origin xyz="-0.0249 -0.0037 0.014" rpy="-3.14159 8.24436e-18 -6.24076e-32" />
    <geometry>
    <mesh filename="package://allegro_hand_description/meshes/proximal_back.stl"/>
    </geometry>
    <material name="proximal_back_material">
    <color rgba="1 0.756863 0.054902 1.0"/>
    </material>
    </visual>
    <collision>
    <origin xyz="-0.0249 -0.0037 0.014" rpy="-3.14159 8.24436e-18 -6.24076e-32" />
    <geometry>
    <mesh filename="package://allegro_hand_description/meshes/proximal_back.stl"/>
    </geometry>
    <material name="proximal_back_material">
    <color rgba="1 0.756863 0.054902 1.0"/>
    </material>
    </collision>
    <inertial>
    <origin xyz="0.00190421 0.00603324 0.0192417" rpy="0 0 0"/>
    <mass value="0.00681742" />
    <inertia ixx="1.33469e-06" ixy="-1.25087e-08"  ixz="-1.65721e-09" iyy="2.12223e-06" iyz="3.02232e-07" izz="1.86525e-06" />
    </inertial>
    </link>

    <joint name="joint_pinky_proximal_back_bracket" type="fixed">
    <origin xyz="-0.0249 0.0037 0.0253" rpy="3.14159 2.21409e-15 3.14159" />
    <parent link="link_9" />
    <child link="ppb_bracket" />
    <axis xyz="0 0 1"/>
    <limit effort="1" velocity="20" />
    <joint_properties friction="0.0"/>
    </joint>

    <link name="ppf_bracket">
    <visual>
    <origin xyz="-0.0249 -0.0077 0.014" rpy="-1.39889e-31 -1.05186e-17 3.25417e-31" />
    <geometry>
    <mesh filename="package://allegro_hand_description/meshes/proximal_front.stl"/>
    </geometry>
    <material name="proximal_front_material">
    <color rgba="1 0.756863 0.054902 1.0"/>
    </material>
    </visual>
    <collision>
    <origin xyz="-0.0249 -0.0077 0.014" rpy="-1.39889e-31 -1.05186e-17 3.25417e-31" />
    <geometry>
    <mesh filename="package://allegro_hand_description/meshes/proximal_front.stl"/>
    </geometry>
    <material name="proximal_front_material">
    <color rgba="1 0.756863 0.054902 1.0"/>
    </material>
    </collision>
    <inertial>
    <origin xyz="0.00266438 0.00143857 0.0191449" rpy="0 0 0"/>
    <mass value="0.00549452" />
    <inertia ixx="8.30997e-07" ixy="-1.44805e-08"  ixz="8.87855e-09" iyy="1.59352e-06" iyz="2.4142e-07" izz="1.37197e-06" />
    </inertial>
    </link>

    <joint name="joint_pinky_proximal_front_bracket" type="fixed">
    <origin xyz="-0.0249 -0.0077 -0.0017" rpy="-1.19862e-14 1.01475e-15 3.14159" />
    <parent link="link_9" />
    <child link="ppf_bracket" />
    <axis xyz="0 0 1"/>
    <limit effort="1" velocity="20" />
    <joint_properties friction="0.0"/>
    </joint>

    <joint name="joint_9_0" type="revolute">
    <origin xyz="-2.77556e-17 -0.0119 0.02545" rpy="-1.5708 1.5708 0" />
    <parent link="link_8" />
    <child link="link_9" />
    <axis xyz="0 0 1"/>
    <limit effort="1" velocity="20" />
    <joint_properties friction="0.0"/>
    </joint>

    <joint name="joint_8_0" type="revolute">
    <origin xyz="0.0435377 0.034 -0.00553922" rpy="0.0872665 4.16334e-17 1.5708" />
    <parent link="palm_link" />
    <child link="link_8" />
    <axis xyz="0 0 1"/>
    <limit effort="1" velocity="20" />
    <joint_properties friction="0.0"/>
    </joint>

    <link name="link_12">
    <visual>
    <origin xyz="0.0232805 -0.0182 -0.0808312" rpy="-2.48535e-33 -0.0872665 -2.25407e-32" />
    <geometry>
    <mesh filename="package://allegro_hand_description/meshes/f1_r.stl"/>
    </geometry>
    <material name="f1_r_material">
    <color rgba="0.129412 0.129412 0.129412 1.0"/>
    </material>
    </visual>
    <collision>
    <origin xyz="0.0232805 -0.0182 -0.0808312" rpy="-2.48535e-33 -0.0872665 -2.25407e-32" />
    <geometry>
    <mesh filename="package://allegro_hand_description/meshes/f1_r.stl"/>
    </geometry>
    <material name="f1_r_material">
    <color rgba="0.129412 0.129412 0.129412 1.0"/>
    </material>
    </collision>
    <inertial>
    <origin xyz="-0.0151161 -0.00905831 -0.0192298" rpy="0 0 0"/>
    <mass value="0.0660275" />
    <inertia ixx="1.44344e-05" ixy="1.24597e-06"  ixz="3.47822e-08" iyy="1.76386e-05" iyz="6.49531e-07" izz="1.41981e-05" />
    </inertial>
    </link>

    <link name="link_13">
    <visual>
    <origin xyz="-3.46945e-18 0 -0.0152" rpy="1.5708 2.06898e-17 1.5708" />
    <geometry>
    <mesh filename="package://allegro_hand_description/meshes/extended_finger_base.stl"/>
    </geometry>
    <material name="extended_finger_base_material">
    <color rgba="0.647059 0.647059 0.647059 1.0"/>
    </material>
    </visual>
    <collision>
    <origin xyz="-3.46945e-18 0 -0.0152" rpy="1.5708 2.06898e-17 1.5708" />
    <geometry>
    <mesh filename="package://allegro_hand_description/meshes/extended_finger_base.stl"/>
    </geometry>
    <material name="extended_finger_base_material">
    <color rgba="0.647059 0.647059 0.647059 1.0"/>
    </material>
    </collision>
    <inertial>
    <origin xyz="-0.000666149 -0.00041342 0.00960564" rpy="0 0 0"/>
    <mass value="0.0136672" />
    <inertia ixx="1.671e-06" ixy="6.13056e-08"  ixz="7.9563e-08" iyy="1.24411e-06" iyz="5.86704e-10" izz="2.13441e-06" />
    </inertial>
    </link>

    <link name="link_14">
    <visual>
    <origin xyz="0.0787805 -0.0716312 0.0251" rpy="-1.5708 1.2208e-31 0.0872665" />
    <geometry>
    <mesh filename="package://allegro_hand_description/meshes/f3_r.stl"/>
    </geometry>
    <material name="f3_r_material">
    <color rgba="0.129412 0.129412 0.129412 1.0"/>
    </material>
    </visual>
    <collision>
    <origin xyz="0.0787805 -0.0716312 0.0251" rpy="-1.5708 1.2208e-31 0.0872665" />
    <geometry>
    <mesh filename="package://allegro_hand_description/meshes/f3_r.stl"/>
    </geometry>
    <material name="f3_r_material">
    <color rgba="0.129412 0.129412 0.129412 1.0"/>
    </material>
    </collision>
    <inertial>
    <origin xyz="-0.0169218 0.00050045 0.012098" rpy="0 0 0"/>
    <mass value="0.0307701" />
    <inertia ixx="3.26297e-06" ixy="-7.80105e-07"  ixz="4.19183e-07" iyy="9.45316e-06" iyz="7.40454e-08" izz="8.27249e-06" />
    </inertial>
    </link>

    <link name="link_15">
    <visual>
    <origin xyz="0.13018 -0.0716312 0.0252" rpy="-1.5708 1.74443e-31 0.0872665" />
    <geometry>
    <mesh filename="package://allegro_hand_description/meshes/f4_r.stl"/>
    </geometry>
    <material name="f4_r_material">
    <color rgba="0.2 0.2 0.2 1.0"/>
    </material>
    </visual>
    <collision>
    <origin xyz="0.13018 -0.0716312 0.0252" rpy="-1.5708 1.74443e-31 0.0872665" />
    <geometry>
    <mesh filename="package://allegro_hand_description/meshes/f4_r.stl"/>
    </geometry>
    <material name="f4_r_material">
    <color rgba="0.2 0.2 0.2 1.0"/>
    </material>
    </collision>
    <inertial>
    <origin xyz="-0.0146717 0.000106021 0.012196" rpy="0 0 0"/>
    <mass value="0.0326938" />
    <inertia ixx="2.85763e-06" ixy="-2.76566e-07"  ixz="3.76274e-07" iyy="6.11217e-06" iyz="5.74019e-08" izz="5.36876e-06" />
    </inertial>
    </link>

    <link name="tft_bracket">
    <visual>
    <origin xyz="-0.1139 -0.004 0.0135" rpy="-3.14159 -8.20535e-32 5.46303e-18" />
    <geometry>
    <mesh filename="package://allegro_hand_description/meshes/distal_pcbbase.stl"/>
    </geometry>
    <material name="distal_pcbbase_material">
    <color rgba="1 0.756863 0.054902 1.0"/>
    </material>
    </visual>
    <collision>
    <origin xyz="-0.1139 -0.004 0.0135" rpy="-3.14159 -8.20535e-32 5.46303e-18" />
    <geometry>
    <mesh filename="package://allegro_hand_description/meshes/distal_pcbbase.stl"/>
    </geometry>
    <material name="distal_pcbbase_material">
    <color rgba="1 0.756863 0.054902 1.0"/>
    </material>
    </collision>
    <inertial>
    <origin xyz="0.0170719 -0.00112911 0.0135244" rpy="0 0 0"/>
    <mass value="0.0155109" />
    <inertia ixx="3.339e-06" ixy="-4.60426e-07"  ixz="1.73449e-08" iyy="6.13257e-06" iyz="-6.39964e-10" izz="4.49513e-06" />
    </inertial>
    </link>

    <joint name="joint_thumb_fingertip_bracket" type="fixed">
    <origin xyz="-0.0291 0.0037 0.0253" rpy="3.14159 3.0723e-15 -3.14159" />
    <parent link="link_15" />
    <child link="tft_bracket" />
    <axis xyz="0 0 1"/>
    <limit effort="1" velocity="20" />
    <joint_properties friction="0.0"/>
    </joint>

    <joint name="joint_15_0" type="revolute">
    <origin xyz="-0.0514 -9.89486e-15 -0.0001" rpy="7.8724e-16 1.94208e-15 2.09209e-13" />
    <parent link="link_14" />
    <child link="link_15" />
    <axis xyz="0 0 1"/>
    <limit effort="1" velocity="20" />
    <joint_properties friction="0.0"/>
    </joint>

    <link name="tmb_bracket">
    <visual>
    <origin xyz="0.004 0.0329 0.014" rpy="1.5708 3.19014e-32 -5.8953e-18" />
    <geometry>
    <mesh filename="package://allegro_hand_description/meshes/thumb_medial_back_bracket.stl"/>
    </geometry>
    <material name="thumb_medial_back_bracket_material">
    <color rgba="0.917647 0.917647 0.917647 1.0"/>
    </material>
    </visual>
    <collision>
    <origin xyz="0.004 0.0329 0.014" rpy="1.5708 3.19014e-32 -5.8953e-18" />
    <geometry>
    <mesh filename="package://allegro_hand_description/meshes/thumb_medial_back_bracket.stl"/>
    </geometry>
    <material name="thumb_medial_back_bracket_material">
    <color rgba="0.917647 0.917647 0.917647 1.0"/>
    </material>
    </collision>
    <inertial>
    <origin xyz="-0.00600734 0.00588203 0.0181482" rpy="0 0 0"/>
    <mass value="0.00473763" />
    <inertia ixx="1.11799e-06" ixy="-2.9649e-08"  ixz="1.65587e-07" iyy="9.60308e-07" iyz="-6.32913e-08" izz="7.92445e-07" />
    </inertial>
    </link>

    <joint name="joint_thumb_medial_back_bracket" type="fixed">
    <origin xyz="-0.0249 0.004 -0.0022" rpy="-2.32122e-16 2.56368e-16 -1.5708" />
    <parent link="link_14" />
    <child link="tmb_bracket" />
    <axis xyz="0 0 1"/>
    <limit effort="1" velocity="20" />
    <joint_properties friction="0.0"/>
    </joint>

    <link name="tmf_bracket">
    <visual>
    <origin xyz="-0.004 -0.0329 0.014" rpy="-1.5708 3.56272e-31 -3.69029e-18" />
    <geometry>
    <mesh filename="package://allegro_hand_description/meshes/thumb_medial_front_bracket.stl"/>
    </geometry>
    <material name="thumb_medial_front_bracket_material">
    <color rgba="0.917647 0.917647 0.917647 1.0"/>
    </material>
    </visual>
    <collision>
    <origin xyz="-0.004 -0.0329 0.014" rpy="-1.5708 3.56272e-31 -3.69029e-18" />
    <geometry>
    <mesh filename="package://allegro_hand_description/meshes/thumb_medial_front_bracket.stl"/>
    </geometry>
    <material name="thumb_medial_front_bracket_material">
    <color rgba="0.917647 0.917647 0.917647 1.0"/>
    </material>
    </collision>
    <inertial>
    <origin xyz="0.00534582 -0.00527635 0.0171061" rpy="0 0 0"/>
    <mass value="0.0040514" />
    <inertia ixx="9.13083e-07" ixy="-5.82508e-09"  ixz="-1.21819e-07" iyy="6.82814e-07" iyz="1.23951e-07" izz="5.97236e-07" />
    </inertial>
    </link>

    <joint name="joint_thumb_medial_front_bracket" type="fixed">
    <origin xyz="-0.0249 -0.004 0.0258" rpy="3.14159 -1.54748e-16 -1.5708" />
    <parent link="link_14" />
    <child link="tmf_bracket" />
    <axis xyz="0 0 1"/>
    <limit effort="1" velocity="20" />
    <joint_properties friction="0.0"/>
    </joint>

    <joint name="joint_14_0" type="revolute">
    <origin xyz="0.0119 0 0.02545" rpy="-3.14159 1.5708 0" />
    <parent link="link_13" />
    <child link="link_14" />
    <axis xyz="0 0 1"/>
    <limit effort="1" velocity="20" />
    <joint_properties friction="0.0"/>
    </joint>

    <joint name="joint_13_0" type="revolute">
    <origin xyz="-0.0375 -0.005 -0.0092" rpy="-1.5708 -3.01469e-15 1.5708" />
    <parent link="link_12" />
    <child link="link_13" />
    <axis xyz="0 0 1"/>
    <limit effort="1" velocity="20" />
    <joint_properties friction="0.0"/>
    </joint>

    <joint name="joint_12_0" type="revolute">
    <origin xyz="-0.0161208 0.0158 -0.0848515" rpy="-3.14159 -0.0872665 1.84398e-16" />
    <parent link="palm_link" />
    <child link="link_12" />
    <axis xyz="0 0 1"/>
    <limit effort="1" velocity="20" />
    <joint_properties friction="0.0"/>
    </joint>

    <link name="boh_bracket">
    <visual>
    <origin xyz="0.02 0.007 0.0435" rpy="-1.5708 -1.5708 0" />
    <geometry>
    <mesh filename="package://allegro_hand_description/meshes/part_4.stl"/>
    </geometry>
    <material name="part_4_material">
    <color rgba="0.980392 0.713725 0.00392157 1.0"/>
    </material>
    </visual>
    <collision>
    <origin xyz="0.02 0.007 0.0435" rpy="-1.5708 -1.5708 0" />
    <geometry>
    <mesh filename="package://allegro_hand_description/meshes/part_4.stl"/>
    </geometry>
    <material name="part_4_material">
    <color rgba="0.980392 0.713725 0.00392157 1.0"/>
    </material>
    </collision>
    <inertial>
    <origin xyz="0.0205425 -0.0333769 -0.00325" rpy="0 0 0"/>
    <mass value="0.0385521" />
    <inertia ixx="5.89511e-05" ixy="3.11147e-09"  ixz="-3.78027e-07" iyy="9.09733e-05" iyz="4.84151e-09" izz="3.60656e-05" />
    </inertial>
    </link>

    <joint name="joint_boh_bracket" type="fixed">
    <origin xyz="0.02 -0.0094 -0.009" rpy="1.5708 -0 3.14159" />
    <parent link="palm_link" />
    <child link="boh_bracket" />
    <axis xyz="0 0 1"/>
    <limit effort="1" velocity="20" />
    <joint_properties friction="0.0"/>
    </joint>

    <link name="palm_bracket">
    <visual>
    <origin xyz="-0.000254584 -0.095 0.0113" rpy="1.5708 1.5708 0" />
    <geometry>
    <mesh filename="package://allegro_hand_description/meshes/palm_bracket.stl"/>
    </geometry>
    <material name="palm_bracket_material">
    <color rgba="0.231373 0.380392 0.705882 1.0"/>
    </material>
    </visual>
    <collision>
    <origin xyz="-0.000254584 -0.095 0.0113" rpy="1.5708 1.5708 0" />
    <geometry>
    <mesh filename="package://allegro_hand_description/meshes/palm_bracket.stl"/>
    </geometry>
    <material name="palm_bracket_material">
    <color rgba="0.231373 0.380392 0.705882 1.0"/>
    </material>
    </collision>
    <inertial>
    <origin xyz="-0.0117692 -0.0440058 -0.00328358" rpy="0 0 0"/>
    <mass value="0.0366468" />
    <inertia ixx="3.0726e-05" ixy="3.33674e-07"  ixz="-2.90867e-06" iyy="5.36054e-05" iyz="1.29147e-07" izz="2.31158e-05" />
    </inertial>
    </link>

    <joint name="joint_palm_bracket" type="fixed">
    <origin xyz="-0.000254584 0.0453 -0.097" rpy="-1.5708 -0 3.14159" />
    <parent link="palm_link" />
    <child link="palm_bracket" />
    <axis xyz="0 0 1"/>
    <limit effort="1" velocity="20" />
    <joint_properties friction="0.0"/>
    </joint>

</robot>







    
